[2024-01-21T12:12:21.033+0100] {processor.py:161} INFO - Started process (PID=4650) to work on /home/ubuntu/airflow/dags/my_dag.py
[2024-01-21T12:12:21.047+0100] {processor.py:830} INFO - Processing file /home/ubuntu/airflow/dags/my_dag.py for tasks to queue
[2024-01-21T12:12:21.054+0100] {logging_mixin.py:188} INFO - [2024-01-21T12:12:21.051+0100] {dagbag.py:538} INFO - Filling up the DagBag from /home/ubuntu/airflow/dags/my_dag.py
[2024-01-21T12:12:23.800+0100] {logging_mixin.py:188} INFO - Nombre: 40
[2024-01-21T12:12:24.281+0100] {logging_mixin.py:188} INFO - Nombre: 60
[2024-01-21T12:12:24.858+0100] {logging_mixin.py:188} INFO - Nombre: 80
[2024-01-21T12:12:25.461+0100] {logging_mixin.py:188} INFO - Nombre: 100
[2024-01-21T12:12:26.515+0100] {logging_mixin.py:188} INFO - Nombre: 120
[2024-01-21T12:12:27.680+0100] {logging_mixin.py:188} INFO - Nombre: 140
[2024-01-21T12:12:28.244+0100] {logging_mixin.py:188} INFO - Nombre: 160
[2024-01-21T12:12:29.348+0100] {logging_mixin.py:188} INFO - Nombre: 180
[2024-01-21T12:12:30.099+0100] {logging_mixin.py:188} INFO - Nombre: 200
[2024-01-21T12:12:31.158+0100] {logging_mixin.py:188} INFO - Nombre: 220
[2024-01-21T12:12:31.867+0100] {logging_mixin.py:188} INFO - Nombre: 240
[2024-01-21T12:12:32.844+0100] {logging_mixin.py:188} INFO - Nombre: 260
[2024-01-21T12:12:33.483+0100] {logging_mixin.py:188} INFO - Nombre: 280
[2024-01-21T12:12:34.648+0100] {logging_mixin.py:188} INFO - Nombre: 300
[2024-01-21T12:12:35.551+0100] {logging_mixin.py:188} INFO - Nombre: 320
[2024-01-21T12:12:36.125+0100] {logging_mixin.py:188} INFO - Nombre: 340
[2024-01-21T12:12:36.764+0100] {logging_mixin.py:188} INFO - Nombre: 360
[2024-01-21T12:12:37.414+0100] {logging_mixin.py:188} INFO - Nombre: 380
[2024-01-21T12:12:37.898+0100] {logging_mixin.py:188} INFO - Nombre: 400
[2024-01-21T12:12:38.740+0100] {logging_mixin.py:188} INFO - Nombre: 420
[2024-01-21T12:12:39.680+0100] {logging_mixin.py:188} INFO - Nombre: 440
[2024-01-21T12:12:40.478+0100] {logging_mixin.py:188} INFO - Nombre: 460
[2024-01-21T12:12:41.046+0100] {logging_mixin.py:188} INFO - Nombre: 480
[2024-01-21T12:12:41.560+0100] {logging_mixin.py:188} INFO - Nombre: 500
[2024-01-21T12:12:43.050+0100] {logging_mixin.py:188} INFO - Nombre: 520
[2024-01-21T12:12:43.568+0100] {logging_mixin.py:188} INFO - Nombre: 540
[2024-01-21T12:12:44.003+0100] {logging_mixin.py:188} INFO - Nombre: 560
[2024-01-21T12:12:44.557+0100] {logging_mixin.py:188} INFO - Nombre: 580
[2024-01-21T12:12:45.058+0100] {logging_mixin.py:188} INFO - Nombre: 600
[2024-01-21T12:12:45.609+0100] {logging_mixin.py:188} INFO - Nombre: 620
[2024-01-21T12:12:46.038+0100] {logging_mixin.py:188} INFO - Nombre: 640
[2024-01-21T12:12:46.438+0100] {logging_mixin.py:188} INFO - Nombre: 660
[2024-01-21T12:12:46.848+0100] {logging_mixin.py:188} INFO - Nombre: 680
[2024-01-21T12:12:47.445+0100] {logging_mixin.py:188} INFO - Nombre: 700
[2024-01-21T12:12:47.918+0100] {logging_mixin.py:188} INFO - Nombre: 720
[2024-01-21T12:12:48.563+0100] {logging_mixin.py:188} INFO - Nombre: 740
[2024-01-21T12:12:49.043+0100] {logging_mixin.py:188} INFO - Nombre: 760
[2024-01-21T12:12:49.663+0100] {logging_mixin.py:188} INFO - Nombre: 780
[2024-01-21T12:12:50.364+0100] {logging_mixin.py:188} INFO - Nombre: 800
[2024-01-21T12:12:51.160+0100] {logging_mixin.py:188} INFO - [2024-01-21T12:12:51.155+0100] {timeout.py:68} ERROR - Process timed out, PID: 4650
[2024-01-21T12:12:51.419+0100] {logging_mixin.py:188} INFO - [2024-01-21T12:12:51.163+0100] {dagbag.py:348} ERROR - Failed to import: /home/ubuntu/airflow/dags/my_dag.py
Traceback (most recent call last):
  File "/home/ubuntu/.local/lib/python3.10/site-packages/airflow/models/dagbag.py", line 344, in parse
    loader.exec_module(new_module)
  File "<frozen importlib._bootstrap_external>", line 883, in exec_module
  File "<frozen importlib._bootstrap>", line 241, in _call_with_frames_removed
  File "/home/ubuntu/airflow/dags/my_dag.py", line 5, in <module>
    from movies import find_popular_movies_and_save, get_movie_genres
  File "/home/ubuntu/airflow/dags/movies.py", line 45, in <module>
    find_popular_movies_and_save()
  File "/home/ubuntu/airflow/dags/movies.py", line 33, in find_popular_movies_and_save
    response = requests.get(base_url, params=params)
  File "/home/ubuntu/.local/lib/python3.10/site-packages/requests/api.py", line 73, in get
    return request("get", url, params=params, **kwargs)
  File "/home/ubuntu/.local/lib/python3.10/site-packages/requests/api.py", line 59, in request
    return session.request(method=method, url=url, **kwargs)
  File "/home/ubuntu/.local/lib/python3.10/site-packages/requests/sessions.py", line 589, in request
    resp = self.send(prep, **send_kwargs)
  File "/home/ubuntu/.local/lib/python3.10/site-packages/requests/sessions.py", line 703, in send
    r = adapter.send(request, **kwargs)
  File "/home/ubuntu/.local/lib/python3.10/site-packages/requests/adapters.py", line 486, in send
    resp = conn.urlopen(
  File "/home/ubuntu/.local/lib/python3.10/site-packages/urllib3/connectionpool.py", line 715, in urlopen
    httplib_response = self._make_request(
  File "/home/ubuntu/.local/lib/python3.10/site-packages/urllib3/connectionpool.py", line 404, in _make_request
    self._validate_conn(conn)
  File "/home/ubuntu/.local/lib/python3.10/site-packages/urllib3/connectionpool.py", line 1058, in _validate_conn
    conn.connect()
  File "/home/ubuntu/.local/lib/python3.10/site-packages/urllib3/connection.py", line 419, in connect
    self.sock = ssl_wrap_socket(
  File "/home/ubuntu/.local/lib/python3.10/site-packages/urllib3/util/ssl_.py", line 449, in ssl_wrap_socket
    ssl_sock = _ssl_wrap_socket_impl(
  File "/home/ubuntu/.local/lib/python3.10/site-packages/urllib3/util/ssl_.py", line 493, in _ssl_wrap_socket_impl
    return ssl_context.wrap_socket(sock, server_hostname=server_hostname)
  File "/usr/lib/python3.10/ssl.py", line 513, in wrap_socket
    return self.sslsocket_class._create(
  File "/usr/lib/python3.10/ssl.py", line 1100, in _create
    self.do_handshake()
  File "/usr/lib/python3.10/ssl.py", line 1371, in do_handshake
    self._sslobj.do_handshake()
  File "/home/ubuntu/.local/lib/python3.10/site-packages/airflow/utils/timeout.py", line 69, in handle_timeout
    raise AirflowTaskTimeout(self.error_message)
airflow.exceptions.AirflowTaskTimeout: DagBag import timeout for /home/ubuntu/airflow/dags/my_dag.py after 30.0s.
Please take a look at these docs to improve your DAG import time:
* https://airflow.apache.org/docs/apache-airflow/2.8.0/best-practices.html#top-level-python-code
* https://airflow.apache.org/docs/apache-airflow/2.8.0/best-practices.html#reducing-dag-complexity, PID: 4650
[2024-01-21T12:12:51.433+0100] {processor.py:842} WARNING - No viable dags retrieved from /home/ubuntu/airflow/dags/my_dag.py
[2024-01-21T12:12:51.800+0100] {processor.py:183} INFO - Processing /home/ubuntu/airflow/dags/my_dag.py took 30.825 seconds
[2024-01-21T12:14:48.611+0100] {processor.py:161} INFO - Started process (PID=4733) to work on /home/ubuntu/airflow/dags/my_dag.py
[2024-01-21T12:14:48.623+0100] {processor.py:830} INFO - Processing file /home/ubuntu/airflow/dags/my_dag.py for tasks to queue
[2024-01-21T12:14:48.625+0100] {logging_mixin.py:188} INFO - [2024-01-21T12:14:48.624+0100] {dagbag.py:538} INFO - Filling up the DagBag from /home/ubuntu/airflow/dags/my_dag.py
[2024-01-21T12:14:50.301+0100] {logging_mixin.py:188} INFO - Nombre: 40
[2024-01-21T12:14:50.712+0100] {logging_mixin.py:188} INFO - Nombre: 60
[2024-01-21T12:14:51.150+0100] {logging_mixin.py:188} INFO - Nombre: 80
[2024-01-21T12:14:51.695+0100] {logging_mixin.py:188} INFO - Nombre: 100
[2024-01-21T12:14:52.477+0100] {logging_mixin.py:188} INFO - Nombre: 120
[2024-01-21T12:14:53.134+0100] {logging_mixin.py:188} INFO - Nombre: 140
[2024-01-21T12:14:53.757+0100] {logging_mixin.py:188} INFO - Nombre: 160
[2024-01-21T12:14:54.412+0100] {logging_mixin.py:188} INFO - Nombre: 180
[2024-01-21T12:14:55.016+0100] {logging_mixin.py:188} INFO - Nombre: 200
[2024-01-21T12:14:55.546+0100] {logging_mixin.py:188} INFO - Nombre: 220
[2024-01-21T12:14:56.022+0100] {logging_mixin.py:188} INFO - Nombre: 240
[2024-01-21T12:14:56.509+0100] {logging_mixin.py:188} INFO - Nombre: 260
[2024-01-21T12:14:57.074+0100] {logging_mixin.py:188} INFO - Nombre: 280
[2024-01-21T12:14:57.465+0100] {logging_mixin.py:188} INFO - Nombre: 300
[2024-01-21T12:14:57.958+0100] {logging_mixin.py:188} INFO - Nombre: 320
[2024-01-21T12:14:58.632+0100] {logging_mixin.py:188} INFO - Nombre: 340
[2024-01-21T12:14:59.310+0100] {logging_mixin.py:188} INFO - Nombre: 360
[2024-01-21T12:14:59.866+0100] {logging_mixin.py:188} INFO - Nombre: 380
[2024-01-21T12:15:00.423+0100] {logging_mixin.py:188} INFO - Nombre: 400
[2024-01-21T12:15:01.016+0100] {logging_mixin.py:188} INFO - Nombre: 420
[2024-01-21T12:15:01.578+0100] {logging_mixin.py:188} INFO - Nombre: 440
[2024-01-21T12:15:02.100+0100] {logging_mixin.py:188} INFO - Nombre: 460
[2024-01-21T12:15:02.679+0100] {logging_mixin.py:188} INFO - Nombre: 480
[2024-01-21T12:15:03.226+0100] {logging_mixin.py:188} INFO - Nombre: 500
[2024-01-21T12:15:03.625+0100] {logging_mixin.py:188} INFO - Nombre: 520
[2024-01-21T12:15:04.183+0100] {logging_mixin.py:188} INFO - Nombre: 540
[2024-01-21T12:15:04.761+0100] {logging_mixin.py:188} INFO - Nombre: 560
[2024-01-21T12:15:05.205+0100] {logging_mixin.py:188} INFO - Nombre: 580
[2024-01-21T12:15:05.775+0100] {logging_mixin.py:188} INFO - Nombre: 600
[2024-01-21T12:15:06.184+0100] {logging_mixin.py:188} INFO - Nombre: 620
[2024-01-21T12:15:06.713+0100] {logging_mixin.py:188} INFO - Nombre: 640
[2024-01-21T12:15:07.230+0100] {logging_mixin.py:188} INFO - Nombre: 660
[2024-01-21T12:15:07.865+0100] {logging_mixin.py:188} INFO - Nombre: 680
[2024-01-21T12:15:08.377+0100] {logging_mixin.py:188} INFO - Nombre: 700
[2024-01-21T12:15:08.867+0100] {logging_mixin.py:188} INFO - Nombre: 720
[2024-01-21T12:15:09.473+0100] {logging_mixin.py:188} INFO - Nombre: 740
[2024-01-21T12:15:09.911+0100] {logging_mixin.py:188} INFO - Nombre: 760
[2024-01-21T12:15:10.414+0100] {logging_mixin.py:188} INFO - Nombre: 780
[2024-01-21T12:15:10.805+0100] {logging_mixin.py:188} INFO - Nombre: 800
[2024-01-21T12:15:11.297+0100] {logging_mixin.py:188} INFO - Nombre: 820
[2024-01-21T12:15:11.762+0100] {logging_mixin.py:188} INFO - Nombre: 840
[2024-01-21T12:15:12.232+0100] {logging_mixin.py:188} INFO - Nombre: 860
[2024-01-21T12:15:12.866+0100] {logging_mixin.py:188} INFO - Nombre: 880
[2024-01-21T12:15:13.393+0100] {logging_mixin.py:188} INFO - Nombre: 900
[2024-01-21T12:15:13.973+0100] {logging_mixin.py:188} INFO - Nombre: 920
[2024-01-21T12:15:14.431+0100] {logging_mixin.py:188} INFO - Nombre: 940
[2024-01-21T12:15:15.057+0100] {logging_mixin.py:188} INFO - Nombre: 960
[2024-01-21T12:15:15.706+0100] {logging_mixin.py:188} INFO - Nombre: 980
[2024-01-21T12:15:16.330+0100] {logging_mixin.py:188} INFO - Nombre: 1000
[2024-01-21T12:15:16.905+0100] {logging_mixin.py:188} INFO - Nombre: 1020
[2024-01-21T12:15:17.428+0100] {logging_mixin.py:188} INFO - Nombre: 1040
[2024-01-21T12:15:18.076+0100] {logging_mixin.py:188} INFO - Nombre: 1060
[2024-01-21T12:15:18.630+0100] {logging_mixin.py:188} INFO - [2024-01-21T12:15:18.629+0100] {timeout.py:68} ERROR - Process timed out, PID: 4733
[2024-01-21T12:15:18.667+0100] {logging_mixin.py:188} INFO - [2024-01-21T12:15:18.631+0100] {dagbag.py:348} ERROR - Failed to import: /home/ubuntu/airflow/dags/my_dag.py
Traceback (most recent call last):
  File "/home/ubuntu/.local/lib/python3.10/site-packages/airflow/models/dagbag.py", line 344, in parse
    loader.exec_module(new_module)
  File "<frozen importlib._bootstrap_external>", line 883, in exec_module
  File "<frozen importlib._bootstrap>", line 241, in _call_with_frames_removed
  File "/home/ubuntu/airflow/dags/my_dag.py", line 5, in <module>
    from movies import find_popular_movies_and_save, get_movie_genres
  File "/home/ubuntu/airflow/dags/movies.py", line 45, in <module>
    find_popular_movies_and_save()
  File "/home/ubuntu/airflow/dags/movies.py", line 33, in find_popular_movies_and_save
    response = requests.get(base_url, params=params)
  File "/home/ubuntu/.local/lib/python3.10/site-packages/requests/api.py", line 73, in get
    return request("get", url, params=params, **kwargs)
  File "/home/ubuntu/.local/lib/python3.10/site-packages/requests/api.py", line 59, in request
    return session.request(method=method, url=url, **kwargs)
  File "/home/ubuntu/.local/lib/python3.10/site-packages/requests/sessions.py", line 589, in request
    resp = self.send(prep, **send_kwargs)
  File "/home/ubuntu/.local/lib/python3.10/site-packages/requests/sessions.py", line 703, in send
    r = adapter.send(request, **kwargs)
  File "/home/ubuntu/.local/lib/python3.10/site-packages/requests/adapters.py", line 486, in send
    resp = conn.urlopen(
  File "/home/ubuntu/.local/lib/python3.10/site-packages/urllib3/connectionpool.py", line 715, in urlopen
    httplib_response = self._make_request(
  File "/home/ubuntu/.local/lib/python3.10/site-packages/urllib3/connectionpool.py", line 467, in _make_request
    six.raise_from(e, None)
  File "<string>", line 3, in raise_from
  File "/home/ubuntu/.local/lib/python3.10/site-packages/urllib3/connectionpool.py", line 462, in _make_request
    httplib_response = conn.getresponse()
  File "/usr/lib/python3.10/http/client.py", line 1375, in getresponse
    response.begin()
  File "/usr/lib/python3.10/http/client.py", line 318, in begin
    version, status, reason = self._read_status()
  File "/usr/lib/python3.10/http/client.py", line 279, in _read_status
    line = str(self.fp.readline(_MAXLINE + 1), "iso-8859-1")
  File "/usr/lib/python3.10/socket.py", line 705, in readinto
    return self._sock.recv_into(b)
  File "/usr/lib/python3.10/ssl.py", line 1303, in recv_into
    return self.read(nbytes, buffer)
  File "/usr/lib/python3.10/ssl.py", line 1159, in read
    return self._sslobj.read(len, buffer)
  File "/home/ubuntu/.local/lib/python3.10/site-packages/airflow/utils/timeout.py", line 69, in handle_timeout
    raise AirflowTaskTimeout(self.error_message)
airflow.exceptions.AirflowTaskTimeout: DagBag import timeout for /home/ubuntu/airflow/dags/my_dag.py after 30.0s.
Please take a look at these docs to improve your DAG import time:
* https://airflow.apache.org/docs/apache-airflow/2.8.0/best-practices.html#top-level-python-code
* https://airflow.apache.org/docs/apache-airflow/2.8.0/best-practices.html#reducing-dag-complexity, PID: 4733
[2024-01-21T12:15:18.680+0100] {processor.py:842} WARNING - No viable dags retrieved from /home/ubuntu/airflow/dags/my_dag.py
[2024-01-21T12:15:18.777+0100] {processor.py:183} INFO - Processing /home/ubuntu/airflow/dags/my_dag.py took 30.180 seconds
[2024-01-21T12:16:00.762+0100] {processor.py:161} INFO - Started process (PID=4778) to work on /home/ubuntu/airflow/dags/my_dag.py
[2024-01-21T12:16:00.767+0100] {processor.py:830} INFO - Processing file /home/ubuntu/airflow/dags/my_dag.py for tasks to queue
[2024-01-21T12:16:00.770+0100] {logging_mixin.py:188} INFO - [2024-01-21T12:16:00.769+0100] {dagbag.py:538} INFO - Filling up the DagBag from /home/ubuntu/airflow/dags/my_dag.py
[2024-01-21T12:16:01.803+0100] {logging_mixin.py:188} INFO - Nombre: 40
[2024-01-21T12:16:02.406+0100] {logging_mixin.py:188} INFO - Nombre: 60
[2024-01-21T12:16:02.897+0100] {logging_mixin.py:188} INFO - Nombre: 80
[2024-01-21T12:16:03.343+0100] {logging_mixin.py:188} INFO - Nombre: 100
[2024-01-21T12:16:03.853+0100] {logging_mixin.py:188} INFO - Nombre: 120
[2024-01-21T12:16:04.230+0100] {logging_mixin.py:188} INFO - Nombre: 140
[2024-01-21T12:16:04.636+0100] {logging_mixin.py:188} INFO - Nombre: 160
[2024-01-21T12:16:05.032+0100] {logging_mixin.py:188} INFO - Nombre: 180
[2024-01-21T12:16:05.459+0100] {logging_mixin.py:188} INFO - Nombre: 200
[2024-01-21T12:16:05.940+0100] {logging_mixin.py:188} INFO - Nombre: 220
[2024-01-21T12:16:06.343+0100] {logging_mixin.py:188} INFO - Nombre: 240
[2024-01-21T12:16:07.030+0100] {logging_mixin.py:188} INFO - Nombre: 260
[2024-01-21T12:16:07.623+0100] {logging_mixin.py:188} INFO - Nombre: 280
[2024-01-21T12:16:08.059+0100] {logging_mixin.py:188} INFO - Nombre: 300
[2024-01-21T12:16:08.606+0100] {logging_mixin.py:188} INFO - Nombre: 320
[2024-01-21T12:16:08.984+0100] {logging_mixin.py:188} INFO - Nombre: 340
[2024-01-21T12:16:09.578+0100] {logging_mixin.py:188} INFO - Nombre: 360
[2024-01-21T12:16:10.136+0100] {logging_mixin.py:188} INFO - Nombre: 380
[2024-01-21T12:16:10.664+0100] {logging_mixin.py:188} INFO - Nombre: 400
[2024-01-21T12:16:11.155+0100] {logging_mixin.py:188} INFO - Nombre: 420
[2024-01-21T12:16:11.621+0100] {logging_mixin.py:188} INFO - Nombre: 440
[2024-01-21T12:16:12.255+0100] {logging_mixin.py:188} INFO - Nombre: 460
[2024-01-21T12:16:12.749+0100] {logging_mixin.py:188} INFO - Nombre: 480
[2024-01-21T12:16:13.454+0100] {logging_mixin.py:188} INFO - Nombre: 500
[2024-01-21T12:16:14.059+0100] {logging_mixin.py:188} INFO - Nombre: 520
[2024-01-21T12:16:14.789+0100] {logging_mixin.py:188} INFO - Nombre: 540
[2024-01-21T12:16:15.482+0100] {logging_mixin.py:188} INFO - Nombre: 560
[2024-01-21T12:16:15.978+0100] {logging_mixin.py:188} INFO - Nombre: 580
[2024-01-21T12:16:16.498+0100] {logging_mixin.py:188} INFO - Nombre: 600
[2024-01-21T12:16:17.042+0100] {logging_mixin.py:188} INFO - Nombre: 620
[2024-01-21T12:16:17.465+0100] {logging_mixin.py:188} INFO - Nombre: 640
[2024-01-21T12:16:17.875+0100] {logging_mixin.py:188} INFO - Nombre: 660
[2024-01-21T12:16:18.454+0100] {logging_mixin.py:188} INFO - Nombre: 680
[2024-01-21T12:16:18.966+0100] {logging_mixin.py:188} INFO - Nombre: 700
[2024-01-21T12:16:19.530+0100] {logging_mixin.py:188} INFO - Nombre: 720
[2024-01-21T12:16:20.065+0100] {logging_mixin.py:188} INFO - Nombre: 740
[2024-01-21T12:16:20.627+0100] {logging_mixin.py:188} INFO - Nombre: 760
[2024-01-21T12:16:21.100+0100] {logging_mixin.py:188} INFO - Nombre: 780
[2024-01-21T12:16:21.582+0100] {logging_mixin.py:188} INFO - Nombre: 800
[2024-01-21T12:16:22.257+0100] {logging_mixin.py:188} INFO - Nombre: 820
[2024-01-21T12:16:22.780+0100] {logging_mixin.py:188} INFO - Nombre: 840
[2024-01-21T12:16:23.465+0100] {logging_mixin.py:188} INFO - Nombre: 860
[2024-01-21T12:16:24.222+0100] {logging_mixin.py:188} INFO - Nombre: 880
[2024-01-21T12:16:24.783+0100] {logging_mixin.py:188} INFO - Nombre: 900
[2024-01-21T12:16:25.347+0100] {logging_mixin.py:188} INFO - Nombre: 920
[2024-01-21T12:16:25.822+0100] {logging_mixin.py:188} INFO - Nombre: 940
[2024-01-21T12:16:26.376+0100] {logging_mixin.py:188} INFO - Nombre: 960
[2024-01-21T12:16:26.813+0100] {logging_mixin.py:188} INFO - Nombre: 980
[2024-01-21T12:16:27.401+0100] {logging_mixin.py:188} INFO - Nombre: 1000
[2024-01-21T12:16:27.958+0100] {logging_mixin.py:188} INFO - Nombre: 1020
[2024-01-21T12:16:28.415+0100] {logging_mixin.py:188} INFO - Nombre: 1040
[2024-01-21T12:16:28.875+0100] {logging_mixin.py:188} INFO - Nombre: 1060
[2024-01-21T12:16:29.452+0100] {logging_mixin.py:188} INFO - Nombre: 1080
[2024-01-21T12:16:30.004+0100] {logging_mixin.py:188} INFO - Nombre: 1100
[2024-01-21T12:16:30.465+0100] {logging_mixin.py:188} INFO - Nombre: 1120
[2024-01-21T12:16:30.795+0100] {logging_mixin.py:188} INFO - [2024-01-21T12:16:30.784+0100] {timeout.py:68} ERROR - Process timed out, PID: 4778
[2024-01-21T12:16:30.831+0100] {logging_mixin.py:188} INFO - [2024-01-21T12:16:30.802+0100] {dagbag.py:348} ERROR - Failed to import: /home/ubuntu/airflow/dags/my_dag.py
Traceback (most recent call last):
  File "/home/ubuntu/.local/lib/python3.10/site-packages/airflow/models/dagbag.py", line 344, in parse
    loader.exec_module(new_module)
  File "<frozen importlib._bootstrap_external>", line 883, in exec_module
  File "<frozen importlib._bootstrap>", line 241, in _call_with_frames_removed
  File "/home/ubuntu/airflow/dags/my_dag.py", line 5, in <module>
    from movies import find_popular_movies_and_save, get_movie_genres
  File "/home/ubuntu/airflow/dags/movies.py", line 45, in <module>
    find_popular_movies_and_save()
  File "/home/ubuntu/airflow/dags/movies.py", line 33, in find_popular_movies_and_save
    response = requests.get(base_url, params=params)
  File "/home/ubuntu/.local/lib/python3.10/site-packages/requests/api.py", line 73, in get
    return request("get", url, params=params, **kwargs)
  File "/home/ubuntu/.local/lib/python3.10/site-packages/requests/api.py", line 59, in request
    return session.request(method=method, url=url, **kwargs)
  File "/home/ubuntu/.local/lib/python3.10/site-packages/requests/sessions.py", line 589, in request
    resp = self.send(prep, **send_kwargs)
  File "/home/ubuntu/.local/lib/python3.10/site-packages/requests/sessions.py", line 703, in send
    r = adapter.send(request, **kwargs)
  File "/home/ubuntu/.local/lib/python3.10/site-packages/requests/adapters.py", line 486, in send
    resp = conn.urlopen(
  File "/home/ubuntu/.local/lib/python3.10/site-packages/urllib3/connectionpool.py", line 715, in urlopen
    httplib_response = self._make_request(
  File "/home/ubuntu/.local/lib/python3.10/site-packages/urllib3/connectionpool.py", line 404, in _make_request
    self._validate_conn(conn)
  File "/home/ubuntu/.local/lib/python3.10/site-packages/urllib3/connectionpool.py", line 1058, in _validate_conn
    conn.connect()
  File "/home/ubuntu/.local/lib/python3.10/site-packages/urllib3/connection.py", line 419, in connect
    self.sock = ssl_wrap_socket(
  File "/home/ubuntu/.local/lib/python3.10/site-packages/urllib3/util/ssl_.py", line 449, in ssl_wrap_socket
    ssl_sock = _ssl_wrap_socket_impl(
  File "/home/ubuntu/.local/lib/python3.10/site-packages/urllib3/util/ssl_.py", line 493, in _ssl_wrap_socket_impl
    return ssl_context.wrap_socket(sock, server_hostname=server_hostname)
  File "/usr/lib/python3.10/ssl.py", line 513, in wrap_socket
    return self.sslsocket_class._create(
  File "/usr/lib/python3.10/ssl.py", line 1100, in _create
    self.do_handshake()
  File "/usr/lib/python3.10/ssl.py", line 1371, in do_handshake
    self._sslobj.do_handshake()
  File "/home/ubuntu/.local/lib/python3.10/site-packages/airflow/utils/timeout.py", line 69, in handle_timeout
    raise AirflowTaskTimeout(self.error_message)
airflow.exceptions.AirflowTaskTimeout: DagBag import timeout for /home/ubuntu/airflow/dags/my_dag.py after 30.0s.
Please take a look at these docs to improve your DAG import time:
* https://airflow.apache.org/docs/apache-airflow/2.8.0/best-practices.html#top-level-python-code
* https://airflow.apache.org/docs/apache-airflow/2.8.0/best-practices.html#reducing-dag-complexity, PID: 4778
[2024-01-21T12:16:30.841+0100] {processor.py:842} WARNING - No viable dags retrieved from /home/ubuntu/airflow/dags/my_dag.py
[2024-01-21T12:16:30.897+0100] {processor.py:183} INFO - Processing /home/ubuntu/airflow/dags/my_dag.py took 30.149 seconds
[2024-01-21T12:17:05.414+0100] {processor.py:161} INFO - Started process (PID=4809) to work on /home/ubuntu/airflow/dags/my_dag.py
[2024-01-21T12:17:05.419+0100] {processor.py:830} INFO - Processing file /home/ubuntu/airflow/dags/my_dag.py for tasks to queue
[2024-01-21T12:17:05.422+0100] {logging_mixin.py:188} INFO - [2024-01-21T12:17:05.421+0100] {dagbag.py:538} INFO - Filling up the DagBag from /home/ubuntu/airflow/dags/my_dag.py
[2024-01-21T12:17:06.517+0100] {logging_mixin.py:188} INFO - Nombre: 40
[2024-01-21T12:17:07.080+0100] {logging_mixin.py:188} INFO - Nombre: 60
[2024-01-21T12:17:07.694+0100] {logging_mixin.py:188} INFO - Nombre: 80
[2024-01-21T12:17:08.095+0100] {logging_mixin.py:188} INFO - Nombre: 100
[2024-01-21T12:17:08.627+0100] {logging_mixin.py:188} INFO - Nombre: 120
[2024-01-21T12:17:09.174+0100] {logging_mixin.py:188} INFO - Nombre: 140
[2024-01-21T12:17:09.716+0100] {logging_mixin.py:188} INFO - Nombre: 160
[2024-01-21T12:17:10.317+0100] {logging_mixin.py:188} INFO - Nombre: 180
[2024-01-21T12:17:10.922+0100] {logging_mixin.py:188} INFO - Nombre: 200
[2024-01-21T12:17:11.451+0100] {logging_mixin.py:188} INFO - Nombre: 220
[2024-01-21T12:17:11.978+0100] {logging_mixin.py:188} INFO - Nombre: 240
[2024-01-21T12:17:12.573+0100] {logging_mixin.py:188} INFO - Nombre: 260
[2024-01-21T12:17:13.173+0100] {logging_mixin.py:188} INFO - Nombre: 280
[2024-01-21T12:17:13.573+0100] {logging_mixin.py:188} INFO - Nombre: 300
[2024-01-21T12:17:14.101+0100] {logging_mixin.py:188} INFO - Nombre: 320
[2024-01-21T12:17:14.550+0100] {logging_mixin.py:188} INFO - Nombre: 340
[2024-01-21T12:17:14.978+0100] {logging_mixin.py:188} INFO - Nombre: 360
[2024-01-21T12:17:15.476+0100] {logging_mixin.py:188} INFO - Nombre: 380
[2024-01-21T12:17:15.944+0100] {logging_mixin.py:188} INFO - Nombre: 400
[2024-01-21T12:17:16.537+0100] {logging_mixin.py:188} INFO - Nombre: 420
[2024-01-21T12:17:16.926+0100] {logging_mixin.py:188} INFO - Nombre: 440
[2024-01-21T12:17:17.425+0100] {logging_mixin.py:188} INFO - Nombre: 460
[2024-01-21T12:17:17.774+0100] {logging_mixin.py:188} INFO - Nombre: 480
[2024-01-21T12:17:18.172+0100] {logging_mixin.py:188} INFO - Nombre: 500
[2024-01-21T12:17:18.745+0100] {logging_mixin.py:188} INFO - Nombre: 520
[2024-01-21T12:17:19.219+0100] {logging_mixin.py:188} INFO - Nombre: 540
[2024-01-21T12:17:19.630+0100] {logging_mixin.py:188} INFO - Nombre: 560
[2024-01-21T12:17:20.124+0100] {logging_mixin.py:188} INFO - Nombre: 580
[2024-01-21T12:17:20.693+0100] {logging_mixin.py:188} INFO - Nombre: 600
[2024-01-21T12:17:21.248+0100] {logging_mixin.py:188} INFO - Nombre: 620
[2024-01-21T12:17:22.156+0100] {logging_mixin.py:188} INFO - Nombre: 640
[2024-01-21T12:17:22.978+0100] {logging_mixin.py:188} INFO - Nombre: 660
[2024-01-21T12:17:23.870+0100] {logging_mixin.py:188} INFO - Nombre: 680
[2024-01-21T12:17:24.747+0100] {logging_mixin.py:188} INFO - Nombre: 700
[2024-01-21T12:17:25.186+0100] {logging_mixin.py:188} INFO - Nombre: 720
[2024-01-21T12:17:25.635+0100] {logging_mixin.py:188} INFO - Nombre: 740
[2024-01-21T12:17:26.049+0100] {logging_mixin.py:188} INFO - Nombre: 760
[2024-01-21T12:17:26.574+0100] {logging_mixin.py:188} INFO - Nombre: 780
[2024-01-21T12:17:27.017+0100] {logging_mixin.py:188} INFO - Nombre: 800
[2024-01-21T12:17:27.502+0100] {logging_mixin.py:188} INFO - Nombre: 820
[2024-01-21T12:17:27.936+0100] {logging_mixin.py:188} INFO - Nombre: 840
[2024-01-21T12:17:28.340+0100] {logging_mixin.py:188} INFO - Nombre: 860
[2024-01-21T12:17:28.774+0100] {logging_mixin.py:188} INFO - Nombre: 880
[2024-01-21T12:17:29.266+0100] {logging_mixin.py:188} INFO - Nombre: 900
[2024-01-21T12:17:29.855+0100] {logging_mixin.py:188} INFO - Nombre: 920
[2024-01-21T12:17:30.391+0100] {logging_mixin.py:188} INFO - Nombre: 940
[2024-01-21T12:17:30.991+0100] {logging_mixin.py:188} INFO - Nombre: 960
[2024-01-21T12:17:31.482+0100] {logging_mixin.py:188} INFO - Nombre: 980
[2024-01-21T12:17:32.059+0100] {logging_mixin.py:188} INFO - Nombre: 1000
[2024-01-21T12:17:32.544+0100] {logging_mixin.py:188} INFO - Nombre: 1020
[2024-01-21T12:17:32.986+0100] {logging_mixin.py:188} INFO - Nombre: 1040
[2024-01-21T12:17:33.504+0100] {logging_mixin.py:188} INFO - Nombre: 1060
[2024-01-21T12:17:34.080+0100] {logging_mixin.py:188} INFO - Nombre: 1080
[2024-01-21T12:17:34.641+0100] {logging_mixin.py:188} INFO - Nombre: 1100
[2024-01-21T12:17:35.158+0100] {logging_mixin.py:188} INFO - Nombre: 1120
[2024-01-21T12:17:35.511+0100] {logging_mixin.py:188} INFO - [2024-01-21T12:17:35.510+0100] {timeout.py:68} ERROR - Process timed out, PID: 4809
[2024-01-21T12:17:35.519+0100] {logging_mixin.py:188} INFO - [2024-01-21T12:17:35.514+0100] {dagbag.py:348} ERROR - Failed to import: /home/ubuntu/airflow/dags/my_dag.py
Traceback (most recent call last):
  File "/home/ubuntu/.local/lib/python3.10/site-packages/airflow/models/dagbag.py", line 344, in parse
    loader.exec_module(new_module)
  File "<frozen importlib._bootstrap_external>", line 883, in exec_module
  File "<frozen importlib._bootstrap>", line 241, in _call_with_frames_removed
  File "/home/ubuntu/airflow/dags/my_dag.py", line 5, in <module>
    from movies import find_popular_movies_and_save, get_movie_genres
  File "/home/ubuntu/airflow/dags/movies.py", line 45, in <module>
    find_popular_movies_and_save()
  File "/home/ubuntu/airflow/dags/movies.py", line 33, in find_popular_movies_and_save
    response = requests.get(base_url, params=params)
  File "/home/ubuntu/.local/lib/python3.10/site-packages/requests/api.py", line 73, in get
    return request("get", url, params=params, **kwargs)
  File "/home/ubuntu/.local/lib/python3.10/site-packages/requests/api.py", line 59, in request
    return session.request(method=method, url=url, **kwargs)
  File "/home/ubuntu/.local/lib/python3.10/site-packages/requests/sessions.py", line 589, in request
    resp = self.send(prep, **send_kwargs)
  File "/home/ubuntu/.local/lib/python3.10/site-packages/requests/sessions.py", line 703, in send
    r = adapter.send(request, **kwargs)
  File "/home/ubuntu/.local/lib/python3.10/site-packages/requests/adapters.py", line 486, in send
    resp = conn.urlopen(
  File "/home/ubuntu/.local/lib/python3.10/site-packages/urllib3/connectionpool.py", line 715, in urlopen
    httplib_response = self._make_request(
  File "/home/ubuntu/.local/lib/python3.10/site-packages/urllib3/connectionpool.py", line 404, in _make_request
    self._validate_conn(conn)
  File "/home/ubuntu/.local/lib/python3.10/site-packages/urllib3/connectionpool.py", line 1058, in _validate_conn
    conn.connect()
  File "/home/ubuntu/.local/lib/python3.10/site-packages/urllib3/connection.py", line 419, in connect
    self.sock = ssl_wrap_socket(
  File "/home/ubuntu/.local/lib/python3.10/site-packages/urllib3/util/ssl_.py", line 402, in ssl_wrap_socket
    context.load_verify_locations(ca_certs, ca_cert_dir, ca_cert_data)
  File "/home/ubuntu/.local/lib/python3.10/site-packages/airflow/utils/timeout.py", line 69, in handle_timeout
    raise AirflowTaskTimeout(self.error_message)
airflow.exceptions.AirflowTaskTimeout: DagBag import timeout for /home/ubuntu/airflow/dags/my_dag.py after 30.0s.
Please take a look at these docs to improve your DAG import time:
* https://airflow.apache.org/docs/apache-airflow/2.8.0/best-practices.html#top-level-python-code
* https://airflow.apache.org/docs/apache-airflow/2.8.0/best-practices.html#reducing-dag-complexity, PID: 4809
[2024-01-21T12:17:35.526+0100] {processor.py:842} WARNING - No viable dags retrieved from /home/ubuntu/airflow/dags/my_dag.py
[2024-01-21T12:17:35.561+0100] {processor.py:183} INFO - Processing /home/ubuntu/airflow/dags/my_dag.py took 30.157 seconds
[2024-01-21T12:18:12.821+0100] {processor.py:161} INFO - Started process (PID=4846) to work on /home/ubuntu/airflow/dags/my_dag.py
[2024-01-21T12:18:12.824+0100] {processor.py:830} INFO - Processing file /home/ubuntu/airflow/dags/my_dag.py for tasks to queue
[2024-01-21T12:18:12.826+0100] {logging_mixin.py:188} INFO - [2024-01-21T12:18:12.825+0100] {dagbag.py:538} INFO - Filling up the DagBag from /home/ubuntu/airflow/dags/my_dag.py
[2024-01-21T12:18:33.151+0100] {logging_mixin.py:188} INFO - [2024-01-21T12:18:33.138+0100] {dagbag.py:348} ERROR - Failed to import: /home/ubuntu/airflow/dags/my_dag.py
Traceback (most recent call last):
  File "/home/ubuntu/.local/lib/python3.10/site-packages/urllib3/connection.py", line 174, in _new_conn
    conn = connection.create_connection(
  File "/home/ubuntu/.local/lib/python3.10/site-packages/urllib3/util/connection.py", line 72, in create_connection
    for res in socket.getaddrinfo(host, port, family, socket.SOCK_STREAM):
  File "/usr/lib/python3.10/socket.py", line 955, in getaddrinfo
    for res in _socket.getaddrinfo(host, port, family, type, proto, flags):
socket.gaierror: [Errno -3] Temporary failure in name resolution

During handling of the above exception, another exception occurred:

Traceback (most recent call last):
  File "/home/ubuntu/.local/lib/python3.10/site-packages/urllib3/connectionpool.py", line 715, in urlopen
    httplib_response = self._make_request(
  File "/home/ubuntu/.local/lib/python3.10/site-packages/urllib3/connectionpool.py", line 404, in _make_request
    self._validate_conn(conn)
  File "/home/ubuntu/.local/lib/python3.10/site-packages/urllib3/connectionpool.py", line 1058, in _validate_conn
    conn.connect()
  File "/home/ubuntu/.local/lib/python3.10/site-packages/urllib3/connection.py", line 363, in connect
    self.sock = conn = self._new_conn()
  File "/home/ubuntu/.local/lib/python3.10/site-packages/urllib3/connection.py", line 186, in _new_conn
    raise NewConnectionError(
urllib3.exceptions.NewConnectionError: <urllib3.connection.HTTPSConnection object at 0x7ff32a6c1f60>: Failed to establish a new connection: [Errno -3] Temporary failure in name resolution

During handling of the above exception, another exception occurred:

Traceback (most recent call last):
  File "/home/ubuntu/.local/lib/python3.10/site-packages/requests/adapters.py", line 486, in send
    resp = conn.urlopen(
  File "/home/ubuntu/.local/lib/python3.10/site-packages/urllib3/connectionpool.py", line 799, in urlopen
    retries = retries.increment(
  File "/home/ubuntu/.local/lib/python3.10/site-packages/urllib3/util/retry.py", line 592, in increment
    raise MaxRetryError(_pool, url, error or ResponseError(cause))
urllib3.exceptions.MaxRetryError: HTTPSConnectionPool(host='api.themoviedb.org', port=443): Max retries exceeded with url: /3/movie/popular?api_key=2c5a15136404a6eb67a3b4498cb2b4b8&page=1 (Caused by NewConnectionError('<urllib3.connection.HTTPSConnection object at 0x7ff32a6c1f60>: Failed to establish a new connection: [Errno -3] Temporary failure in name resolution'))

During handling of the above exception, another exception occurred:

Traceback (most recent call last):
  File "/home/ubuntu/.local/lib/python3.10/site-packages/airflow/models/dagbag.py", line 344, in parse
    loader.exec_module(new_module)
  File "<frozen importlib._bootstrap_external>", line 883, in exec_module
  File "<frozen importlib._bootstrap>", line 241, in _call_with_frames_removed
  File "/home/ubuntu/airflow/dags/my_dag.py", line 5, in <module>
    from movies import find_popular_movies_and_save, get_movie_genres
  File "/home/ubuntu/airflow/dags/movies.py", line 45, in <module>
    find_popular_movies_and_save()
  File "/home/ubuntu/airflow/dags/movies.py", line 23, in find_popular_movies_and_save
    response = requests.get(base_url, params=params)
  File "/home/ubuntu/.local/lib/python3.10/site-packages/requests/api.py", line 73, in get
    return request("get", url, params=params, **kwargs)
  File "/home/ubuntu/.local/lib/python3.10/site-packages/requests/api.py", line 59, in request
    return session.request(method=method, url=url, **kwargs)
  File "/home/ubuntu/.local/lib/python3.10/site-packages/requests/sessions.py", line 589, in request
    resp = self.send(prep, **send_kwargs)
  File "/home/ubuntu/.local/lib/python3.10/site-packages/requests/sessions.py", line 703, in send
    r = adapter.send(request, **kwargs)
  File "/home/ubuntu/.local/lib/python3.10/site-packages/requests/adapters.py", line 519, in send
    raise ConnectionError(e, request=request)
requests.exceptions.ConnectionError: HTTPSConnectionPool(host='api.themoviedb.org', port=443): Max retries exceeded with url: /3/movie/popular?api_key=2c5a15136404a6eb67a3b4498cb2b4b8&page=1 (Caused by NewConnectionError('<urllib3.connection.HTTPSConnection object at 0x7ff32a6c1f60>: Failed to establish a new connection: [Errno -3] Temporary failure in name resolution'))
[2024-01-21T12:18:33.152+0100] {processor.py:842} WARNING - No viable dags retrieved from /home/ubuntu/airflow/dags/my_dag.py
[2024-01-21T12:18:33.196+0100] {processor.py:183} INFO - Processing /home/ubuntu/airflow/dags/my_dag.py took 20.382 seconds
[2024-01-21T12:19:10.546+0100] {processor.py:161} INFO - Started process (PID=4877) to work on /home/ubuntu/airflow/dags/my_dag.py
[2024-01-21T12:19:10.551+0100] {processor.py:830} INFO - Processing file /home/ubuntu/airflow/dags/my_dag.py for tasks to queue
[2024-01-21T12:19:10.553+0100] {logging_mixin.py:188} INFO - [2024-01-21T12:19:10.552+0100] {dagbag.py:538} INFO - Filling up the DagBag from /home/ubuntu/airflow/dags/my_dag.py
[2024-01-21T12:19:30.798+0100] {logging_mixin.py:188} INFO - [2024-01-21T12:19:30.787+0100] {dagbag.py:348} ERROR - Failed to import: /home/ubuntu/airflow/dags/my_dag.py
Traceback (most recent call last):
  File "/home/ubuntu/.local/lib/python3.10/site-packages/urllib3/connection.py", line 174, in _new_conn
    conn = connection.create_connection(
  File "/home/ubuntu/.local/lib/python3.10/site-packages/urllib3/util/connection.py", line 72, in create_connection
    for res in socket.getaddrinfo(host, port, family, socket.SOCK_STREAM):
  File "/usr/lib/python3.10/socket.py", line 955, in getaddrinfo
    for res in _socket.getaddrinfo(host, port, family, type, proto, flags):
socket.gaierror: [Errno -3] Temporary failure in name resolution

During handling of the above exception, another exception occurred:

Traceback (most recent call last):
  File "/home/ubuntu/.local/lib/python3.10/site-packages/urllib3/connectionpool.py", line 715, in urlopen
    httplib_response = self._make_request(
  File "/home/ubuntu/.local/lib/python3.10/site-packages/urllib3/connectionpool.py", line 404, in _make_request
    self._validate_conn(conn)
  File "/home/ubuntu/.local/lib/python3.10/site-packages/urllib3/connectionpool.py", line 1058, in _validate_conn
    conn.connect()
  File "/home/ubuntu/.local/lib/python3.10/site-packages/urllib3/connection.py", line 363, in connect
    self.sock = conn = self._new_conn()
  File "/home/ubuntu/.local/lib/python3.10/site-packages/urllib3/connection.py", line 186, in _new_conn
    raise NewConnectionError(
urllib3.exceptions.NewConnectionError: <urllib3.connection.HTTPSConnection object at 0x7ff32a6c1fc0>: Failed to establish a new connection: [Errno -3] Temporary failure in name resolution

During handling of the above exception, another exception occurred:

Traceback (most recent call last):
  File "/home/ubuntu/.local/lib/python3.10/site-packages/requests/adapters.py", line 486, in send
    resp = conn.urlopen(
  File "/home/ubuntu/.local/lib/python3.10/site-packages/urllib3/connectionpool.py", line 799, in urlopen
    retries = retries.increment(
  File "/home/ubuntu/.local/lib/python3.10/site-packages/urllib3/util/retry.py", line 592, in increment
    raise MaxRetryError(_pool, url, error or ResponseError(cause))
urllib3.exceptions.MaxRetryError: HTTPSConnectionPool(host='api.themoviedb.org', port=443): Max retries exceeded with url: /3/movie/popular?api_key=2c5a15136404a6eb67a3b4498cb2b4b8&page=1 (Caused by NewConnectionError('<urllib3.connection.HTTPSConnection object at 0x7ff32a6c1fc0>: Failed to establish a new connection: [Errno -3] Temporary failure in name resolution'))

During handling of the above exception, another exception occurred:

Traceback (most recent call last):
  File "/home/ubuntu/.local/lib/python3.10/site-packages/airflow/models/dagbag.py", line 344, in parse
    loader.exec_module(new_module)
  File "<frozen importlib._bootstrap_external>", line 883, in exec_module
  File "<frozen importlib._bootstrap>", line 241, in _call_with_frames_removed
  File "/home/ubuntu/airflow/dags/my_dag.py", line 5, in <module>
    from movies import find_popular_movies_and_save, get_movie_genres
  File "/home/ubuntu/airflow/dags/movies.py", line 45, in <module>
    find_popular_movies_and_save()
  File "/home/ubuntu/airflow/dags/movies.py", line 23, in find_popular_movies_and_save
    response = requests.get(base_url, params=params)
  File "/home/ubuntu/.local/lib/python3.10/site-packages/requests/api.py", line 73, in get
    return request("get", url, params=params, **kwargs)
  File "/home/ubuntu/.local/lib/python3.10/site-packages/requests/api.py", line 59, in request
    return session.request(method=method, url=url, **kwargs)
  File "/home/ubuntu/.local/lib/python3.10/site-packages/requests/sessions.py", line 589, in request
    resp = self.send(prep, **send_kwargs)
  File "/home/ubuntu/.local/lib/python3.10/site-packages/requests/sessions.py", line 703, in send
    r = adapter.send(request, **kwargs)
  File "/home/ubuntu/.local/lib/python3.10/site-packages/requests/adapters.py", line 519, in send
    raise ConnectionError(e, request=request)
requests.exceptions.ConnectionError: HTTPSConnectionPool(host='api.themoviedb.org', port=443): Max retries exceeded with url: /3/movie/popular?api_key=2c5a15136404a6eb67a3b4498cb2b4b8&page=1 (Caused by NewConnectionError('<urllib3.connection.HTTPSConnection object at 0x7ff32a6c1fc0>: Failed to establish a new connection: [Errno -3] Temporary failure in name resolution'))
[2024-01-21T12:19:30.801+0100] {processor.py:842} WARNING - No viable dags retrieved from /home/ubuntu/airflow/dags/my_dag.py
[2024-01-21T12:19:30.866+0100] {processor.py:183} INFO - Processing /home/ubuntu/airflow/dags/my_dag.py took 20.332 seconds
[2024-01-21T12:20:06.058+0100] {processor.py:161} INFO - Started process (PID=4908) to work on /home/ubuntu/airflow/dags/my_dag.py
[2024-01-21T12:20:06.063+0100] {processor.py:830} INFO - Processing file /home/ubuntu/airflow/dags/my_dag.py for tasks to queue
[2024-01-21T12:20:06.066+0100] {logging_mixin.py:188} INFO - [2024-01-21T12:20:06.065+0100] {dagbag.py:538} INFO - Filling up the DagBag from /home/ubuntu/airflow/dags/my_dag.py
[2024-01-21T12:20:26.311+0100] {logging_mixin.py:188} INFO - [2024-01-21T12:20:26.282+0100] {dagbag.py:348} ERROR - Failed to import: /home/ubuntu/airflow/dags/my_dag.py
Traceback (most recent call last):
  File "/home/ubuntu/.local/lib/python3.10/site-packages/urllib3/connection.py", line 174, in _new_conn
    conn = connection.create_connection(
  File "/home/ubuntu/.local/lib/python3.10/site-packages/urllib3/util/connection.py", line 72, in create_connection
    for res in socket.getaddrinfo(host, port, family, socket.SOCK_STREAM):
  File "/usr/lib/python3.10/socket.py", line 955, in getaddrinfo
    for res in _socket.getaddrinfo(host, port, family, type, proto, flags):
socket.gaierror: [Errno -3] Temporary failure in name resolution

During handling of the above exception, another exception occurred:

Traceback (most recent call last):
  File "/home/ubuntu/.local/lib/python3.10/site-packages/urllib3/connectionpool.py", line 715, in urlopen
    httplib_response = self._make_request(
  File "/home/ubuntu/.local/lib/python3.10/site-packages/urllib3/connectionpool.py", line 404, in _make_request
    self._validate_conn(conn)
  File "/home/ubuntu/.local/lib/python3.10/site-packages/urllib3/connectionpool.py", line 1058, in _validate_conn
    conn.connect()
  File "/home/ubuntu/.local/lib/python3.10/site-packages/urllib3/connection.py", line 363, in connect
    self.sock = conn = self._new_conn()
  File "/home/ubuntu/.local/lib/python3.10/site-packages/urllib3/connection.py", line 186, in _new_conn
    raise NewConnectionError(
urllib3.exceptions.NewConnectionError: <urllib3.connection.HTTPSConnection object at 0x7ff32a6bdfc0>: Failed to establish a new connection: [Errno -3] Temporary failure in name resolution

During handling of the above exception, another exception occurred:

Traceback (most recent call last):
  File "/home/ubuntu/.local/lib/python3.10/site-packages/requests/adapters.py", line 486, in send
    resp = conn.urlopen(
  File "/home/ubuntu/.local/lib/python3.10/site-packages/urllib3/connectionpool.py", line 799, in urlopen
    retries = retries.increment(
  File "/home/ubuntu/.local/lib/python3.10/site-packages/urllib3/util/retry.py", line 592, in increment
    raise MaxRetryError(_pool, url, error or ResponseError(cause))
urllib3.exceptions.MaxRetryError: HTTPSConnectionPool(host='api.themoviedb.org', port=443): Max retries exceeded with url: /3/movie/popular?api_key=2c5a15136404a6eb67a3b4498cb2b4b8&page=1 (Caused by NewConnectionError('<urllib3.connection.HTTPSConnection object at 0x7ff32a6bdfc0>: Failed to establish a new connection: [Errno -3] Temporary failure in name resolution'))

During handling of the above exception, another exception occurred:

Traceback (most recent call last):
  File "/home/ubuntu/.local/lib/python3.10/site-packages/airflow/models/dagbag.py", line 344, in parse
    loader.exec_module(new_module)
  File "<frozen importlib._bootstrap_external>", line 883, in exec_module
  File "<frozen importlib._bootstrap>", line 241, in _call_with_frames_removed
  File "/home/ubuntu/airflow/dags/my_dag.py", line 5, in <module>
    from movies import find_popular_movies_and_save, get_movie_genres
  File "/home/ubuntu/airflow/dags/movies.py", line 45, in <module>
    find_popular_movies_and_save()
  File "/home/ubuntu/airflow/dags/movies.py", line 23, in find_popular_movies_and_save
    response = requests.get(base_url, params=params)
  File "/home/ubuntu/.local/lib/python3.10/site-packages/requests/api.py", line 73, in get
    return request("get", url, params=params, **kwargs)
  File "/home/ubuntu/.local/lib/python3.10/site-packages/requests/api.py", line 59, in request
    return session.request(method=method, url=url, **kwargs)
  File "/home/ubuntu/.local/lib/python3.10/site-packages/requests/sessions.py", line 589, in request
    resp = self.send(prep, **send_kwargs)
  File "/home/ubuntu/.local/lib/python3.10/site-packages/requests/sessions.py", line 703, in send
    r = adapter.send(request, **kwargs)
  File "/home/ubuntu/.local/lib/python3.10/site-packages/requests/adapters.py", line 519, in send
    raise ConnectionError(e, request=request)
requests.exceptions.ConnectionError: HTTPSConnectionPool(host='api.themoviedb.org', port=443): Max retries exceeded with url: /3/movie/popular?api_key=2c5a15136404a6eb67a3b4498cb2b4b8&page=1 (Caused by NewConnectionError('<urllib3.connection.HTTPSConnection object at 0x7ff32a6bdfc0>: Failed to establish a new connection: [Errno -3] Temporary failure in name resolution'))
[2024-01-21T12:20:26.315+0100] {processor.py:842} WARNING - No viable dags retrieved from /home/ubuntu/airflow/dags/my_dag.py
[2024-01-21T12:20:26.355+0100] {processor.py:183} INFO - Processing /home/ubuntu/airflow/dags/my_dag.py took 20.303 seconds
[2024-01-21T12:20:58.495+0100] {processor.py:161} INFO - Started process (PID=4939) to work on /home/ubuntu/airflow/dags/my_dag.py
[2024-01-21T12:20:58.503+0100] {processor.py:830} INFO - Processing file /home/ubuntu/airflow/dags/my_dag.py for tasks to queue
[2024-01-21T12:20:58.505+0100] {logging_mixin.py:188} INFO - [2024-01-21T12:20:58.504+0100] {dagbag.py:538} INFO - Filling up the DagBag from /home/ubuntu/airflow/dags/my_dag.py
[2024-01-21T12:21:18.723+0100] {logging_mixin.py:188} INFO - [2024-01-21T12:21:18.703+0100] {dagbag.py:348} ERROR - Failed to import: /home/ubuntu/airflow/dags/my_dag.py
Traceback (most recent call last):
  File "/home/ubuntu/.local/lib/python3.10/site-packages/urllib3/connection.py", line 174, in _new_conn
    conn = connection.create_connection(
  File "/home/ubuntu/.local/lib/python3.10/site-packages/urllib3/util/connection.py", line 72, in create_connection
    for res in socket.getaddrinfo(host, port, family, socket.SOCK_STREAM):
  File "/usr/lib/python3.10/socket.py", line 955, in getaddrinfo
    for res in _socket.getaddrinfo(host, port, family, type, proto, flags):
socket.gaierror: [Errno -3] Temporary failure in name resolution

During handling of the above exception, another exception occurred:

Traceback (most recent call last):
  File "/home/ubuntu/.local/lib/python3.10/site-packages/urllib3/connectionpool.py", line 715, in urlopen
    httplib_response = self._make_request(
  File "/home/ubuntu/.local/lib/python3.10/site-packages/urllib3/connectionpool.py", line 404, in _make_request
    self._validate_conn(conn)
  File "/home/ubuntu/.local/lib/python3.10/site-packages/urllib3/connectionpool.py", line 1058, in _validate_conn
    conn.connect()
  File "/home/ubuntu/.local/lib/python3.10/site-packages/urllib3/connection.py", line 363, in connect
    self.sock = conn = self._new_conn()
  File "/home/ubuntu/.local/lib/python3.10/site-packages/urllib3/connection.py", line 186, in _new_conn
    raise NewConnectionError(
urllib3.exceptions.NewConnectionError: <urllib3.connection.HTTPSConnection object at 0x7ff32a6c1fc0>: Failed to establish a new connection: [Errno -3] Temporary failure in name resolution

During handling of the above exception, another exception occurred:

Traceback (most recent call last):
  File "/home/ubuntu/.local/lib/python3.10/site-packages/requests/adapters.py", line 486, in send
    resp = conn.urlopen(
  File "/home/ubuntu/.local/lib/python3.10/site-packages/urllib3/connectionpool.py", line 799, in urlopen
    retries = retries.increment(
  File "/home/ubuntu/.local/lib/python3.10/site-packages/urllib3/util/retry.py", line 592, in increment
    raise MaxRetryError(_pool, url, error or ResponseError(cause))
urllib3.exceptions.MaxRetryError: HTTPSConnectionPool(host='api.themoviedb.org', port=443): Max retries exceeded with url: /3/movie/popular?api_key=2c5a15136404a6eb67a3b4498cb2b4b8&page=1 (Caused by NewConnectionError('<urllib3.connection.HTTPSConnection object at 0x7ff32a6c1fc0>: Failed to establish a new connection: [Errno -3] Temporary failure in name resolution'))

During handling of the above exception, another exception occurred:

Traceback (most recent call last):
  File "/home/ubuntu/.local/lib/python3.10/site-packages/airflow/models/dagbag.py", line 344, in parse
    loader.exec_module(new_module)
  File "<frozen importlib._bootstrap_external>", line 883, in exec_module
  File "<frozen importlib._bootstrap>", line 241, in _call_with_frames_removed
  File "/home/ubuntu/airflow/dags/my_dag.py", line 5, in <module>
    from movies import find_popular_movies_and_save, get_movie_genres
  File "/home/ubuntu/airflow/dags/movies.py", line 45, in <module>
    find_popular_movies_and_save()
  File "/home/ubuntu/airflow/dags/movies.py", line 23, in find_popular_movies_and_save
    response = requests.get(base_url, params=params)
  File "/home/ubuntu/.local/lib/python3.10/site-packages/requests/api.py", line 73, in get
    return request("get", url, params=params, **kwargs)
  File "/home/ubuntu/.local/lib/python3.10/site-packages/requests/api.py", line 59, in request
    return session.request(method=method, url=url, **kwargs)
  File "/home/ubuntu/.local/lib/python3.10/site-packages/requests/sessions.py", line 589, in request
    resp = self.send(prep, **send_kwargs)
  File "/home/ubuntu/.local/lib/python3.10/site-packages/requests/sessions.py", line 703, in send
    r = adapter.send(request, **kwargs)
  File "/home/ubuntu/.local/lib/python3.10/site-packages/requests/adapters.py", line 519, in send
    raise ConnectionError(e, request=request)
requests.exceptions.ConnectionError: HTTPSConnectionPool(host='api.themoviedb.org', port=443): Max retries exceeded with url: /3/movie/popular?api_key=2c5a15136404a6eb67a3b4498cb2b4b8&page=1 (Caused by NewConnectionError('<urllib3.connection.HTTPSConnection object at 0x7ff32a6c1fc0>: Failed to establish a new connection: [Errno -3] Temporary failure in name resolution'))
[2024-01-21T12:21:18.737+0100] {processor.py:842} WARNING - No viable dags retrieved from /home/ubuntu/airflow/dags/my_dag.py
[2024-01-21T12:21:18.781+0100] {processor.py:183} INFO - Processing /home/ubuntu/airflow/dags/my_dag.py took 20.297 seconds
[2024-01-21T12:21:50.730+0100] {processor.py:161} INFO - Started process (PID=4970) to work on /home/ubuntu/airflow/dags/my_dag.py
[2024-01-21T12:21:50.740+0100] {processor.py:830} INFO - Processing file /home/ubuntu/airflow/dags/my_dag.py for tasks to queue
[2024-01-21T12:21:50.745+0100] {logging_mixin.py:188} INFO - [2024-01-21T12:21:50.743+0100] {dagbag.py:538} INFO - Filling up the DagBag from /home/ubuntu/airflow/dags/my_dag.py
[2024-01-21T12:22:11.149+0100] {logging_mixin.py:188} INFO - [2024-01-21T12:22:11.111+0100] {dagbag.py:348} ERROR - Failed to import: /home/ubuntu/airflow/dags/my_dag.py
Traceback (most recent call last):
  File "/home/ubuntu/.local/lib/python3.10/site-packages/urllib3/connection.py", line 174, in _new_conn
    conn = connection.create_connection(
  File "/home/ubuntu/.local/lib/python3.10/site-packages/urllib3/util/connection.py", line 72, in create_connection
    for res in socket.getaddrinfo(host, port, family, socket.SOCK_STREAM):
  File "/usr/lib/python3.10/socket.py", line 955, in getaddrinfo
    for res in _socket.getaddrinfo(host, port, family, type, proto, flags):
socket.gaierror: [Errno -3] Temporary failure in name resolution

During handling of the above exception, another exception occurred:

Traceback (most recent call last):
  File "/home/ubuntu/.local/lib/python3.10/site-packages/urllib3/connectionpool.py", line 715, in urlopen
    httplib_response = self._make_request(
  File "/home/ubuntu/.local/lib/python3.10/site-packages/urllib3/connectionpool.py", line 404, in _make_request
    self._validate_conn(conn)
  File "/home/ubuntu/.local/lib/python3.10/site-packages/urllib3/connectionpool.py", line 1058, in _validate_conn
    conn.connect()
  File "/home/ubuntu/.local/lib/python3.10/site-packages/urllib3/connection.py", line 363, in connect
    self.sock = conn = self._new_conn()
  File "/home/ubuntu/.local/lib/python3.10/site-packages/urllib3/connection.py", line 186, in _new_conn
    raise NewConnectionError(
urllib3.exceptions.NewConnectionError: <urllib3.connection.HTTPSConnection object at 0x7ff32a6bdff0>: Failed to establish a new connection: [Errno -3] Temporary failure in name resolution

During handling of the above exception, another exception occurred:

Traceback (most recent call last):
  File "/home/ubuntu/.local/lib/python3.10/site-packages/requests/adapters.py", line 486, in send
    resp = conn.urlopen(
  File "/home/ubuntu/.local/lib/python3.10/site-packages/urllib3/connectionpool.py", line 799, in urlopen
    retries = retries.increment(
  File "/home/ubuntu/.local/lib/python3.10/site-packages/urllib3/util/retry.py", line 592, in increment
    raise MaxRetryError(_pool, url, error or ResponseError(cause))
urllib3.exceptions.MaxRetryError: HTTPSConnectionPool(host='api.themoviedb.org', port=443): Max retries exceeded with url: /3/movie/popular?api_key=2c5a15136404a6eb67a3b4498cb2b4b8&page=1 (Caused by NewConnectionError('<urllib3.connection.HTTPSConnection object at 0x7ff32a6bdff0>: Failed to establish a new connection: [Errno -3] Temporary failure in name resolution'))

During handling of the above exception, another exception occurred:

Traceback (most recent call last):
  File "/home/ubuntu/.local/lib/python3.10/site-packages/airflow/models/dagbag.py", line 344, in parse
    loader.exec_module(new_module)
  File "<frozen importlib._bootstrap_external>", line 883, in exec_module
  File "<frozen importlib._bootstrap>", line 241, in _call_with_frames_removed
  File "/home/ubuntu/airflow/dags/my_dag.py", line 5, in <module>
    from movies import find_popular_movies_and_save, get_movie_genres
  File "/home/ubuntu/airflow/dags/movies.py", line 45, in <module>
    find_popular_movies_and_save()
  File "/home/ubuntu/airflow/dags/movies.py", line 23, in find_popular_movies_and_save
    response = requests.get(base_url, params=params)
  File "/home/ubuntu/.local/lib/python3.10/site-packages/requests/api.py", line 73, in get
    return request("get", url, params=params, **kwargs)
  File "/home/ubuntu/.local/lib/python3.10/site-packages/requests/api.py", line 59, in request
    return session.request(method=method, url=url, **kwargs)
  File "/home/ubuntu/.local/lib/python3.10/site-packages/requests/sessions.py", line 589, in request
    resp = self.send(prep, **send_kwargs)
  File "/home/ubuntu/.local/lib/python3.10/site-packages/requests/sessions.py", line 703, in send
    r = adapter.send(request, **kwargs)
  File "/home/ubuntu/.local/lib/python3.10/site-packages/requests/adapters.py", line 519, in send
    raise ConnectionError(e, request=request)
requests.exceptions.ConnectionError: HTTPSConnectionPool(host='api.themoviedb.org', port=443): Max retries exceeded with url: /3/movie/popular?api_key=2c5a15136404a6eb67a3b4498cb2b4b8&page=1 (Caused by NewConnectionError('<urllib3.connection.HTTPSConnection object at 0x7ff32a6bdff0>: Failed to establish a new connection: [Errno -3] Temporary failure in name resolution'))
[2024-01-21T12:22:11.168+0100] {processor.py:842} WARNING - No viable dags retrieved from /home/ubuntu/airflow/dags/my_dag.py
[2024-01-21T12:22:11.216+0100] {processor.py:183} INFO - Processing /home/ubuntu/airflow/dags/my_dag.py took 20.494 seconds
[2024-01-21T12:22:45.849+0100] {processor.py:161} INFO - Started process (PID=5021) to work on /home/ubuntu/airflow/dags/my_dag.py
[2024-01-21T12:22:45.852+0100] {processor.py:830} INFO - Processing file /home/ubuntu/airflow/dags/my_dag.py for tasks to queue
[2024-01-21T12:22:45.853+0100] {logging_mixin.py:188} INFO - [2024-01-21T12:22:45.853+0100] {dagbag.py:538} INFO - Filling up the DagBag from /home/ubuntu/airflow/dags/my_dag.py
[2024-01-21T12:23:06.084+0100] {logging_mixin.py:188} INFO - [2024-01-21T12:23:06.051+0100] {dagbag.py:348} ERROR - Failed to import: /home/ubuntu/airflow/dags/my_dag.py
Traceback (most recent call last):
  File "/home/ubuntu/.local/lib/python3.10/site-packages/urllib3/connection.py", line 174, in _new_conn
    conn = connection.create_connection(
  File "/home/ubuntu/.local/lib/python3.10/site-packages/urllib3/util/connection.py", line 72, in create_connection
    for res in socket.getaddrinfo(host, port, family, socket.SOCK_STREAM):
  File "/usr/lib/python3.10/socket.py", line 955, in getaddrinfo
    for res in _socket.getaddrinfo(host, port, family, type, proto, flags):
socket.gaierror: [Errno -3] Temporary failure in name resolution

During handling of the above exception, another exception occurred:

Traceback (most recent call last):
  File "/home/ubuntu/.local/lib/python3.10/site-packages/urllib3/connectionpool.py", line 715, in urlopen
    httplib_response = self._make_request(
  File "/home/ubuntu/.local/lib/python3.10/site-packages/urllib3/connectionpool.py", line 404, in _make_request
    self._validate_conn(conn)
  File "/home/ubuntu/.local/lib/python3.10/site-packages/urllib3/connectionpool.py", line 1058, in _validate_conn
    conn.connect()
  File "/home/ubuntu/.local/lib/python3.10/site-packages/urllib3/connection.py", line 363, in connect
    self.sock = conn = self._new_conn()
  File "/home/ubuntu/.local/lib/python3.10/site-packages/urllib3/connection.py", line 186, in _new_conn
    raise NewConnectionError(
urllib3.exceptions.NewConnectionError: <urllib3.connection.HTTPSConnection object at 0x7ff32a6be0b0>: Failed to establish a new connection: [Errno -3] Temporary failure in name resolution

During handling of the above exception, another exception occurred:

Traceback (most recent call last):
  File "/home/ubuntu/.local/lib/python3.10/site-packages/requests/adapters.py", line 486, in send
    resp = conn.urlopen(
  File "/home/ubuntu/.local/lib/python3.10/site-packages/urllib3/connectionpool.py", line 799, in urlopen
    retries = retries.increment(
  File "/home/ubuntu/.local/lib/python3.10/site-packages/urllib3/util/retry.py", line 592, in increment
    raise MaxRetryError(_pool, url, error or ResponseError(cause))
urllib3.exceptions.MaxRetryError: HTTPSConnectionPool(host='api.themoviedb.org', port=443): Max retries exceeded with url: /3/movie/popular?api_key=2c5a15136404a6eb67a3b4498cb2b4b8&page=1 (Caused by NewConnectionError('<urllib3.connection.HTTPSConnection object at 0x7ff32a6be0b0>: Failed to establish a new connection: [Errno -3] Temporary failure in name resolution'))

During handling of the above exception, another exception occurred:

Traceback (most recent call last):
  File "/home/ubuntu/.local/lib/python3.10/site-packages/airflow/models/dagbag.py", line 344, in parse
    loader.exec_module(new_module)
  File "<frozen importlib._bootstrap_external>", line 883, in exec_module
  File "<frozen importlib._bootstrap>", line 241, in _call_with_frames_removed
  File "/home/ubuntu/airflow/dags/my_dag.py", line 5, in <module>
    from movies import find_popular_movies_and_save, get_movie_genres
  File "/home/ubuntu/airflow/dags/movies.py", line 45, in <module>
    find_popular_movies_and_save()
  File "/home/ubuntu/airflow/dags/movies.py", line 23, in find_popular_movies_and_save
    response = requests.get(base_url, params=params)
  File "/home/ubuntu/.local/lib/python3.10/site-packages/requests/api.py", line 73, in get
    return request("get", url, params=params, **kwargs)
  File "/home/ubuntu/.local/lib/python3.10/site-packages/requests/api.py", line 59, in request
    return session.request(method=method, url=url, **kwargs)
  File "/home/ubuntu/.local/lib/python3.10/site-packages/requests/sessions.py", line 589, in request
    resp = self.send(prep, **send_kwargs)
  File "/home/ubuntu/.local/lib/python3.10/site-packages/requests/sessions.py", line 703, in send
    r = adapter.send(request, **kwargs)
  File "/home/ubuntu/.local/lib/python3.10/site-packages/requests/adapters.py", line 519, in send
    raise ConnectionError(e, request=request)
requests.exceptions.ConnectionError: HTTPSConnectionPool(host='api.themoviedb.org', port=443): Max retries exceeded with url: /3/movie/popular?api_key=2c5a15136404a6eb67a3b4498cb2b4b8&page=1 (Caused by NewConnectionError('<urllib3.connection.HTTPSConnection object at 0x7ff32a6be0b0>: Failed to establish a new connection: [Errno -3] Temporary failure in name resolution'))
[2024-01-21T12:23:06.090+0100] {processor.py:842} WARNING - No viable dags retrieved from /home/ubuntu/airflow/dags/my_dag.py
[2024-01-21T12:23:06.187+0100] {processor.py:183} INFO - Processing /home/ubuntu/airflow/dags/my_dag.py took 20.344 seconds
[2024-01-21T12:23:39.577+0100] {processor.py:161} INFO - Started process (PID=5058) to work on /home/ubuntu/airflow/dags/my_dag.py
[2024-01-21T12:23:39.582+0100] {processor.py:830} INFO - Processing file /home/ubuntu/airflow/dags/my_dag.py for tasks to queue
[2024-01-21T12:23:39.584+0100] {logging_mixin.py:188} INFO - [2024-01-21T12:23:39.583+0100] {dagbag.py:538} INFO - Filling up the DagBag from /home/ubuntu/airflow/dags/my_dag.py
[2024-01-21T12:23:59.815+0100] {logging_mixin.py:188} INFO - [2024-01-21T12:23:59.804+0100] {dagbag.py:348} ERROR - Failed to import: /home/ubuntu/airflow/dags/my_dag.py
Traceback (most recent call last):
  File "/home/ubuntu/.local/lib/python3.10/site-packages/urllib3/connection.py", line 174, in _new_conn
    conn = connection.create_connection(
  File "/home/ubuntu/.local/lib/python3.10/site-packages/urllib3/util/connection.py", line 72, in create_connection
    for res in socket.getaddrinfo(host, port, family, socket.SOCK_STREAM):
  File "/usr/lib/python3.10/socket.py", line 955, in getaddrinfo
    for res in _socket.getaddrinfo(host, port, family, type, proto, flags):
socket.gaierror: [Errno -3] Temporary failure in name resolution

During handling of the above exception, another exception occurred:

Traceback (most recent call last):
  File "/home/ubuntu/.local/lib/python3.10/site-packages/urllib3/connectionpool.py", line 715, in urlopen
    httplib_response = self._make_request(
  File "/home/ubuntu/.local/lib/python3.10/site-packages/urllib3/connectionpool.py", line 404, in _make_request
    self._validate_conn(conn)
  File "/home/ubuntu/.local/lib/python3.10/site-packages/urllib3/connectionpool.py", line 1058, in _validate_conn
    conn.connect()
  File "/home/ubuntu/.local/lib/python3.10/site-packages/urllib3/connection.py", line 363, in connect
    self.sock = conn = self._new_conn()
  File "/home/ubuntu/.local/lib/python3.10/site-packages/urllib3/connection.py", line 186, in _new_conn
    raise NewConnectionError(
urllib3.exceptions.NewConnectionError: <urllib3.connection.HTTPSConnection object at 0x7ff32a6ba0b0>: Failed to establish a new connection: [Errno -3] Temporary failure in name resolution

During handling of the above exception, another exception occurred:

Traceback (most recent call last):
  File "/home/ubuntu/.local/lib/python3.10/site-packages/requests/adapters.py", line 486, in send
    resp = conn.urlopen(
  File "/home/ubuntu/.local/lib/python3.10/site-packages/urllib3/connectionpool.py", line 799, in urlopen
    retries = retries.increment(
  File "/home/ubuntu/.local/lib/python3.10/site-packages/urllib3/util/retry.py", line 592, in increment
    raise MaxRetryError(_pool, url, error or ResponseError(cause))
urllib3.exceptions.MaxRetryError: HTTPSConnectionPool(host='api.themoviedb.org', port=443): Max retries exceeded with url: /3/movie/popular?api_key=2c5a15136404a6eb67a3b4498cb2b4b8&page=1 (Caused by NewConnectionError('<urllib3.connection.HTTPSConnection object at 0x7ff32a6ba0b0>: Failed to establish a new connection: [Errno -3] Temporary failure in name resolution'))

During handling of the above exception, another exception occurred:

Traceback (most recent call last):
  File "/home/ubuntu/.local/lib/python3.10/site-packages/airflow/models/dagbag.py", line 344, in parse
    loader.exec_module(new_module)
  File "<frozen importlib._bootstrap_external>", line 883, in exec_module
  File "<frozen importlib._bootstrap>", line 241, in _call_with_frames_removed
  File "/home/ubuntu/airflow/dags/my_dag.py", line 5, in <module>
    from movies import find_popular_movies_and_save, get_movie_genres
  File "/home/ubuntu/airflow/dags/movies.py", line 45, in <module>
    find_popular_movies_and_save()
  File "/home/ubuntu/airflow/dags/movies.py", line 23, in find_popular_movies_and_save
    response = requests.get(base_url, params=params)
  File "/home/ubuntu/.local/lib/python3.10/site-packages/requests/api.py", line 73, in get
    return request("get", url, params=params, **kwargs)
  File "/home/ubuntu/.local/lib/python3.10/site-packages/requests/api.py", line 59, in request
    return session.request(method=method, url=url, **kwargs)
  File "/home/ubuntu/.local/lib/python3.10/site-packages/requests/sessions.py", line 589, in request
    resp = self.send(prep, **send_kwargs)
  File "/home/ubuntu/.local/lib/python3.10/site-packages/requests/sessions.py", line 703, in send
    r = adapter.send(request, **kwargs)
  File "/home/ubuntu/.local/lib/python3.10/site-packages/requests/adapters.py", line 519, in send
    raise ConnectionError(e, request=request)
requests.exceptions.ConnectionError: HTTPSConnectionPool(host='api.themoviedb.org', port=443): Max retries exceeded with url: /3/movie/popular?api_key=2c5a15136404a6eb67a3b4498cb2b4b8&page=1 (Caused by NewConnectionError('<urllib3.connection.HTTPSConnection object at 0x7ff32a6ba0b0>: Failed to establish a new connection: [Errno -3] Temporary failure in name resolution'))
[2024-01-21T12:23:59.818+0100] {processor.py:842} WARNING - No viable dags retrieved from /home/ubuntu/airflow/dags/my_dag.py
[2024-01-21T12:23:59.854+0100] {processor.py:183} INFO - Processing /home/ubuntu/airflow/dags/my_dag.py took 20.285 seconds
[2024-01-21T12:24:30.497+0100] {processor.py:161} INFO - Started process (PID=5089) to work on /home/ubuntu/airflow/dags/my_dag.py
[2024-01-21T12:24:30.504+0100] {processor.py:830} INFO - Processing file /home/ubuntu/airflow/dags/my_dag.py for tasks to queue
[2024-01-21T12:24:30.506+0100] {logging_mixin.py:188} INFO - [2024-01-21T12:24:30.505+0100] {dagbag.py:538} INFO - Filling up the DagBag from /home/ubuntu/airflow/dags/my_dag.py
[2024-01-21T12:24:50.753+0100] {logging_mixin.py:188} INFO - [2024-01-21T12:24:50.744+0100] {dagbag.py:348} ERROR - Failed to import: /home/ubuntu/airflow/dags/my_dag.py
Traceback (most recent call last):
  File "/home/ubuntu/.local/lib/python3.10/site-packages/urllib3/connection.py", line 174, in _new_conn
    conn = connection.create_connection(
  File "/home/ubuntu/.local/lib/python3.10/site-packages/urllib3/util/connection.py", line 72, in create_connection
    for res in socket.getaddrinfo(host, port, family, socket.SOCK_STREAM):
  File "/usr/lib/python3.10/socket.py", line 955, in getaddrinfo
    for res in _socket.getaddrinfo(host, port, family, type, proto, flags):
socket.gaierror: [Errno -3] Temporary failure in name resolution

During handling of the above exception, another exception occurred:

Traceback (most recent call last):
  File "/home/ubuntu/.local/lib/python3.10/site-packages/urllib3/connectionpool.py", line 715, in urlopen
    httplib_response = self._make_request(
  File "/home/ubuntu/.local/lib/python3.10/site-packages/urllib3/connectionpool.py", line 404, in _make_request
    self._validate_conn(conn)
  File "/home/ubuntu/.local/lib/python3.10/site-packages/urllib3/connectionpool.py", line 1058, in _validate_conn
    conn.connect()
  File "/home/ubuntu/.local/lib/python3.10/site-packages/urllib3/connection.py", line 363, in connect
    self.sock = conn = self._new_conn()
  File "/home/ubuntu/.local/lib/python3.10/site-packages/urllib3/connection.py", line 186, in _new_conn
    raise NewConnectionError(
urllib3.exceptions.NewConnectionError: <urllib3.connection.HTTPSConnection object at 0x7ff32a6be0b0>: Failed to establish a new connection: [Errno -3] Temporary failure in name resolution

During handling of the above exception, another exception occurred:

Traceback (most recent call last):
  File "/home/ubuntu/.local/lib/python3.10/site-packages/requests/adapters.py", line 486, in send
    resp = conn.urlopen(
  File "/home/ubuntu/.local/lib/python3.10/site-packages/urllib3/connectionpool.py", line 799, in urlopen
    retries = retries.increment(
  File "/home/ubuntu/.local/lib/python3.10/site-packages/urllib3/util/retry.py", line 592, in increment
    raise MaxRetryError(_pool, url, error or ResponseError(cause))
urllib3.exceptions.MaxRetryError: HTTPSConnectionPool(host='api.themoviedb.org', port=443): Max retries exceeded with url: /3/movie/popular?api_key=2c5a15136404a6eb67a3b4498cb2b4b8&page=1 (Caused by NewConnectionError('<urllib3.connection.HTTPSConnection object at 0x7ff32a6be0b0>: Failed to establish a new connection: [Errno -3] Temporary failure in name resolution'))

During handling of the above exception, another exception occurred:

Traceback (most recent call last):
  File "/home/ubuntu/.local/lib/python3.10/site-packages/airflow/models/dagbag.py", line 344, in parse
    loader.exec_module(new_module)
  File "<frozen importlib._bootstrap_external>", line 883, in exec_module
  File "<frozen importlib._bootstrap>", line 241, in _call_with_frames_removed
  File "/home/ubuntu/airflow/dags/my_dag.py", line 5, in <module>
    from movies import find_popular_movies_and_save, get_movie_genres
  File "/home/ubuntu/airflow/dags/movies.py", line 45, in <module>
    find_popular_movies_and_save()
  File "/home/ubuntu/airflow/dags/movies.py", line 23, in find_popular_movies_and_save
    response = requests.get(base_url, params=params)
  File "/home/ubuntu/.local/lib/python3.10/site-packages/requests/api.py", line 73, in get
    return request("get", url, params=params, **kwargs)
  File "/home/ubuntu/.local/lib/python3.10/site-packages/requests/api.py", line 59, in request
    return session.request(method=method, url=url, **kwargs)
  File "/home/ubuntu/.local/lib/python3.10/site-packages/requests/sessions.py", line 589, in request
    resp = self.send(prep, **send_kwargs)
  File "/home/ubuntu/.local/lib/python3.10/site-packages/requests/sessions.py", line 703, in send
    r = adapter.send(request, **kwargs)
  File "/home/ubuntu/.local/lib/python3.10/site-packages/requests/adapters.py", line 519, in send
    raise ConnectionError(e, request=request)
requests.exceptions.ConnectionError: HTTPSConnectionPool(host='api.themoviedb.org', port=443): Max retries exceeded with url: /3/movie/popular?api_key=2c5a15136404a6eb67a3b4498cb2b4b8&page=1 (Caused by NewConnectionError('<urllib3.connection.HTTPSConnection object at 0x7ff32a6be0b0>: Failed to establish a new connection: [Errno -3] Temporary failure in name resolution'))
[2024-01-21T12:24:50.756+0100] {processor.py:842} WARNING - No viable dags retrieved from /home/ubuntu/airflow/dags/my_dag.py
[2024-01-21T12:24:50.804+0100] {processor.py:183} INFO - Processing /home/ubuntu/airflow/dags/my_dag.py took 20.314 seconds
[2024-01-21T12:25:23.088+0100] {processor.py:161} INFO - Started process (PID=5121) to work on /home/ubuntu/airflow/dags/my_dag.py
[2024-01-21T12:25:23.093+0100] {processor.py:830} INFO - Processing file /home/ubuntu/airflow/dags/my_dag.py for tasks to queue
[2024-01-21T12:25:23.095+0100] {logging_mixin.py:188} INFO - [2024-01-21T12:25:23.094+0100] {dagbag.py:538} INFO - Filling up the DagBag from /home/ubuntu/airflow/dags/my_dag.py
[2024-01-21T12:25:43.344+0100] {logging_mixin.py:188} INFO - [2024-01-21T12:25:43.335+0100] {dagbag.py:348} ERROR - Failed to import: /home/ubuntu/airflow/dags/my_dag.py
Traceback (most recent call last):
  File "/home/ubuntu/.local/lib/python3.10/site-packages/urllib3/connection.py", line 174, in _new_conn
    conn = connection.create_connection(
  File "/home/ubuntu/.local/lib/python3.10/site-packages/urllib3/util/connection.py", line 72, in create_connection
    for res in socket.getaddrinfo(host, port, family, socket.SOCK_STREAM):
  File "/usr/lib/python3.10/socket.py", line 955, in getaddrinfo
    for res in _socket.getaddrinfo(host, port, family, type, proto, flags):
socket.gaierror: [Errno -3] Temporary failure in name resolution

During handling of the above exception, another exception occurred:

Traceback (most recent call last):
  File "/home/ubuntu/.local/lib/python3.10/site-packages/urllib3/connectionpool.py", line 715, in urlopen
    httplib_response = self._make_request(
  File "/home/ubuntu/.local/lib/python3.10/site-packages/urllib3/connectionpool.py", line 404, in _make_request
    self._validate_conn(conn)
  File "/home/ubuntu/.local/lib/python3.10/site-packages/urllib3/connectionpool.py", line 1058, in _validate_conn
    conn.connect()
  File "/home/ubuntu/.local/lib/python3.10/site-packages/urllib3/connection.py", line 363, in connect
    self.sock = conn = self._new_conn()
  File "/home/ubuntu/.local/lib/python3.10/site-packages/urllib3/connection.py", line 186, in _new_conn
    raise NewConnectionError(
urllib3.exceptions.NewConnectionError: <urllib3.connection.HTTPSConnection object at 0x7ff32a6be0b0>: Failed to establish a new connection: [Errno -3] Temporary failure in name resolution

During handling of the above exception, another exception occurred:

Traceback (most recent call last):
  File "/home/ubuntu/.local/lib/python3.10/site-packages/requests/adapters.py", line 486, in send
    resp = conn.urlopen(
  File "/home/ubuntu/.local/lib/python3.10/site-packages/urllib3/connectionpool.py", line 799, in urlopen
    retries = retries.increment(
  File "/home/ubuntu/.local/lib/python3.10/site-packages/urllib3/util/retry.py", line 592, in increment
    raise MaxRetryError(_pool, url, error or ResponseError(cause))
urllib3.exceptions.MaxRetryError: HTTPSConnectionPool(host='api.themoviedb.org', port=443): Max retries exceeded with url: /3/movie/popular?api_key=2c5a15136404a6eb67a3b4498cb2b4b8&page=1 (Caused by NewConnectionError('<urllib3.connection.HTTPSConnection object at 0x7ff32a6be0b0>: Failed to establish a new connection: [Errno -3] Temporary failure in name resolution'))

During handling of the above exception, another exception occurred:

Traceback (most recent call last):
  File "/home/ubuntu/.local/lib/python3.10/site-packages/airflow/models/dagbag.py", line 344, in parse
    loader.exec_module(new_module)
  File "<frozen importlib._bootstrap_external>", line 883, in exec_module
  File "<frozen importlib._bootstrap>", line 241, in _call_with_frames_removed
  File "/home/ubuntu/airflow/dags/my_dag.py", line 5, in <module>
    from movies import find_popular_movies_and_save, get_movie_genres
  File "/home/ubuntu/airflow/dags/movies.py", line 45, in <module>
    find_popular_movies_and_save()
  File "/home/ubuntu/airflow/dags/movies.py", line 23, in find_popular_movies_and_save
    response = requests.get(base_url, params=params)
  File "/home/ubuntu/.local/lib/python3.10/site-packages/requests/api.py", line 73, in get
    return request("get", url, params=params, **kwargs)
  File "/home/ubuntu/.local/lib/python3.10/site-packages/requests/api.py", line 59, in request
    return session.request(method=method, url=url, **kwargs)
  File "/home/ubuntu/.local/lib/python3.10/site-packages/requests/sessions.py", line 589, in request
    resp = self.send(prep, **send_kwargs)
  File "/home/ubuntu/.local/lib/python3.10/site-packages/requests/sessions.py", line 703, in send
    r = adapter.send(request, **kwargs)
  File "/home/ubuntu/.local/lib/python3.10/site-packages/requests/adapters.py", line 519, in send
    raise ConnectionError(e, request=request)
requests.exceptions.ConnectionError: HTTPSConnectionPool(host='api.themoviedb.org', port=443): Max retries exceeded with url: /3/movie/popular?api_key=2c5a15136404a6eb67a3b4498cb2b4b8&page=1 (Caused by NewConnectionError('<urllib3.connection.HTTPSConnection object at 0x7ff32a6be0b0>: Failed to establish a new connection: [Errno -3] Temporary failure in name resolution'))
[2024-01-21T12:25:43.346+0100] {processor.py:842} WARNING - No viable dags retrieved from /home/ubuntu/airflow/dags/my_dag.py
[2024-01-21T12:25:43.396+0100] {processor.py:183} INFO - Processing /home/ubuntu/airflow/dags/my_dag.py took 20.314 seconds
[2024-01-21T12:26:30.572+0100] {processor.py:161} INFO - Started process (PID=5243) to work on /home/ubuntu/airflow/dags/my_dag.py
[2024-01-21T12:26:30.579+0100] {processor.py:830} INFO - Processing file /home/ubuntu/airflow/dags/my_dag.py for tasks to queue
[2024-01-21T12:26:30.581+0100] {logging_mixin.py:188} INFO - [2024-01-21T12:26:30.580+0100] {dagbag.py:538} INFO - Filling up the DagBag from /home/ubuntu/airflow/dags/my_dag.py
[2024-01-21T12:26:51.134+0100] {logging_mixin.py:188} INFO - [2024-01-21T12:26:51.091+0100] {dagbag.py:348} ERROR - Failed to import: /home/ubuntu/airflow/dags/my_dag.py
Traceback (most recent call last):
  File "/home/ubuntu/.local/lib/python3.10/site-packages/urllib3/connection.py", line 174, in _new_conn
    conn = connection.create_connection(
  File "/home/ubuntu/.local/lib/python3.10/site-packages/urllib3/util/connection.py", line 72, in create_connection
    for res in socket.getaddrinfo(host, port, family, socket.SOCK_STREAM):
  File "/usr/lib/python3.10/socket.py", line 955, in getaddrinfo
    for res in _socket.getaddrinfo(host, port, family, type, proto, flags):
socket.gaierror: [Errno -3] Temporary failure in name resolution

During handling of the above exception, another exception occurred:

Traceback (most recent call last):
  File "/home/ubuntu/.local/lib/python3.10/site-packages/urllib3/connectionpool.py", line 715, in urlopen
    httplib_response = self._make_request(
  File "/home/ubuntu/.local/lib/python3.10/site-packages/urllib3/connectionpool.py", line 404, in _make_request
    self._validate_conn(conn)
  File "/home/ubuntu/.local/lib/python3.10/site-packages/urllib3/connectionpool.py", line 1058, in _validate_conn
    conn.connect()
  File "/home/ubuntu/.local/lib/python3.10/site-packages/urllib3/connection.py", line 363, in connect
    self.sock = conn = self._new_conn()
  File "/home/ubuntu/.local/lib/python3.10/site-packages/urllib3/connection.py", line 186, in _new_conn
    raise NewConnectionError(
urllib3.exceptions.NewConnectionError: <urllib3.connection.HTTPSConnection object at 0x7ff32a6be0b0>: Failed to establish a new connection: [Errno -3] Temporary failure in name resolution

During handling of the above exception, another exception occurred:

Traceback (most recent call last):
  File "/home/ubuntu/.local/lib/python3.10/site-packages/requests/adapters.py", line 486, in send
    resp = conn.urlopen(
  File "/home/ubuntu/.local/lib/python3.10/site-packages/urllib3/connectionpool.py", line 799, in urlopen
    retries = retries.increment(
  File "/home/ubuntu/.local/lib/python3.10/site-packages/urllib3/util/retry.py", line 592, in increment
    raise MaxRetryError(_pool, url, error or ResponseError(cause))
urllib3.exceptions.MaxRetryError: HTTPSConnectionPool(host='api.themoviedb.org', port=443): Max retries exceeded with url: /3/movie/popular?api_key=2c5a15136404a6eb67a3b4498cb2b4b8&page=1 (Caused by NewConnectionError('<urllib3.connection.HTTPSConnection object at 0x7ff32a6be0b0>: Failed to establish a new connection: [Errno -3] Temporary failure in name resolution'))

During handling of the above exception, another exception occurred:

Traceback (most recent call last):
  File "/home/ubuntu/.local/lib/python3.10/site-packages/airflow/models/dagbag.py", line 344, in parse
    loader.exec_module(new_module)
  File "<frozen importlib._bootstrap_external>", line 883, in exec_module
  File "<frozen importlib._bootstrap>", line 241, in _call_with_frames_removed
  File "/home/ubuntu/airflow/dags/my_dag.py", line 5, in <module>
    from movies import find_popular_movies_and_save, get_movie_genres
  File "/home/ubuntu/airflow/dags/movies.py", line 45, in <module>
    find_popular_movies_and_save()
  File "/home/ubuntu/airflow/dags/movies.py", line 23, in find_popular_movies_and_save
    response = requests.get(base_url, params=params)
  File "/home/ubuntu/.local/lib/python3.10/site-packages/requests/api.py", line 73, in get
    return request("get", url, params=params, **kwargs)
  File "/home/ubuntu/.local/lib/python3.10/site-packages/requests/api.py", line 59, in request
    return session.request(method=method, url=url, **kwargs)
  File "/home/ubuntu/.local/lib/python3.10/site-packages/requests/sessions.py", line 589, in request
    resp = self.send(prep, **send_kwargs)
  File "/home/ubuntu/.local/lib/python3.10/site-packages/requests/sessions.py", line 703, in send
    r = adapter.send(request, **kwargs)
  File "/home/ubuntu/.local/lib/python3.10/site-packages/requests/adapters.py", line 519, in send
    raise ConnectionError(e, request=request)
requests.exceptions.ConnectionError: HTTPSConnectionPool(host='api.themoviedb.org', port=443): Max retries exceeded with url: /3/movie/popular?api_key=2c5a15136404a6eb67a3b4498cb2b4b8&page=1 (Caused by NewConnectionError('<urllib3.connection.HTTPSConnection object at 0x7ff32a6be0b0>: Failed to establish a new connection: [Errno -3] Temporary failure in name resolution'))
[2024-01-21T12:26:51.136+0100] {processor.py:842} WARNING - No viable dags retrieved from /home/ubuntu/airflow/dags/my_dag.py
[2024-01-21T12:26:51.212+0100] {processor.py:183} INFO - Processing /home/ubuntu/airflow/dags/my_dag.py took 20.647 seconds
[2024-01-21T12:27:41.855+0100] {processor.py:161} INFO - Started process (PID=5289) to work on /home/ubuntu/airflow/dags/my_dag.py
[2024-01-21T12:27:41.862+0100] {processor.py:830} INFO - Processing file /home/ubuntu/airflow/dags/my_dag.py for tasks to queue
[2024-01-21T12:27:41.865+0100] {logging_mixin.py:188} INFO - [2024-01-21T12:27:41.863+0100] {dagbag.py:538} INFO - Filling up the DagBag from /home/ubuntu/airflow/dags/my_dag.py
[2024-01-21T12:28:02.403+0100] {logging_mixin.py:188} INFO - [2024-01-21T12:28:02.298+0100] {dagbag.py:348} ERROR - Failed to import: /home/ubuntu/airflow/dags/my_dag.py
Traceback (most recent call last):
  File "/home/ubuntu/.local/lib/python3.10/site-packages/urllib3/connection.py", line 174, in _new_conn
    conn = connection.create_connection(
  File "/home/ubuntu/.local/lib/python3.10/site-packages/urllib3/util/connection.py", line 72, in create_connection
    for res in socket.getaddrinfo(host, port, family, socket.SOCK_STREAM):
  File "/usr/lib/python3.10/socket.py", line 955, in getaddrinfo
    for res in _socket.getaddrinfo(host, port, family, type, proto, flags):
socket.gaierror: [Errno -3] Temporary failure in name resolution

During handling of the above exception, another exception occurred:

Traceback (most recent call last):
  File "/home/ubuntu/.local/lib/python3.10/site-packages/urllib3/connectionpool.py", line 715, in urlopen
    httplib_response = self._make_request(
  File "/home/ubuntu/.local/lib/python3.10/site-packages/urllib3/connectionpool.py", line 404, in _make_request
    self._validate_conn(conn)
  File "/home/ubuntu/.local/lib/python3.10/site-packages/urllib3/connectionpool.py", line 1058, in _validate_conn
    conn.connect()
  File "/home/ubuntu/.local/lib/python3.10/site-packages/urllib3/connection.py", line 363, in connect
    self.sock = conn = self._new_conn()
  File "/home/ubuntu/.local/lib/python3.10/site-packages/urllib3/connection.py", line 186, in _new_conn
    raise NewConnectionError(
urllib3.exceptions.NewConnectionError: <urllib3.connection.HTTPSConnection object at 0x7ff32a6be0b0>: Failed to establish a new connection: [Errno -3] Temporary failure in name resolution

During handling of the above exception, another exception occurred:

Traceback (most recent call last):
  File "/home/ubuntu/.local/lib/python3.10/site-packages/requests/adapters.py", line 486, in send
    resp = conn.urlopen(
  File "/home/ubuntu/.local/lib/python3.10/site-packages/urllib3/connectionpool.py", line 799, in urlopen
    retries = retries.increment(
  File "/home/ubuntu/.local/lib/python3.10/site-packages/urllib3/util/retry.py", line 592, in increment
    raise MaxRetryError(_pool, url, error or ResponseError(cause))
urllib3.exceptions.MaxRetryError: HTTPSConnectionPool(host='api.themoviedb.org', port=443): Max retries exceeded with url: /3/movie/popular?api_key=2c5a15136404a6eb67a3b4498cb2b4b8&page=1 (Caused by NewConnectionError('<urllib3.connection.HTTPSConnection object at 0x7ff32a6be0b0>: Failed to establish a new connection: [Errno -3] Temporary failure in name resolution'))

During handling of the above exception, another exception occurred:

Traceback (most recent call last):
  File "/home/ubuntu/.local/lib/python3.10/site-packages/airflow/models/dagbag.py", line 344, in parse
    loader.exec_module(new_module)
  File "<frozen importlib._bootstrap_external>", line 883, in exec_module
  File "<frozen importlib._bootstrap>", line 241, in _call_with_frames_removed
  File "/home/ubuntu/airflow/dags/my_dag.py", line 5, in <module>
    from movies import find_popular_movies_and_save, get_movie_genres
  File "/home/ubuntu/airflow/dags/movies.py", line 45, in <module>
    find_popular_movies_and_save()
  File "/home/ubuntu/airflow/dags/movies.py", line 23, in find_popular_movies_and_save
    response = requests.get(base_url, params=params)
  File "/home/ubuntu/.local/lib/python3.10/site-packages/requests/api.py", line 73, in get
    return request("get", url, params=params, **kwargs)
  File "/home/ubuntu/.local/lib/python3.10/site-packages/requests/api.py", line 59, in request
    return session.request(method=method, url=url, **kwargs)
  File "/home/ubuntu/.local/lib/python3.10/site-packages/requests/sessions.py", line 589, in request
    resp = self.send(prep, **send_kwargs)
  File "/home/ubuntu/.local/lib/python3.10/site-packages/requests/sessions.py", line 703, in send
    r = adapter.send(request, **kwargs)
  File "/home/ubuntu/.local/lib/python3.10/site-packages/requests/adapters.py", line 519, in send
    raise ConnectionError(e, request=request)
requests.exceptions.ConnectionError: HTTPSConnectionPool(host='api.themoviedb.org', port=443): Max retries exceeded with url: /3/movie/popular?api_key=2c5a15136404a6eb67a3b4498cb2b4b8&page=1 (Caused by NewConnectionError('<urllib3.connection.HTTPSConnection object at 0x7ff32a6be0b0>: Failed to establish a new connection: [Errno -3] Temporary failure in name resolution'))
[2024-01-21T12:28:02.405+0100] {processor.py:842} WARNING - No viable dags retrieved from /home/ubuntu/airflow/dags/my_dag.py
[2024-01-21T12:28:02.531+0100] {processor.py:183} INFO - Processing /home/ubuntu/airflow/dags/my_dag.py took 20.681 seconds
[2024-01-21T12:28:43.321+0100] {processor.py:161} INFO - Started process (PID=5318) to work on /home/ubuntu/airflow/dags/my_dag.py
[2024-01-21T12:28:43.328+0100] {processor.py:830} INFO - Processing file /home/ubuntu/airflow/dags/my_dag.py for tasks to queue
[2024-01-21T12:28:43.333+0100] {logging_mixin.py:188} INFO - [2024-01-21T12:28:43.330+0100] {dagbag.py:538} INFO - Filling up the DagBag from /home/ubuntu/airflow/dags/my_dag.py
[2024-01-21T12:29:03.592+0100] {logging_mixin.py:188} INFO - [2024-01-21T12:29:03.585+0100] {dagbag.py:348} ERROR - Failed to import: /home/ubuntu/airflow/dags/my_dag.py
Traceback (most recent call last):
  File "/home/ubuntu/.local/lib/python3.10/site-packages/urllib3/connection.py", line 174, in _new_conn
    conn = connection.create_connection(
  File "/home/ubuntu/.local/lib/python3.10/site-packages/urllib3/util/connection.py", line 72, in create_connection
    for res in socket.getaddrinfo(host, port, family, socket.SOCK_STREAM):
  File "/usr/lib/python3.10/socket.py", line 955, in getaddrinfo
    for res in _socket.getaddrinfo(host, port, family, type, proto, flags):
socket.gaierror: [Errno -3] Temporary failure in name resolution

During handling of the above exception, another exception occurred:

Traceback (most recent call last):
  File "/home/ubuntu/.local/lib/python3.10/site-packages/urllib3/connectionpool.py", line 715, in urlopen
    httplib_response = self._make_request(
  File "/home/ubuntu/.local/lib/python3.10/site-packages/urllib3/connectionpool.py", line 404, in _make_request
    self._validate_conn(conn)
  File "/home/ubuntu/.local/lib/python3.10/site-packages/urllib3/connectionpool.py", line 1058, in _validate_conn
    conn.connect()
  File "/home/ubuntu/.local/lib/python3.10/site-packages/urllib3/connection.py", line 363, in connect
    self.sock = conn = self._new_conn()
  File "/home/ubuntu/.local/lib/python3.10/site-packages/urllib3/connection.py", line 186, in _new_conn
    raise NewConnectionError(
urllib3.exceptions.NewConnectionError: <urllib3.connection.HTTPSConnection object at 0x7ff32a6be0e0>: Failed to establish a new connection: [Errno -3] Temporary failure in name resolution

During handling of the above exception, another exception occurred:

Traceback (most recent call last):
  File "/home/ubuntu/.local/lib/python3.10/site-packages/requests/adapters.py", line 486, in send
    resp = conn.urlopen(
  File "/home/ubuntu/.local/lib/python3.10/site-packages/urllib3/connectionpool.py", line 799, in urlopen
    retries = retries.increment(
  File "/home/ubuntu/.local/lib/python3.10/site-packages/urllib3/util/retry.py", line 592, in increment
    raise MaxRetryError(_pool, url, error or ResponseError(cause))
urllib3.exceptions.MaxRetryError: HTTPSConnectionPool(host='api.themoviedb.org', port=443): Max retries exceeded with url: /3/movie/popular?api_key=2c5a15136404a6eb67a3b4498cb2b4b8&page=1 (Caused by NewConnectionError('<urllib3.connection.HTTPSConnection object at 0x7ff32a6be0e0>: Failed to establish a new connection: [Errno -3] Temporary failure in name resolution'))

During handling of the above exception, another exception occurred:

Traceback (most recent call last):
  File "/home/ubuntu/.local/lib/python3.10/site-packages/airflow/models/dagbag.py", line 344, in parse
    loader.exec_module(new_module)
  File "<frozen importlib._bootstrap_external>", line 883, in exec_module
  File "<frozen importlib._bootstrap>", line 241, in _call_with_frames_removed
  File "/home/ubuntu/airflow/dags/my_dag.py", line 5, in <module>
    from movies import find_popular_movies_and_save, get_movie_genres
  File "/home/ubuntu/airflow/dags/movies.py", line 45, in <module>
    find_popular_movies_and_save()
  File "/home/ubuntu/airflow/dags/movies.py", line 23, in find_popular_movies_and_save
    response = requests.get(base_url, params=params)
  File "/home/ubuntu/.local/lib/python3.10/site-packages/requests/api.py", line 73, in get
    return request("get", url, params=params, **kwargs)
  File "/home/ubuntu/.local/lib/python3.10/site-packages/requests/api.py", line 59, in request
    return session.request(method=method, url=url, **kwargs)
  File "/home/ubuntu/.local/lib/python3.10/site-packages/requests/sessions.py", line 589, in request
    resp = self.send(prep, **send_kwargs)
  File "/home/ubuntu/.local/lib/python3.10/site-packages/requests/sessions.py", line 703, in send
    r = adapter.send(request, **kwargs)
  File "/home/ubuntu/.local/lib/python3.10/site-packages/requests/adapters.py", line 519, in send
    raise ConnectionError(e, request=request)
requests.exceptions.ConnectionError: HTTPSConnectionPool(host='api.themoviedb.org', port=443): Max retries exceeded with url: /3/movie/popular?api_key=2c5a15136404a6eb67a3b4498cb2b4b8&page=1 (Caused by NewConnectionError('<urllib3.connection.HTTPSConnection object at 0x7ff32a6be0e0>: Failed to establish a new connection: [Errno -3] Temporary failure in name resolution'))
[2024-01-21T12:29:03.594+0100] {processor.py:842} WARNING - No viable dags retrieved from /home/ubuntu/airflow/dags/my_dag.py
[2024-01-21T12:29:03.750+0100] {processor.py:183} INFO - Processing /home/ubuntu/airflow/dags/my_dag.py took 20.441 seconds
[2024-01-21T12:29:42.681+0100] {processor.py:161} INFO - Started process (PID=5407) to work on /home/ubuntu/airflow/dags/my_dag.py
[2024-01-21T12:29:42.689+0100] {processor.py:830} INFO - Processing file /home/ubuntu/airflow/dags/my_dag.py for tasks to queue
[2024-01-21T12:29:42.691+0100] {logging_mixin.py:188} INFO - [2024-01-21T12:29:42.690+0100] {dagbag.py:538} INFO - Filling up the DagBag from /home/ubuntu/airflow/dags/my_dag.py
[2024-01-21T12:30:03.095+0100] {logging_mixin.py:188} INFO - [2024-01-21T12:30:03.062+0100] {dagbag.py:348} ERROR - Failed to import: /home/ubuntu/airflow/dags/my_dag.py
Traceback (most recent call last):
  File "/home/ubuntu/.local/lib/python3.10/site-packages/urllib3/connection.py", line 174, in _new_conn
    conn = connection.create_connection(
  File "/home/ubuntu/.local/lib/python3.10/site-packages/urllib3/util/connection.py", line 72, in create_connection
    for res in socket.getaddrinfo(host, port, family, socket.SOCK_STREAM):
  File "/usr/lib/python3.10/socket.py", line 955, in getaddrinfo
    for res in _socket.getaddrinfo(host, port, family, type, proto, flags):
socket.gaierror: [Errno -3] Temporary failure in name resolution

During handling of the above exception, another exception occurred:

Traceback (most recent call last):
  File "/home/ubuntu/.local/lib/python3.10/site-packages/urllib3/connectionpool.py", line 715, in urlopen
    httplib_response = self._make_request(
  File "/home/ubuntu/.local/lib/python3.10/site-packages/urllib3/connectionpool.py", line 404, in _make_request
    self._validate_conn(conn)
  File "/home/ubuntu/.local/lib/python3.10/site-packages/urllib3/connectionpool.py", line 1058, in _validate_conn
    conn.connect()
  File "/home/ubuntu/.local/lib/python3.10/site-packages/urllib3/connection.py", line 363, in connect
    self.sock = conn = self._new_conn()
  File "/home/ubuntu/.local/lib/python3.10/site-packages/urllib3/connection.py", line 186, in _new_conn
    raise NewConnectionError(
urllib3.exceptions.NewConnectionError: <urllib3.connection.HTTPSConnection object at 0x7ff32a6be110>: Failed to establish a new connection: [Errno -3] Temporary failure in name resolution

During handling of the above exception, another exception occurred:

Traceback (most recent call last):
  File "/home/ubuntu/.local/lib/python3.10/site-packages/requests/adapters.py", line 486, in send
    resp = conn.urlopen(
  File "/home/ubuntu/.local/lib/python3.10/site-packages/urllib3/connectionpool.py", line 799, in urlopen
    retries = retries.increment(
  File "/home/ubuntu/.local/lib/python3.10/site-packages/urllib3/util/retry.py", line 592, in increment
    raise MaxRetryError(_pool, url, error or ResponseError(cause))
urllib3.exceptions.MaxRetryError: HTTPSConnectionPool(host='api.themoviedb.org', port=443): Max retries exceeded with url: /3/movie/popular?api_key=2c5a15136404a6eb67a3b4498cb2b4b8&page=1 (Caused by NewConnectionError('<urllib3.connection.HTTPSConnection object at 0x7ff32a6be110>: Failed to establish a new connection: [Errno -3] Temporary failure in name resolution'))

During handling of the above exception, another exception occurred:

Traceback (most recent call last):
  File "/home/ubuntu/.local/lib/python3.10/site-packages/airflow/models/dagbag.py", line 344, in parse
    loader.exec_module(new_module)
  File "<frozen importlib._bootstrap_external>", line 883, in exec_module
  File "<frozen importlib._bootstrap>", line 241, in _call_with_frames_removed
  File "/home/ubuntu/airflow/dags/my_dag.py", line 5, in <module>
    from movies import find_popular_movies_and_save, get_movie_genres
  File "/home/ubuntu/airflow/dags/movies.py", line 45, in <module>
    find_popular_movies_and_save()
  File "/home/ubuntu/airflow/dags/movies.py", line 23, in find_popular_movies_and_save
    response = requests.get(base_url, params=params)
  File "/home/ubuntu/.local/lib/python3.10/site-packages/requests/api.py", line 73, in get
    return request("get", url, params=params, **kwargs)
  File "/home/ubuntu/.local/lib/python3.10/site-packages/requests/api.py", line 59, in request
    return session.request(method=method, url=url, **kwargs)
  File "/home/ubuntu/.local/lib/python3.10/site-packages/requests/sessions.py", line 589, in request
    resp = self.send(prep, **send_kwargs)
  File "/home/ubuntu/.local/lib/python3.10/site-packages/requests/sessions.py", line 703, in send
    r = adapter.send(request, **kwargs)
  File "/home/ubuntu/.local/lib/python3.10/site-packages/requests/adapters.py", line 519, in send
    raise ConnectionError(e, request=request)
requests.exceptions.ConnectionError: HTTPSConnectionPool(host='api.themoviedb.org', port=443): Max retries exceeded with url: /3/movie/popular?api_key=2c5a15136404a6eb67a3b4498cb2b4b8&page=1 (Caused by NewConnectionError('<urllib3.connection.HTTPSConnection object at 0x7ff32a6be110>: Failed to establish a new connection: [Errno -3] Temporary failure in name resolution'))
[2024-01-21T12:30:03.099+0100] {processor.py:842} WARNING - No viable dags retrieved from /home/ubuntu/airflow/dags/my_dag.py
[2024-01-21T12:30:03.142+0100] {processor.py:183} INFO - Processing /home/ubuntu/airflow/dags/my_dag.py took 20.484 seconds
[2024-01-21T12:30:41.980+0100] {processor.py:161} INFO - Started process (PID=5450) to work on /home/ubuntu/airflow/dags/my_dag.py
[2024-01-21T12:30:41.986+0100] {processor.py:830} INFO - Processing file /home/ubuntu/airflow/dags/my_dag.py for tasks to queue
[2024-01-21T12:30:41.988+0100] {logging_mixin.py:188} INFO - [2024-01-21T12:30:41.987+0100] {dagbag.py:538} INFO - Filling up the DagBag from /home/ubuntu/airflow/dags/my_dag.py
[2024-01-21T12:30:55.965+0100] {logging_mixin.py:188} INFO - Nombre: 40
[2024-01-21T12:30:56.438+0100] {logging_mixin.py:188} INFO - Nombre: 60
[2024-01-21T12:30:56.982+0100] {logging_mixin.py:188} INFO - Nombre: 80
[2024-01-21T12:30:57.666+0100] {logging_mixin.py:188} INFO - Nombre: 100
[2024-01-21T12:30:58.224+0100] {logging_mixin.py:188} INFO - Nombre: 120
[2024-01-21T12:30:59.037+0100] {logging_mixin.py:188} INFO - Nombre: 140
[2024-01-21T12:30:59.948+0100] {logging_mixin.py:188} INFO - Nombre: 160
[2024-01-21T12:31:00.811+0100] {logging_mixin.py:188} INFO - Nombre: 180
[2024-01-21T12:31:01.233+0100] {logging_mixin.py:188} INFO - Nombre: 200
[2024-01-21T12:31:01.730+0100] {logging_mixin.py:188} INFO - Nombre: 220
[2024-01-21T12:31:02.288+0100] {logging_mixin.py:188} INFO - Nombre: 240
[2024-01-21T12:31:02.755+0100] {logging_mixin.py:188} INFO - Nombre: 260
[2024-01-21T12:31:03.691+0100] {logging_mixin.py:188} INFO - Nombre: 280
[2024-01-21T12:31:04.270+0100] {logging_mixin.py:188} INFO - Nombre: 300
[2024-01-21T12:31:05.487+0100] {logging_mixin.py:188} INFO - Nombre: 320
[2024-01-21T12:31:12.000+0100] {logging_mixin.py:188} INFO - [2024-01-21T12:31:11.993+0100] {timeout.py:68} ERROR - Process timed out, PID: 5450
[2024-01-21T12:31:12.038+0100] {logging_mixin.py:188} INFO - [2024-01-21T12:31:12.007+0100] {dagbag.py:348} ERROR - Failed to import: /home/ubuntu/airflow/dags/my_dag.py
Traceback (most recent call last):
  File "/home/ubuntu/.local/lib/python3.10/site-packages/airflow/models/dagbag.py", line 344, in parse
    loader.exec_module(new_module)
  File "<frozen importlib._bootstrap_external>", line 883, in exec_module
  File "<frozen importlib._bootstrap>", line 241, in _call_with_frames_removed
  File "/home/ubuntu/airflow/dags/my_dag.py", line 5, in <module>
    from movies import find_popular_movies_and_save, get_movie_genres
  File "/home/ubuntu/airflow/dags/movies.py", line 45, in <module>
    find_popular_movies_and_save()
  File "/home/ubuntu/airflow/dags/movies.py", line 33, in find_popular_movies_and_save
    response = requests.get(base_url, params=params)
  File "/home/ubuntu/.local/lib/python3.10/site-packages/requests/api.py", line 73, in get
    return request("get", url, params=params, **kwargs)
  File "/home/ubuntu/.local/lib/python3.10/site-packages/requests/api.py", line 59, in request
    return session.request(method=method, url=url, **kwargs)
  File "/home/ubuntu/.local/lib/python3.10/site-packages/requests/sessions.py", line 589, in request
    resp = self.send(prep, **send_kwargs)
  File "/home/ubuntu/.local/lib/python3.10/site-packages/requests/sessions.py", line 703, in send
    r = adapter.send(request, **kwargs)
  File "/home/ubuntu/.local/lib/python3.10/site-packages/requests/adapters.py", line 486, in send
    resp = conn.urlopen(
  File "/home/ubuntu/.local/lib/python3.10/site-packages/urllib3/connectionpool.py", line 715, in urlopen
    httplib_response = self._make_request(
  File "/home/ubuntu/.local/lib/python3.10/site-packages/urllib3/connectionpool.py", line 404, in _make_request
    self._validate_conn(conn)
  File "/home/ubuntu/.local/lib/python3.10/site-packages/urllib3/connectionpool.py", line 1058, in _validate_conn
    conn.connect()
  File "/home/ubuntu/.local/lib/python3.10/site-packages/urllib3/connection.py", line 419, in connect
    self.sock = ssl_wrap_socket(
  File "/home/ubuntu/.local/lib/python3.10/site-packages/urllib3/util/ssl_.py", line 449, in ssl_wrap_socket
    ssl_sock = _ssl_wrap_socket_impl(
  File "/home/ubuntu/.local/lib/python3.10/site-packages/urllib3/util/ssl_.py", line 493, in _ssl_wrap_socket_impl
    return ssl_context.wrap_socket(sock, server_hostname=server_hostname)
  File "/usr/lib/python3.10/ssl.py", line 513, in wrap_socket
    return self.sslsocket_class._create(
  File "/usr/lib/python3.10/ssl.py", line 1100, in _create
    self.do_handshake()
  File "/usr/lib/python3.10/ssl.py", line 1371, in do_handshake
    self._sslobj.do_handshake()
  File "/home/ubuntu/.local/lib/python3.10/site-packages/airflow/utils/timeout.py", line 69, in handle_timeout
    raise AirflowTaskTimeout(self.error_message)
airflow.exceptions.AirflowTaskTimeout: DagBag import timeout for /home/ubuntu/airflow/dags/my_dag.py after 30.0s.
Please take a look at these docs to improve your DAG import time:
* https://airflow.apache.org/docs/apache-airflow/2.8.0/best-practices.html#top-level-python-code
* https://airflow.apache.org/docs/apache-airflow/2.8.0/best-practices.html#reducing-dag-complexity, PID: 5450
[2024-01-21T12:31:12.046+0100] {processor.py:842} WARNING - No viable dags retrieved from /home/ubuntu/airflow/dags/my_dag.py
[2024-01-21T12:31:12.110+0100] {processor.py:183} INFO - Processing /home/ubuntu/airflow/dags/my_dag.py took 30.134 seconds
[2024-01-21T12:31:53.037+0100] {processor.py:161} INFO - Started process (PID=5502) to work on /home/ubuntu/airflow/dags/my_dag.py
[2024-01-21T12:31:53.045+0100] {processor.py:830} INFO - Processing file /home/ubuntu/airflow/dags/my_dag.py for tasks to queue
[2024-01-21T12:31:53.047+0100] {logging_mixin.py:188} INFO - [2024-01-21T12:31:53.046+0100] {dagbag.py:538} INFO - Filling up the DagBag from /home/ubuntu/airflow/dags/my_dag.py
[2024-01-21T12:31:54.986+0100] {logging_mixin.py:188} INFO - Nombre: 40
[2024-01-21T12:31:55.490+0100] {logging_mixin.py:188} INFO - Nombre: 60
[2024-01-21T12:31:56.115+0100] {logging_mixin.py:188} INFO - Nombre: 80
[2024-01-21T12:31:56.648+0100] {logging_mixin.py:188} INFO - Nombre: 100
[2024-01-21T12:31:57.090+0100] {logging_mixin.py:188} INFO - Nombre: 120
[2024-01-21T12:31:57.615+0100] {logging_mixin.py:188} INFO - Nombre: 140
[2024-01-21T12:31:58.146+0100] {logging_mixin.py:188} INFO - Nombre: 160
[2024-01-21T12:31:58.861+0100] {logging_mixin.py:188} INFO - Nombre: 180
[2024-01-21T12:31:59.998+0100] {logging_mixin.py:188} INFO - Nombre: 200
[2024-01-21T12:32:00.792+0100] {logging_mixin.py:188} INFO - Nombre: 220
[2024-01-21T12:32:01.891+0100] {logging_mixin.py:188} INFO - Nombre: 240
[2024-01-21T12:32:02.736+0100] {logging_mixin.py:188} INFO - Nombre: 260
[2024-01-21T12:32:03.280+0100] {logging_mixin.py:188} INFO - Nombre: 280
[2024-01-21T12:32:03.869+0100] {logging_mixin.py:188} INFO - Nombre: 300
[2024-01-21T12:32:04.317+0100] {logging_mixin.py:188} INFO - Nombre: 320
[2024-01-21T12:32:04.814+0100] {logging_mixin.py:188} INFO - Nombre: 340
[2024-01-21T12:32:05.216+0100] {logging_mixin.py:188} INFO - Nombre: 360
[2024-01-21T12:32:05.681+0100] {logging_mixin.py:188} INFO - Nombre: 380
[2024-01-21T12:32:06.098+0100] {logging_mixin.py:188} INFO - Nombre: 400
[2024-01-21T12:32:06.582+0100] {logging_mixin.py:188} INFO - Nombre: 420
[2024-01-21T12:32:06.999+0100] {logging_mixin.py:188} INFO - Nombre: 440
[2024-01-21T12:32:07.395+0100] {logging_mixin.py:188} INFO - Nombre: 460
[2024-01-21T12:32:07.835+0100] {logging_mixin.py:188} INFO - Nombre: 480
[2024-01-21T12:32:08.196+0100] {logging_mixin.py:188} INFO - Nombre: 500
[2024-01-21T12:32:08.564+0100] {logging_mixin.py:188} INFO - Nombre: 520
[2024-01-21T12:32:09.134+0100] {logging_mixin.py:188} INFO - Nombre: 540
[2024-01-21T12:32:09.584+0100] {logging_mixin.py:188} INFO - Nombre: 560
[2024-01-21T12:32:10.073+0100] {logging_mixin.py:188} INFO - Nombre: 580
[2024-01-21T12:32:10.664+0100] {logging_mixin.py:188} INFO - Nombre: 600
[2024-01-21T12:32:11.466+0100] {logging_mixin.py:188} INFO - Nombre: 620
[2024-01-21T12:32:11.942+0100] {logging_mixin.py:188} INFO - Nombre: 640
[2024-01-21T12:32:12.381+0100] {logging_mixin.py:188} INFO - Nombre: 660
[2024-01-21T12:32:12.914+0100] {logging_mixin.py:188} INFO - Nombre: 680
[2024-01-21T12:32:13.322+0100] {logging_mixin.py:188} INFO - Nombre: 700
[2024-01-21T12:32:13.755+0100] {logging_mixin.py:188} INFO - Nombre: 720
[2024-01-21T12:32:14.151+0100] {logging_mixin.py:188} INFO - Nombre: 740
[2024-01-21T12:32:14.619+0100] {logging_mixin.py:188} INFO - Nombre: 760
[2024-01-21T12:32:15.130+0100] {logging_mixin.py:188} INFO - Nombre: 780
[2024-01-21T12:32:15.499+0100] {logging_mixin.py:188} INFO - Nombre: 800
[2024-01-21T12:32:15.903+0100] {logging_mixin.py:188} INFO - Nombre: 820
[2024-01-21T12:32:16.239+0100] {logging_mixin.py:188} INFO - Nombre: 840
[2024-01-21T12:32:16.786+0100] {logging_mixin.py:188} INFO - Nombre: 860
[2024-01-21T12:32:17.194+0100] {logging_mixin.py:188} INFO - Nombre: 880
[2024-01-21T12:32:17.580+0100] {logging_mixin.py:188} INFO - Nombre: 900
[2024-01-21T12:32:18.091+0100] {logging_mixin.py:188} INFO - Nombre: 920
[2024-01-21T12:32:18.552+0100] {logging_mixin.py:188} INFO - Nombre: 940
[2024-01-21T12:32:19.035+0100] {logging_mixin.py:188} INFO - Nombre: 960
[2024-01-21T12:32:19.449+0100] {logging_mixin.py:188} INFO - Nombre: 980
[2024-01-21T12:32:19.846+0100] {logging_mixin.py:188} INFO - Nombre: 1000
[2024-01-21T12:32:20.295+0100] {logging_mixin.py:188} INFO - Nombre: 1020
[2024-01-21T12:32:20.705+0100] {logging_mixin.py:188} INFO - Nombre: 1040
[2024-01-21T12:32:21.078+0100] {logging_mixin.py:188} INFO - Nombre: 1060
[2024-01-21T12:32:21.476+0100] {logging_mixin.py:188} INFO - Nombre: 1080
[2024-01-21T12:32:21.897+0100] {logging_mixin.py:188} INFO - Nombre: 1100
[2024-01-21T12:32:22.383+0100] {logging_mixin.py:188} INFO - Nombre: 1120
[2024-01-21T12:32:22.910+0100] {logging_mixin.py:188} INFO - Nombre: 1140
[2024-01-21T12:32:23.148+0100] {logging_mixin.py:188} INFO - [2024-01-21T12:32:23.147+0100] {timeout.py:68} ERROR - Process timed out, PID: 5502
[2024-01-21T12:32:23.154+0100] {logging_mixin.py:188} INFO - [2024-01-21T12:32:23.150+0100] {dagbag.py:348} ERROR - Failed to import: /home/ubuntu/airflow/dags/my_dag.py
Traceback (most recent call last):
  File "/home/ubuntu/.local/lib/python3.10/site-packages/airflow/models/dagbag.py", line 344, in parse
    loader.exec_module(new_module)
  File "<frozen importlib._bootstrap_external>", line 883, in exec_module
  File "<frozen importlib._bootstrap>", line 241, in _call_with_frames_removed
  File "/home/ubuntu/airflow/dags/my_dag.py", line 5, in <module>
    from movies import find_popular_movies_and_save, get_movie_genres
  File "/home/ubuntu/airflow/dags/movies.py", line 45, in <module>
    find_popular_movies_and_save()
  File "/home/ubuntu/airflow/dags/movies.py", line 33, in find_popular_movies_and_save
    response = requests.get(base_url, params=params)
  File "/home/ubuntu/.local/lib/python3.10/site-packages/requests/api.py", line 73, in get
    return request("get", url, params=params, **kwargs)
  File "/home/ubuntu/.local/lib/python3.10/site-packages/requests/api.py", line 59, in request
    return session.request(method=method, url=url, **kwargs)
  File "/home/ubuntu/.local/lib/python3.10/site-packages/requests/sessions.py", line 589, in request
    resp = self.send(prep, **send_kwargs)
  File "/home/ubuntu/.local/lib/python3.10/site-packages/requests/sessions.py", line 703, in send
    r = adapter.send(request, **kwargs)
  File "/home/ubuntu/.local/lib/python3.10/site-packages/requests/adapters.py", line 486, in send
    resp = conn.urlopen(
  File "/home/ubuntu/.local/lib/python3.10/site-packages/urllib3/connectionpool.py", line 715, in urlopen
    httplib_response = self._make_request(
  File "/home/ubuntu/.local/lib/python3.10/site-packages/urllib3/connectionpool.py", line 404, in _make_request
    self._validate_conn(conn)
  File "/home/ubuntu/.local/lib/python3.10/site-packages/urllib3/connectionpool.py", line 1058, in _validate_conn
    conn.connect()
  File "/home/ubuntu/.local/lib/python3.10/site-packages/urllib3/connection.py", line 419, in connect
    self.sock = ssl_wrap_socket(
  File "/home/ubuntu/.local/lib/python3.10/site-packages/urllib3/util/ssl_.py", line 402, in ssl_wrap_socket
    context.load_verify_locations(ca_certs, ca_cert_dir, ca_cert_data)
  File "/home/ubuntu/.local/lib/python3.10/site-packages/airflow/utils/timeout.py", line 69, in handle_timeout
    raise AirflowTaskTimeout(self.error_message)
airflow.exceptions.AirflowTaskTimeout: DagBag import timeout for /home/ubuntu/airflow/dags/my_dag.py after 30.0s.
Please take a look at these docs to improve your DAG import time:
* https://airflow.apache.org/docs/apache-airflow/2.8.0/best-practices.html#top-level-python-code
* https://airflow.apache.org/docs/apache-airflow/2.8.0/best-practices.html#reducing-dag-complexity, PID: 5502
[2024-01-21T12:32:23.161+0100] {processor.py:842} WARNING - No viable dags retrieved from /home/ubuntu/airflow/dags/my_dag.py
[2024-01-21T12:32:23.199+0100] {processor.py:183} INFO - Processing /home/ubuntu/airflow/dags/my_dag.py took 30.177 seconds
[2024-01-21T12:33:04.977+0100] {processor.py:161} INFO - Started process (PID=5545) to work on /home/ubuntu/airflow/dags/my_dag.py
[2024-01-21T12:33:04.981+0100] {processor.py:830} INFO - Processing file /home/ubuntu/airflow/dags/my_dag.py for tasks to queue
[2024-01-21T12:33:04.984+0100] {logging_mixin.py:188} INFO - [2024-01-21T12:33:04.983+0100] {dagbag.py:538} INFO - Filling up the DagBag from /home/ubuntu/airflow/dags/my_dag.py
[2024-01-21T12:33:06.090+0100] {logging_mixin.py:188} INFO - Nombre: 40
[2024-01-21T12:33:06.487+0100] {logging_mixin.py:188} INFO - Nombre: 60
[2024-01-21T12:33:06.869+0100] {logging_mixin.py:188} INFO - Nombre: 80
[2024-01-21T12:33:07.263+0100] {logging_mixin.py:188} INFO - Nombre: 100
[2024-01-21T12:33:07.736+0100] {logging_mixin.py:188} INFO - Nombre: 120
[2024-01-21T12:33:08.181+0100] {logging_mixin.py:188} INFO - Nombre: 140
[2024-01-21T12:33:08.558+0100] {logging_mixin.py:188} INFO - Nombre: 160
[2024-01-21T12:33:09.039+0100] {logging_mixin.py:188} INFO - Nombre: 180
[2024-01-21T12:33:09.526+0100] {logging_mixin.py:188} INFO - Nombre: 200
[2024-01-21T12:33:09.966+0100] {logging_mixin.py:188} INFO - Nombre: 220
[2024-01-21T12:33:10.395+0100] {logging_mixin.py:188} INFO - Nombre: 240
[2024-01-21T12:33:10.830+0100] {logging_mixin.py:188} INFO - Nombre: 260
[2024-01-21T12:33:11.226+0100] {logging_mixin.py:188} INFO - Nombre: 280
[2024-01-21T12:33:11.628+0100] {logging_mixin.py:188} INFO - Nombre: 300
[2024-01-21T12:33:12.096+0100] {logging_mixin.py:188} INFO - Nombre: 320
[2024-01-21T12:33:12.487+0100] {logging_mixin.py:188} INFO - Nombre: 340
[2024-01-21T12:33:12.887+0100] {logging_mixin.py:188} INFO - Nombre: 360
[2024-01-21T12:33:13.290+0100] {logging_mixin.py:188} INFO - Nombre: 380
[2024-01-21T12:33:13.881+0100] {logging_mixin.py:188} INFO - Nombre: 400
[2024-01-21T12:33:14.273+0100] {logging_mixin.py:188} INFO - Nombre: 420
[2024-01-21T12:33:14.678+0100] {logging_mixin.py:188} INFO - Nombre: 440
[2024-01-21T12:33:15.114+0100] {logging_mixin.py:188} INFO - Nombre: 460
[2024-01-21T12:33:15.557+0100] {logging_mixin.py:188} INFO - Nombre: 480
[2024-01-21T12:33:15.962+0100] {logging_mixin.py:188} INFO - Nombre: 500
[2024-01-21T12:33:16.314+0100] {logging_mixin.py:188} INFO - Nombre: 520
[2024-01-21T12:33:16.689+0100] {logging_mixin.py:188} INFO - Nombre: 540
[2024-01-21T12:33:17.260+0100] {logging_mixin.py:188} INFO - Nombre: 560
[2024-01-21T12:33:17.831+0100] {logging_mixin.py:188} INFO - Nombre: 580
[2024-01-21T12:33:18.406+0100] {logging_mixin.py:188} INFO - Nombre: 600
[2024-01-21T12:33:18.951+0100] {logging_mixin.py:188} INFO - Nombre: 620
[2024-01-21T12:33:19.430+0100] {logging_mixin.py:188} INFO - Nombre: 640
[2024-01-21T12:33:19.835+0100] {logging_mixin.py:188} INFO - Nombre: 660
[2024-01-21T12:33:20.208+0100] {logging_mixin.py:188} INFO - Nombre: 680
[2024-01-21T12:33:20.534+0100] {logging_mixin.py:188} INFO - Nombre: 700
[2024-01-21T12:33:21.053+0100] {logging_mixin.py:188} INFO - Nombre: 720
[2024-01-21T12:33:21.479+0100] {logging_mixin.py:188} INFO - Nombre: 740
[2024-01-21T12:33:21.916+0100] {logging_mixin.py:188} INFO - Nombre: 760
[2024-01-21T12:33:22.286+0100] {logging_mixin.py:188} INFO - Nombre: 780
[2024-01-21T12:33:22.731+0100] {logging_mixin.py:188} INFO - Nombre: 800
[2024-01-21T12:33:23.121+0100] {logging_mixin.py:188} INFO - Nombre: 820
[2024-01-21T12:33:23.474+0100] {logging_mixin.py:188} INFO - Nombre: 840
[2024-01-21T12:33:23.840+0100] {logging_mixin.py:188} INFO - Nombre: 860
[2024-01-21T12:33:24.250+0100] {logging_mixin.py:188} INFO - Nombre: 880
[2024-01-21T12:33:24.769+0100] {logging_mixin.py:188} INFO - Nombre: 900
[2024-01-21T12:33:25.162+0100] {logging_mixin.py:188} INFO - Nombre: 920
[2024-01-21T12:33:25.718+0100] {logging_mixin.py:188} INFO - Nombre: 940
[2024-01-21T12:33:26.155+0100] {logging_mixin.py:188} INFO - Nombre: 960
[2024-01-21T12:33:26.595+0100] {logging_mixin.py:188} INFO - Nombre: 980
[2024-01-21T12:33:27.132+0100] {logging_mixin.py:188} INFO - Nombre: 1000
[2024-01-21T12:33:27.691+0100] {logging_mixin.py:188} INFO - Nombre: 1020
[2024-01-21T12:33:28.146+0100] {logging_mixin.py:188} INFO - Nombre: 1040
[2024-01-21T12:33:28.599+0100] {logging_mixin.py:188} INFO - Nombre: 1060
[2024-01-21T12:33:29.083+0100] {logging_mixin.py:188} INFO - Nombre: 1080
[2024-01-21T12:33:29.490+0100] {logging_mixin.py:188} INFO - Nombre: 1100
[2024-01-21T12:33:29.877+0100] {logging_mixin.py:188} INFO - Nombre: 1120
[2024-01-21T12:33:30.258+0100] {logging_mixin.py:188} INFO - Nombre: 1140
[2024-01-21T12:33:30.847+0100] {logging_mixin.py:188} INFO - Nombre: 1160
[2024-01-21T12:33:31.513+0100] {logging_mixin.py:188} INFO - Nombre: 1180
[2024-01-21T12:33:32.345+0100] {logging_mixin.py:188} INFO - Nombre: 1200
[2024-01-21T12:33:32.805+0100] {logging_mixin.py:188} INFO - Nombre: 1220
[2024-01-21T12:33:33.394+0100] {logging_mixin.py:188} INFO - Nombre: 1240
[2024-01-21T12:33:34.287+0100] {logging_mixin.py:188} INFO - Nombre: 1260
[2024-01-21T12:33:35.006+0100] {logging_mixin.py:188} INFO - [2024-01-21T12:33:34.992+0100] {timeout.py:68} ERROR - Process timed out, PID: 5545
[2024-01-21T12:33:35.062+0100] {logging_mixin.py:188} INFO - [2024-01-21T12:33:35.010+0100] {dagbag.py:348} ERROR - Failed to import: /home/ubuntu/airflow/dags/my_dag.py
Traceback (most recent call last):
  File "/home/ubuntu/.local/lib/python3.10/site-packages/airflow/models/dagbag.py", line 344, in parse
    loader.exec_module(new_module)
  File "<frozen importlib._bootstrap_external>", line 883, in exec_module
  File "<frozen importlib._bootstrap>", line 241, in _call_with_frames_removed
  File "/home/ubuntu/airflow/dags/my_dag.py", line 5, in <module>
    from movies import find_popular_movies_and_save, get_movie_genres
  File "/home/ubuntu/airflow/dags/movies.py", line 45, in <module>
    find_popular_movies_and_save()
  File "/home/ubuntu/airflow/dags/movies.py", line 33, in find_popular_movies_and_save
    response = requests.get(base_url, params=params)
  File "/home/ubuntu/.local/lib/python3.10/site-packages/requests/api.py", line 73, in get
    return request("get", url, params=params, **kwargs)
  File "/home/ubuntu/.local/lib/python3.10/site-packages/requests/api.py", line 59, in request
    return session.request(method=method, url=url, **kwargs)
  File "/home/ubuntu/.local/lib/python3.10/site-packages/requests/sessions.py", line 589, in request
    resp = self.send(prep, **send_kwargs)
  File "/home/ubuntu/.local/lib/python3.10/site-packages/requests/sessions.py", line 703, in send
    r = adapter.send(request, **kwargs)
  File "/home/ubuntu/.local/lib/python3.10/site-packages/requests/adapters.py", line 486, in send
    resp = conn.urlopen(
  File "/home/ubuntu/.local/lib/python3.10/site-packages/urllib3/connectionpool.py", line 715, in urlopen
    httplib_response = self._make_request(
  File "/home/ubuntu/.local/lib/python3.10/site-packages/urllib3/connectionpool.py", line 467, in _make_request
    six.raise_from(e, None)
  File "<string>", line 3, in raise_from
  File "/home/ubuntu/.local/lib/python3.10/site-packages/urllib3/connectionpool.py", line 462, in _make_request
    httplib_response = conn.getresponse()
  File "/usr/lib/python3.10/http/client.py", line 1375, in getresponse
    response.begin()
  File "/usr/lib/python3.10/http/client.py", line 318, in begin
    version, status, reason = self._read_status()
  File "/usr/lib/python3.10/http/client.py", line 279, in _read_status
    line = str(self.fp.readline(_MAXLINE + 1), "iso-8859-1")
  File "/usr/lib/python3.10/socket.py", line 705, in readinto
    return self._sock.recv_into(b)
  File "/usr/lib/python3.10/ssl.py", line 1303, in recv_into
    return self.read(nbytes, buffer)
  File "/usr/lib/python3.10/ssl.py", line 1159, in read
    return self._sslobj.read(len, buffer)
  File "/home/ubuntu/.local/lib/python3.10/site-packages/airflow/utils/timeout.py", line 69, in handle_timeout
    raise AirflowTaskTimeout(self.error_message)
airflow.exceptions.AirflowTaskTimeout: DagBag import timeout for /home/ubuntu/airflow/dags/my_dag.py after 30.0s.
Please take a look at these docs to improve your DAG import time:
* https://airflow.apache.org/docs/apache-airflow/2.8.0/best-practices.html#top-level-python-code
* https://airflow.apache.org/docs/apache-airflow/2.8.0/best-practices.html#reducing-dag-complexity, PID: 5545
[2024-01-21T12:33:35.079+0100] {processor.py:842} WARNING - No viable dags retrieved from /home/ubuntu/airflow/dags/my_dag.py
[2024-01-21T12:33:35.122+0100] {processor.py:183} INFO - Processing /home/ubuntu/airflow/dags/my_dag.py took 30.157 seconds
[2024-01-21T12:34:22.087+0100] {processor.py:161} INFO - Started process (PID=5593) to work on /home/ubuntu/airflow/dags/my_dag.py
[2024-01-21T12:34:22.092+0100] {processor.py:830} INFO - Processing file /home/ubuntu/airflow/dags/my_dag.py for tasks to queue
[2024-01-21T12:34:22.094+0100] {logging_mixin.py:188} INFO - [2024-01-21T12:34:22.093+0100] {dagbag.py:538} INFO - Filling up the DagBag from /home/ubuntu/airflow/dags/my_dag.py
[2024-01-21T12:34:23.797+0100] {logging_mixin.py:188} INFO - Nombre: 40
[2024-01-21T12:34:24.270+0100] {logging_mixin.py:188} INFO - Nombre: 60
[2024-01-21T12:34:24.799+0100] {logging_mixin.py:188} INFO - Nombre: 80
[2024-01-21T12:34:25.341+0100] {logging_mixin.py:188} INFO - Nombre: 100
[2024-01-21T12:34:26.013+0100] {logging_mixin.py:188} INFO - Nombre: 120
[2024-01-21T12:34:26.650+0100] {logging_mixin.py:188} INFO - Nombre: 140
[2024-01-21T12:34:27.243+0100] {logging_mixin.py:188} INFO - Nombre: 160
[2024-01-21T12:34:27.823+0100] {logging_mixin.py:188} INFO - Nombre: 180
[2024-01-21T12:34:28.335+0100] {logging_mixin.py:188} INFO - Nombre: 200
[2024-01-21T12:34:28.888+0100] {logging_mixin.py:188} INFO - Nombre: 220
[2024-01-21T12:34:29.404+0100] {logging_mixin.py:188} INFO - Nombre: 240
[2024-01-21T12:34:29.765+0100] {logging_mixin.py:188} INFO - Nombre: 260
[2024-01-21T12:34:30.187+0100] {logging_mixin.py:188} INFO - Nombre: 280
[2024-01-21T12:34:30.638+0100] {logging_mixin.py:188} INFO - Nombre: 300
[2024-01-21T12:34:31.042+0100] {logging_mixin.py:188} INFO - Nombre: 320
[2024-01-21T12:34:31.492+0100] {logging_mixin.py:188} INFO - Nombre: 340
[2024-01-21T12:34:31.987+0100] {logging_mixin.py:188} INFO - Nombre: 360
[2024-01-21T12:34:32.572+0100] {logging_mixin.py:188} INFO - Nombre: 380
[2024-01-21T12:34:33.065+0100] {logging_mixin.py:188} INFO - Nombre: 400
[2024-01-21T12:34:33.521+0100] {logging_mixin.py:188} INFO - Nombre: 420
[2024-01-21T12:34:34.045+0100] {logging_mixin.py:188} INFO - Nombre: 440
[2024-01-21T12:34:34.572+0100] {logging_mixin.py:188} INFO - Nombre: 460
[2024-01-21T12:34:35.081+0100] {logging_mixin.py:188} INFO - Nombre: 480
[2024-01-21T12:34:35.538+0100] {logging_mixin.py:188} INFO - Nombre: 500
[2024-01-21T12:34:35.979+0100] {logging_mixin.py:188} INFO - Nombre: 520
[2024-01-21T12:34:36.471+0100] {logging_mixin.py:188} INFO - Nombre: 540
[2024-01-21T12:34:37.046+0100] {logging_mixin.py:188} INFO - Nombre: 560
[2024-01-21T12:34:37.567+0100] {logging_mixin.py:188} INFO - Nombre: 580
[2024-01-21T12:34:38.106+0100] {logging_mixin.py:188} INFO - Nombre: 600
[2024-01-21T12:34:38.581+0100] {logging_mixin.py:188} INFO - Nombre: 620
[2024-01-21T12:34:39.152+0100] {logging_mixin.py:188} INFO - Nombre: 640
[2024-01-21T12:34:39.662+0100] {logging_mixin.py:188} INFO - Nombre: 660
[2024-01-21T12:34:40.127+0100] {logging_mixin.py:188} INFO - Nombre: 680
[2024-01-21T12:34:40.659+0100] {logging_mixin.py:188} INFO - Nombre: 700
[2024-01-21T12:34:41.519+0100] {logging_mixin.py:188} INFO - Nombre: 720
[2024-01-21T12:34:42.603+0100] {logging_mixin.py:188} INFO - Nombre: 740
[2024-01-21T12:34:43.282+0100] {logging_mixin.py:188} INFO - Nombre: 760
[2024-01-21T12:34:43.691+0100] {logging_mixin.py:188} INFO - Nombre: 780
[2024-01-21T12:34:44.254+0100] {logging_mixin.py:188} INFO - Nombre: 800
[2024-01-21T12:34:44.853+0100] {logging_mixin.py:188} INFO - Nombre: 820
[2024-01-21T12:34:45.527+0100] {logging_mixin.py:188} INFO - Nombre: 840
[2024-01-21T12:34:46.121+0100] {logging_mixin.py:188} INFO - Nombre: 860
[2024-01-21T12:34:46.721+0100] {logging_mixin.py:188} INFO - Nombre: 880
[2024-01-21T12:34:47.102+0100] {logging_mixin.py:188} INFO - Nombre: 900
[2024-01-21T12:34:47.489+0100] {logging_mixin.py:188} INFO - Nombre: 920
[2024-01-21T12:34:48.045+0100] {logging_mixin.py:188} INFO - Nombre: 940
[2024-01-21T12:34:48.512+0100] {logging_mixin.py:188} INFO - Nombre: 960
[2024-01-21T12:34:49.251+0100] {logging_mixin.py:188} INFO - Nombre: 980
[2024-01-21T12:34:49.852+0100] {logging_mixin.py:188} INFO - Nombre: 1000
[2024-01-21T12:34:50.209+0100] {logging_mixin.py:188} INFO - Nombre: 1020
[2024-01-21T12:34:50.691+0100] {logging_mixin.py:188} INFO - Nombre: 1040
[2024-01-21T12:34:51.259+0100] {logging_mixin.py:188} INFO - Nombre: 1060
[2024-01-21T12:34:51.695+0100] {logging_mixin.py:188} INFO - Nombre: 1080
[2024-01-21T12:34:52.080+0100] {logging_mixin.py:188} INFO - Nombre: 1100
[2024-01-21T12:34:52.100+0100] {logging_mixin.py:188} INFO - [2024-01-21T12:34:52.099+0100] {timeout.py:68} ERROR - Process timed out, PID: 5593
[2024-01-21T12:34:52.113+0100] {logging_mixin.py:188} INFO - [2024-01-21T12:34:52.100+0100] {dagbag.py:348} ERROR - Failed to import: /home/ubuntu/airflow/dags/my_dag.py
Traceback (most recent call last):
  File "/home/ubuntu/.local/lib/python3.10/site-packages/airflow/models/dagbag.py", line 344, in parse
    loader.exec_module(new_module)
  File "<frozen importlib._bootstrap_external>", line 883, in exec_module
  File "<frozen importlib._bootstrap>", line 241, in _call_with_frames_removed
  File "/home/ubuntu/airflow/dags/my_dag.py", line 5, in <module>
    from movies import find_popular_movies_and_save, get_movie_genres
  File "/home/ubuntu/airflow/dags/movies.py", line 45, in <module>
    find_popular_movies_and_save()
  File "/home/ubuntu/airflow/dags/movies.py", line 33, in find_popular_movies_and_save
    response = requests.get(base_url, params=params)
  File "/home/ubuntu/.local/lib/python3.10/site-packages/requests/api.py", line 73, in get
    return request("get", url, params=params, **kwargs)
  File "/home/ubuntu/.local/lib/python3.10/site-packages/requests/api.py", line 59, in request
    return session.request(method=method, url=url, **kwargs)
  File "/home/ubuntu/.local/lib/python3.10/site-packages/requests/sessions.py", line 589, in request
    resp = self.send(prep, **send_kwargs)
  File "/home/ubuntu/.local/lib/python3.10/site-packages/requests/sessions.py", line 703, in send
    r = adapter.send(request, **kwargs)
  File "/home/ubuntu/.local/lib/python3.10/site-packages/requests/adapters.py", line 486, in send
    resp = conn.urlopen(
  File "/home/ubuntu/.local/lib/python3.10/site-packages/urllib3/connectionpool.py", line 715, in urlopen
    httplib_response = self._make_request(
  File "/home/ubuntu/.local/lib/python3.10/site-packages/urllib3/connectionpool.py", line 404, in _make_request
    self._validate_conn(conn)
  File "/home/ubuntu/.local/lib/python3.10/site-packages/urllib3/connectionpool.py", line 1058, in _validate_conn
    conn.connect()
  File "/home/ubuntu/.local/lib/python3.10/site-packages/urllib3/connection.py", line 363, in connect
    self.sock = conn = self._new_conn()
  File "/home/ubuntu/.local/lib/python3.10/site-packages/urllib3/connection.py", line 174, in _new_conn
    conn = connection.create_connection(
  File "/home/ubuntu/.local/lib/python3.10/site-packages/urllib3/util/connection.py", line 85, in create_connection
    sock.connect(sa)
  File "/home/ubuntu/.local/lib/python3.10/site-packages/airflow/utils/timeout.py", line 69, in handle_timeout
    raise AirflowTaskTimeout(self.error_message)
airflow.exceptions.AirflowTaskTimeout: DagBag import timeout for /home/ubuntu/airflow/dags/my_dag.py after 30.0s.
Please take a look at these docs to improve your DAG import time:
* https://airflow.apache.org/docs/apache-airflow/2.8.0/best-practices.html#top-level-python-code
* https://airflow.apache.org/docs/apache-airflow/2.8.0/best-practices.html#reducing-dag-complexity, PID: 5593
[2024-01-21T12:34:52.122+0100] {processor.py:842} WARNING - No viable dags retrieved from /home/ubuntu/airflow/dags/my_dag.py
[2024-01-21T12:34:52.179+0100] {processor.py:183} INFO - Processing /home/ubuntu/airflow/dags/my_dag.py took 30.100 seconds
[2024-01-21T12:35:35.429+0100] {processor.py:161} INFO - Started process (PID=5639) to work on /home/ubuntu/airflow/dags/my_dag.py
[2024-01-21T12:35:35.456+0100] {processor.py:830} INFO - Processing file /home/ubuntu/airflow/dags/my_dag.py for tasks to queue
[2024-01-21T12:35:35.459+0100] {logging_mixin.py:188} INFO - [2024-01-21T12:35:35.458+0100] {dagbag.py:538} INFO - Filling up the DagBag from /home/ubuntu/airflow/dags/my_dag.py
[2024-01-21T12:35:37.213+0100] {logging_mixin.py:188} INFO - Nombre: 40
[2024-01-21T12:35:37.607+0100] {logging_mixin.py:188} INFO - Nombre: 60
[2024-01-21T12:35:38.239+0100] {logging_mixin.py:188} INFO - Nombre: 80
[2024-01-21T12:35:38.639+0100] {logging_mixin.py:188} INFO - Nombre: 100
[2024-01-21T12:35:39.115+0100] {logging_mixin.py:188} INFO - Nombre: 120
[2024-01-21T12:35:39.771+0100] {logging_mixin.py:188} INFO - Nombre: 140
[2024-01-21T12:35:40.198+0100] {logging_mixin.py:188} INFO - Nombre: 160
[2024-01-21T12:35:40.606+0100] {logging_mixin.py:188} INFO - Nombre: 180
[2024-01-21T12:35:41.129+0100] {logging_mixin.py:188} INFO - Nombre: 200
[2024-01-21T12:35:41.645+0100] {logging_mixin.py:188} INFO - Nombre: 220
[2024-01-21T12:35:42.205+0100] {logging_mixin.py:188} INFO - Nombre: 240
[2024-01-21T12:35:42.589+0100] {logging_mixin.py:188} INFO - Nombre: 260
[2024-01-21T12:35:43.128+0100] {logging_mixin.py:188} INFO - Nombre: 280
[2024-01-21T12:35:43.570+0100] {logging_mixin.py:188} INFO - Nombre: 300
[2024-01-21T12:35:44.025+0100] {logging_mixin.py:188} INFO - Nombre: 320
[2024-01-21T12:35:44.611+0100] {logging_mixin.py:188} INFO - Nombre: 340
[2024-01-21T12:35:45.245+0100] {logging_mixin.py:188} INFO - Nombre: 360
[2024-01-21T12:35:46.151+0100] {logging_mixin.py:188} INFO - Nombre: 380
[2024-01-21T12:35:46.721+0100] {logging_mixin.py:188} INFO - Nombre: 400
[2024-01-21T12:35:47.693+0100] {logging_mixin.py:188} INFO - Nombre: 420
[2024-01-21T12:35:48.353+0100] {logging_mixin.py:188} INFO - Nombre: 440
[2024-01-21T12:35:49.137+0100] {logging_mixin.py:188} INFO - Nombre: 460
[2024-01-21T12:35:49.756+0100] {logging_mixin.py:188} INFO - Nombre: 480
[2024-01-21T12:35:50.469+0100] {logging_mixin.py:188} INFO - Nombre: 500
[2024-01-21T12:35:50.971+0100] {logging_mixin.py:188} INFO - Nombre: 520
[2024-01-21T12:35:51.478+0100] {logging_mixin.py:188} INFO - Nombre: 540
[2024-01-21T12:35:51.876+0100] {logging_mixin.py:188} INFO - Nombre: 560
[2024-01-21T12:35:52.377+0100] {logging_mixin.py:188} INFO - Nombre: 580
[2024-01-21T12:35:52.826+0100] {logging_mixin.py:188} INFO - Nombre: 600
[2024-01-21T12:35:53.224+0100] {logging_mixin.py:188} INFO - Nombre: 620
[2024-01-21T12:35:53.645+0100] {logging_mixin.py:188} INFO - Nombre: 640
[2024-01-21T12:35:54.138+0100] {logging_mixin.py:188} INFO - Nombre: 660
[2024-01-21T12:35:54.551+0100] {logging_mixin.py:188} INFO - Nombre: 680
[2024-01-21T12:35:54.958+0100] {logging_mixin.py:188} INFO - Nombre: 700
[2024-01-21T12:35:55.316+0100] {logging_mixin.py:188} INFO - Nombre: 720
[2024-01-21T12:35:55.963+0100] {logging_mixin.py:188} INFO - Nombre: 740
[2024-01-21T12:35:56.352+0100] {logging_mixin.py:188} INFO - Nombre: 760
[2024-01-21T12:35:56.788+0100] {logging_mixin.py:188} INFO - Nombre: 780
[2024-01-21T12:35:57.192+0100] {logging_mixin.py:188} INFO - Nombre: 800
[2024-01-21T12:35:57.634+0100] {logging_mixin.py:188} INFO - Nombre: 820
[2024-01-21T12:35:58.126+0100] {logging_mixin.py:188} INFO - Nombre: 840
[2024-01-21T12:35:58.597+0100] {logging_mixin.py:188} INFO - Nombre: 860
[2024-01-21T12:35:59.404+0100] {logging_mixin.py:188} INFO - Nombre: 880
[2024-01-21T12:35:59.959+0100] {logging_mixin.py:188} INFO - Nombre: 900
[2024-01-21T12:36:00.558+0100] {logging_mixin.py:188} INFO - Nombre: 920
[2024-01-21T12:36:01.081+0100] {logging_mixin.py:188} INFO - Nombre: 940
[2024-01-21T12:36:01.842+0100] {logging_mixin.py:188} INFO - Nombre: 960
[2024-01-21T12:36:02.318+0100] {logging_mixin.py:188} INFO - Nombre: 980
[2024-01-21T12:36:02.921+0100] {logging_mixin.py:188} INFO - Nombre: 1000
[2024-01-21T12:36:03.439+0100] {logging_mixin.py:188} INFO - Nombre: 1020
[2024-01-21T12:36:04.183+0100] {logging_mixin.py:188} INFO - Nombre: 1040
[2024-01-21T12:36:04.713+0100] {logging_mixin.py:188} INFO - Nombre: 1060
[2024-01-21T12:36:05.097+0100] {logging_mixin.py:188} INFO - Nombre: 1080
[2024-01-21T12:36:05.475+0100] {logging_mixin.py:188} INFO - [2024-01-21T12:36:05.469+0100] {timeout.py:68} ERROR - Process timed out, PID: 5639
[2024-01-21T12:36:05.498+0100] {logging_mixin.py:188} INFO - [2024-01-21T12:36:05.480+0100] {dagbag.py:348} ERROR - Failed to import: /home/ubuntu/airflow/dags/my_dag.py
Traceback (most recent call last):
  File "/home/ubuntu/.local/lib/python3.10/site-packages/airflow/models/dagbag.py", line 344, in parse
    loader.exec_module(new_module)
  File "<frozen importlib._bootstrap_external>", line 883, in exec_module
  File "<frozen importlib._bootstrap>", line 241, in _call_with_frames_removed
  File "/home/ubuntu/airflow/dags/my_dag.py", line 5, in <module>
    from movies import find_popular_movies_and_save, get_movie_genres
  File "/home/ubuntu/airflow/dags/movies.py", line 45, in <module>
    find_popular_movies_and_save()
  File "/home/ubuntu/airflow/dags/movies.py", line 33, in find_popular_movies_and_save
    response = requests.get(base_url, params=params)
  File "/home/ubuntu/.local/lib/python3.10/site-packages/requests/api.py", line 73, in get
    return request("get", url, params=params, **kwargs)
  File "/home/ubuntu/.local/lib/python3.10/site-packages/requests/api.py", line 59, in request
    return session.request(method=method, url=url, **kwargs)
  File "/home/ubuntu/.local/lib/python3.10/site-packages/requests/sessions.py", line 589, in request
    resp = self.send(prep, **send_kwargs)
  File "/home/ubuntu/.local/lib/python3.10/site-packages/requests/sessions.py", line 703, in send
    r = adapter.send(request, **kwargs)
  File "/home/ubuntu/.local/lib/python3.10/site-packages/requests/adapters.py", line 486, in send
    resp = conn.urlopen(
  File "/home/ubuntu/.local/lib/python3.10/site-packages/urllib3/connectionpool.py", line 715, in urlopen
    httplib_response = self._make_request(
  File "/home/ubuntu/.local/lib/python3.10/site-packages/urllib3/connectionpool.py", line 404, in _make_request
    self._validate_conn(conn)
  File "/home/ubuntu/.local/lib/python3.10/site-packages/urllib3/connectionpool.py", line 1058, in _validate_conn
    conn.connect()
  File "/home/ubuntu/.local/lib/python3.10/site-packages/urllib3/connection.py", line 419, in connect
    self.sock = ssl_wrap_socket(
  File "/home/ubuntu/.local/lib/python3.10/site-packages/urllib3/util/ssl_.py", line 449, in ssl_wrap_socket
    ssl_sock = _ssl_wrap_socket_impl(
  File "/home/ubuntu/.local/lib/python3.10/site-packages/urllib3/util/ssl_.py", line 493, in _ssl_wrap_socket_impl
    return ssl_context.wrap_socket(sock, server_hostname=server_hostname)
  File "/usr/lib/python3.10/ssl.py", line 513, in wrap_socket
    return self.sslsocket_class._create(
  File "/usr/lib/python3.10/ssl.py", line 1100, in _create
    self.do_handshake()
  File "/usr/lib/python3.10/ssl.py", line 1371, in do_handshake
    self._sslobj.do_handshake()
  File "/home/ubuntu/.local/lib/python3.10/site-packages/airflow/utils/timeout.py", line 69, in handle_timeout
    raise AirflowTaskTimeout(self.error_message)
airflow.exceptions.AirflowTaskTimeout: DagBag import timeout for /home/ubuntu/airflow/dags/my_dag.py after 30.0s.
Please take a look at these docs to improve your DAG import time:
* https://airflow.apache.org/docs/apache-airflow/2.8.0/best-practices.html#top-level-python-code
* https://airflow.apache.org/docs/apache-airflow/2.8.0/best-practices.html#reducing-dag-complexity, PID: 5639
[2024-01-21T12:36:05.510+0100] {processor.py:842} WARNING - No viable dags retrieved from /home/ubuntu/airflow/dags/my_dag.py
[2024-01-21T12:36:05.600+0100] {processor.py:183} INFO - Processing /home/ubuntu/airflow/dags/my_dag.py took 30.202 seconds
[2024-01-21T12:36:51.647+0100] {processor.py:161} INFO - Started process (PID=5686) to work on /home/ubuntu/airflow/dags/my_dag.py
[2024-01-21T12:36:51.650+0100] {processor.py:830} INFO - Processing file /home/ubuntu/airflow/dags/my_dag.py for tasks to queue
[2024-01-21T12:36:51.653+0100] {logging_mixin.py:188} INFO - [2024-01-21T12:36:51.652+0100] {dagbag.py:538} INFO - Filling up the DagBag from /home/ubuntu/airflow/dags/my_dag.py
[2024-01-21T12:36:53.356+0100] {logging_mixin.py:188} INFO - Nombre: 40
[2024-01-21T12:36:53.982+0100] {logging_mixin.py:188} INFO - Nombre: 60
[2024-01-21T12:36:54.494+0100] {logging_mixin.py:188} INFO - Nombre: 80
[2024-01-21T12:36:54.987+0100] {logging_mixin.py:188} INFO - Nombre: 100
[2024-01-21T12:36:55.552+0100] {logging_mixin.py:188} INFO - Nombre: 120
[2024-01-21T12:36:56.009+0100] {logging_mixin.py:188} INFO - Nombre: 140
[2024-01-21T12:36:56.559+0100] {logging_mixin.py:188} INFO - Nombre: 160
[2024-01-21T12:36:56.999+0100] {logging_mixin.py:188} INFO - Nombre: 180
[2024-01-21T12:36:57.544+0100] {logging_mixin.py:188} INFO - Nombre: 200
[2024-01-21T12:36:57.968+0100] {logging_mixin.py:188} INFO - Nombre: 220
[2024-01-21T12:36:58.446+0100] {logging_mixin.py:188} INFO - Nombre: 240
[2024-01-21T12:36:58.961+0100] {logging_mixin.py:188} INFO - Nombre: 260
[2024-01-21T12:36:59.527+0100] {logging_mixin.py:188} INFO - Nombre: 280
[2024-01-21T12:36:59.919+0100] {logging_mixin.py:188} INFO - Nombre: 300
[2024-01-21T12:37:00.533+0100] {logging_mixin.py:188} INFO - Nombre: 320
[2024-01-21T12:37:00.893+0100] {logging_mixin.py:188} INFO - Nombre: 340
[2024-01-21T12:37:01.435+0100] {logging_mixin.py:188} INFO - Nombre: 360
[2024-01-21T12:37:01.934+0100] {logging_mixin.py:188} INFO - Nombre: 380
[2024-01-21T12:37:02.374+0100] {logging_mixin.py:188} INFO - Nombre: 400
[2024-01-21T12:37:02.728+0100] {logging_mixin.py:188} INFO - Nombre: 420
[2024-01-21T12:37:03.046+0100] {logging_mixin.py:188} INFO - Nombre: 440
[2024-01-21T12:37:03.456+0100] {logging_mixin.py:188} INFO - Nombre: 460
[2024-01-21T12:37:03.798+0100] {logging_mixin.py:188} INFO - Nombre: 480
[2024-01-21T12:37:04.154+0100] {logging_mixin.py:188} INFO - Nombre: 500
[2024-01-21T12:37:04.574+0100] {logging_mixin.py:188} INFO - Nombre: 520
[2024-01-21T12:37:05.069+0100] {logging_mixin.py:188} INFO - Nombre: 540
[2024-01-21T12:37:05.587+0100] {logging_mixin.py:188} INFO - Nombre: 560
[2024-01-21T12:37:06.011+0100] {logging_mixin.py:188} INFO - Nombre: 580
[2024-01-21T12:37:06.490+0100] {logging_mixin.py:188} INFO - Nombre: 600
[2024-01-21T12:37:07.031+0100] {logging_mixin.py:188} INFO - Nombre: 620
[2024-01-21T12:37:07.432+0100] {logging_mixin.py:188} INFO - Nombre: 640
[2024-01-21T12:37:07.793+0100] {logging_mixin.py:188} INFO - Nombre: 660
[2024-01-21T12:37:08.246+0100] {logging_mixin.py:188} INFO - Nombre: 680
[2024-01-21T12:37:08.627+0100] {logging_mixin.py:188} INFO - Nombre: 700
[2024-01-21T12:37:09.198+0100] {logging_mixin.py:188} INFO - Nombre: 720
[2024-01-21T12:37:09.871+0100] {logging_mixin.py:188} INFO - Nombre: 740
[2024-01-21T12:37:10.360+0100] {logging_mixin.py:188} INFO - Nombre: 760
[2024-01-21T12:37:10.798+0100] {logging_mixin.py:188} INFO - Nombre: 780
[2024-01-21T12:37:11.271+0100] {logging_mixin.py:188} INFO - Nombre: 800
[2024-01-21T12:37:11.758+0100] {logging_mixin.py:188} INFO - Nombre: 820
[2024-01-21T12:37:12.239+0100] {logging_mixin.py:188} INFO - Nombre: 840
[2024-01-21T12:37:12.731+0100] {logging_mixin.py:188} INFO - Nombre: 860
[2024-01-21T12:37:13.279+0100] {logging_mixin.py:188} INFO - Nombre: 880
[2024-01-21T12:37:13.740+0100] {logging_mixin.py:188} INFO - Nombre: 900
[2024-01-21T12:37:14.177+0100] {logging_mixin.py:188} INFO - Nombre: 920
[2024-01-21T12:37:14.631+0100] {logging_mixin.py:188} INFO - Nombre: 940
[2024-01-21T12:37:15.111+0100] {logging_mixin.py:188} INFO - Nombre: 960
[2024-01-21T12:37:15.609+0100] {logging_mixin.py:188} INFO - Nombre: 980
[2024-01-21T12:37:16.054+0100] {logging_mixin.py:188} INFO - Nombre: 1000
[2024-01-21T12:37:16.486+0100] {logging_mixin.py:188} INFO - Nombre: 1020
[2024-01-21T12:37:17.088+0100] {logging_mixin.py:188} INFO - Nombre: 1040
[2024-01-21T12:37:17.600+0100] {logging_mixin.py:188} INFO - Nombre: 1060
[2024-01-21T12:37:18.146+0100] {logging_mixin.py:188} INFO - Nombre: 1080
[2024-01-21T12:37:18.626+0100] {logging_mixin.py:188} INFO - Nombre: 1100
[2024-01-21T12:37:19.112+0100] {logging_mixin.py:188} INFO - Nombre: 1120
[2024-01-21T12:37:19.666+0100] {logging_mixin.py:188} INFO - Nombre: 1140
[2024-01-21T12:37:20.200+0100] {logging_mixin.py:188} INFO - Nombre: 1160
[2024-01-21T12:37:20.639+0100] {logging_mixin.py:188} INFO - Nombre: 1180
[2024-01-21T12:37:21.288+0100] {logging_mixin.py:188} INFO - Nombre: 1200
[2024-01-21T12:37:21.664+0100] {logging_mixin.py:188} INFO - [2024-01-21T12:37:21.662+0100] {timeout.py:68} ERROR - Process timed out, PID: 5686
[2024-01-21T12:37:21.700+0100] {logging_mixin.py:188} INFO - [2024-01-21T12:37:21.670+0100] {dagbag.py:348} ERROR - Failed to import: /home/ubuntu/airflow/dags/my_dag.py
Traceback (most recent call last):
  File "/home/ubuntu/.local/lib/python3.10/site-packages/airflow/models/dagbag.py", line 344, in parse
    loader.exec_module(new_module)
  File "<frozen importlib._bootstrap_external>", line 883, in exec_module
  File "<frozen importlib._bootstrap>", line 241, in _call_with_frames_removed
  File "/home/ubuntu/airflow/dags/my_dag.py", line 5, in <module>
    from movies import find_popular_movies_and_save, get_movie_genres
  File "/home/ubuntu/airflow/dags/movies.py", line 45, in <module>
    find_popular_movies_and_save()
  File "/home/ubuntu/airflow/dags/movies.py", line 33, in find_popular_movies_and_save
    response = requests.get(base_url, params=params)
  File "/home/ubuntu/.local/lib/python3.10/site-packages/requests/api.py", line 73, in get
    return request("get", url, params=params, **kwargs)
  File "/home/ubuntu/.local/lib/python3.10/site-packages/requests/api.py", line 59, in request
    return session.request(method=method, url=url, **kwargs)
  File "/home/ubuntu/.local/lib/python3.10/site-packages/requests/sessions.py", line 589, in request
    resp = self.send(prep, **send_kwargs)
  File "/home/ubuntu/.local/lib/python3.10/site-packages/requests/sessions.py", line 703, in send
    r = adapter.send(request, **kwargs)
  File "/home/ubuntu/.local/lib/python3.10/site-packages/requests/adapters.py", line 486, in send
    resp = conn.urlopen(
  File "/home/ubuntu/.local/lib/python3.10/site-packages/urllib3/connectionpool.py", line 715, in urlopen
    httplib_response = self._make_request(
  File "/home/ubuntu/.local/lib/python3.10/site-packages/urllib3/connectionpool.py", line 467, in _make_request
    six.raise_from(e, None)
  File "<string>", line 3, in raise_from
  File "/home/ubuntu/.local/lib/python3.10/site-packages/urllib3/connectionpool.py", line 462, in _make_request
    httplib_response = conn.getresponse()
  File "/usr/lib/python3.10/http/client.py", line 1375, in getresponse
    response.begin()
  File "/usr/lib/python3.10/http/client.py", line 318, in begin
    version, status, reason = self._read_status()
  File "/usr/lib/python3.10/http/client.py", line 279, in _read_status
    line = str(self.fp.readline(_MAXLINE + 1), "iso-8859-1")
  File "/usr/lib/python3.10/socket.py", line 705, in readinto
    return self._sock.recv_into(b)
  File "/usr/lib/python3.10/ssl.py", line 1303, in recv_into
    return self.read(nbytes, buffer)
  File "/usr/lib/python3.10/ssl.py", line 1159, in read
    return self._sslobj.read(len, buffer)
  File "/home/ubuntu/.local/lib/python3.10/site-packages/airflow/utils/timeout.py", line 69, in handle_timeout
    raise AirflowTaskTimeout(self.error_message)
airflow.exceptions.AirflowTaskTimeout: DagBag import timeout for /home/ubuntu/airflow/dags/my_dag.py after 30.0s.
Please take a look at these docs to improve your DAG import time:
* https://airflow.apache.org/docs/apache-airflow/2.8.0/best-practices.html#top-level-python-code
* https://airflow.apache.org/docs/apache-airflow/2.8.0/best-practices.html#reducing-dag-complexity, PID: 5686
[2024-01-21T12:37:21.710+0100] {processor.py:842} WARNING - No viable dags retrieved from /home/ubuntu/airflow/dags/my_dag.py
[2024-01-21T12:37:21.772+0100] {processor.py:183} INFO - Processing /home/ubuntu/airflow/dags/my_dag.py took 30.130 seconds
[2024-01-21T12:38:07.131+0100] {processor.py:161} INFO - Started process (PID=5725) to work on /home/ubuntu/airflow/dags/my_dag.py
[2024-01-21T12:38:07.154+0100] {processor.py:830} INFO - Processing file /home/ubuntu/airflow/dags/my_dag.py for tasks to queue
[2024-01-21T12:38:07.156+0100] {logging_mixin.py:188} INFO - [2024-01-21T12:38:07.156+0100] {dagbag.py:538} INFO - Filling up the DagBag from /home/ubuntu/airflow/dags/my_dag.py
[2024-01-21T12:38:08.789+0100] {logging_mixin.py:188} INFO - Nombre: 40
[2024-01-21T12:38:09.427+0100] {logging_mixin.py:188} INFO - Nombre: 60
[2024-01-21T12:38:09.998+0100] {logging_mixin.py:188} INFO - Nombre: 80
[2024-01-21T12:38:10.477+0100] {logging_mixin.py:188} INFO - Nombre: 100
[2024-01-21T12:38:11.075+0100] {logging_mixin.py:188} INFO - Nombre: 120
[2024-01-21T12:38:11.615+0100] {logging_mixin.py:188} INFO - Nombre: 140
[2024-01-21T12:38:12.278+0100] {logging_mixin.py:188} INFO - Nombre: 160
[2024-01-21T12:38:12.773+0100] {logging_mixin.py:188} INFO - Nombre: 180
[2024-01-21T12:38:13.242+0100] {logging_mixin.py:188} INFO - Nombre: 200
[2024-01-21T12:38:13.690+0100] {logging_mixin.py:188} INFO - Nombre: 220
[2024-01-21T12:38:14.265+0100] {logging_mixin.py:188} INFO - Nombre: 240
[2024-01-21T12:38:14.706+0100] {logging_mixin.py:188} INFO - Nombre: 260
[2024-01-21T12:38:15.222+0100] {logging_mixin.py:188} INFO - Nombre: 280
[2024-01-21T12:38:15.632+0100] {logging_mixin.py:188} INFO - Nombre: 300
[2024-01-21T12:38:16.626+0100] {logging_mixin.py:188} INFO - Nombre: 320
[2024-01-21T12:38:17.312+0100] {logging_mixin.py:188} INFO - Nombre: 340
[2024-01-21T12:38:17.869+0100] {logging_mixin.py:188} INFO - Nombre: 360
[2024-01-21T12:38:18.388+0100] {logging_mixin.py:188} INFO - Nombre: 380
[2024-01-21T12:38:18.921+0100] {logging_mixin.py:188} INFO - Nombre: 400
[2024-01-21T12:38:19.481+0100] {logging_mixin.py:188} INFO - Nombre: 420
[2024-01-21T12:38:19.948+0100] {logging_mixin.py:188} INFO - Nombre: 440
[2024-01-21T12:38:20.465+0100] {logging_mixin.py:188} INFO - Nombre: 460
[2024-01-21T12:38:20.962+0100] {logging_mixin.py:188} INFO - Nombre: 480
[2024-01-21T12:38:21.461+0100] {logging_mixin.py:188} INFO - Nombre: 500
[2024-01-21T12:38:21.910+0100] {logging_mixin.py:188} INFO - Nombre: 520
[2024-01-21T12:38:22.323+0100] {logging_mixin.py:188} INFO - Nombre: 540
[2024-01-21T12:38:22.803+0100] {logging_mixin.py:188} INFO - Nombre: 560
[2024-01-21T12:38:23.187+0100] {logging_mixin.py:188} INFO - Nombre: 580
[2024-01-21T12:38:23.551+0100] {logging_mixin.py:188} INFO - Nombre: 600
[2024-01-21T12:38:24.004+0100] {logging_mixin.py:188} INFO - Nombre: 620
[2024-01-21T12:38:24.468+0100] {logging_mixin.py:188} INFO - Nombre: 640
[2024-01-21T12:38:24.838+0100] {logging_mixin.py:188} INFO - Nombre: 660
[2024-01-21T12:38:25.239+0100] {logging_mixin.py:188} INFO - Nombre: 680
[2024-01-21T12:38:25.704+0100] {logging_mixin.py:188} INFO - Nombre: 700
[2024-01-21T12:38:26.232+0100] {logging_mixin.py:188} INFO - Nombre: 720
[2024-01-21T12:38:26.641+0100] {logging_mixin.py:188} INFO - Nombre: 740
[2024-01-21T12:38:27.097+0100] {logging_mixin.py:188} INFO - Nombre: 760
[2024-01-21T12:38:27.625+0100] {logging_mixin.py:188} INFO - Nombre: 780
[2024-01-21T12:38:27.997+0100] {logging_mixin.py:188} INFO - Nombre: 800
[2024-01-21T12:38:28.458+0100] {logging_mixin.py:188} INFO - Nombre: 820
[2024-01-21T12:38:28.958+0100] {logging_mixin.py:188} INFO - Nombre: 840
[2024-01-21T12:38:29.445+0100] {logging_mixin.py:188} INFO - Nombre: 860
[2024-01-21T12:38:29.921+0100] {logging_mixin.py:188} INFO - Nombre: 880
[2024-01-21T12:38:30.252+0100] {logging_mixin.py:188} INFO - Nombre: 900
[2024-01-21T12:38:30.690+0100] {logging_mixin.py:188} INFO - Nombre: 920
[2024-01-21T12:38:31.123+0100] {logging_mixin.py:188} INFO - Nombre: 940
[2024-01-21T12:38:31.646+0100] {logging_mixin.py:188} INFO - Nombre: 960
[2024-01-21T12:38:32.106+0100] {logging_mixin.py:188} INFO - Nombre: 980
[2024-01-21T12:38:32.486+0100] {logging_mixin.py:188} INFO - Nombre: 1000
[2024-01-21T12:38:32.949+0100] {logging_mixin.py:188} INFO - Nombre: 1020
[2024-01-21T12:38:33.367+0100] {logging_mixin.py:188} INFO - Nombre: 1040
[2024-01-21T12:38:33.798+0100] {logging_mixin.py:188} INFO - Nombre: 1060
[2024-01-21T12:38:34.248+0100] {logging_mixin.py:188} INFO - Nombre: 1080
[2024-01-21T12:38:34.696+0100] {logging_mixin.py:188} INFO - Nombre: 1100
[2024-01-21T12:38:35.318+0100] {logging_mixin.py:188} INFO - Nombre: 1120
[2024-01-21T12:38:35.734+0100] {logging_mixin.py:188} INFO - Nombre: 1140
[2024-01-21T12:38:36.099+0100] {logging_mixin.py:188} INFO - Nombre: 1160
[2024-01-21T12:38:36.420+0100] {logging_mixin.py:188} INFO - Nombre: 1180
[2024-01-21T12:38:36.710+0100] {logging_mixin.py:188} INFO - Nombre: 1200
[2024-01-21T12:38:37.083+0100] {logging_mixin.py:188} INFO - Nombre: 1220
[2024-01-21T12:38:37.275+0100] {logging_mixin.py:188} INFO - [2024-01-21T12:38:37.275+0100] {timeout.py:68} ERROR - Process timed out, PID: 5725
[2024-01-21T12:38:37.282+0100] {logging_mixin.py:188} INFO - [2024-01-21T12:38:37.276+0100] {dagbag.py:348} ERROR - Failed to import: /home/ubuntu/airflow/dags/my_dag.py
Traceback (most recent call last):
  File "/home/ubuntu/.local/lib/python3.10/site-packages/airflow/models/dagbag.py", line 344, in parse
    loader.exec_module(new_module)
  File "<frozen importlib._bootstrap_external>", line 883, in exec_module
  File "<frozen importlib._bootstrap>", line 241, in _call_with_frames_removed
  File "/home/ubuntu/airflow/dags/my_dag.py", line 5, in <module>
    from movies import find_popular_movies_and_save, get_movie_genres
  File "/home/ubuntu/airflow/dags/movies.py", line 45, in <module>
    find_popular_movies_and_save()
  File "/home/ubuntu/airflow/dags/movies.py", line 33, in find_popular_movies_and_save
    response = requests.get(base_url, params=params)
  File "/home/ubuntu/.local/lib/python3.10/site-packages/requests/api.py", line 73, in get
    return request("get", url, params=params, **kwargs)
  File "/home/ubuntu/.local/lib/python3.10/site-packages/requests/api.py", line 59, in request
    return session.request(method=method, url=url, **kwargs)
  File "/home/ubuntu/.local/lib/python3.10/site-packages/requests/sessions.py", line 589, in request
    resp = self.send(prep, **send_kwargs)
  File "/home/ubuntu/.local/lib/python3.10/site-packages/requests/sessions.py", line 703, in send
    r = adapter.send(request, **kwargs)
  File "/home/ubuntu/.local/lib/python3.10/site-packages/requests/adapters.py", line 486, in send
    resp = conn.urlopen(
  File "/home/ubuntu/.local/lib/python3.10/site-packages/urllib3/connectionpool.py", line 715, in urlopen
    httplib_response = self._make_request(
  File "/home/ubuntu/.local/lib/python3.10/site-packages/urllib3/connectionpool.py", line 404, in _make_request
    self._validate_conn(conn)
  File "/home/ubuntu/.local/lib/python3.10/site-packages/urllib3/connectionpool.py", line 1058, in _validate_conn
    conn.connect()
  File "/home/ubuntu/.local/lib/python3.10/site-packages/urllib3/connection.py", line 419, in connect
    self.sock = ssl_wrap_socket(
  File "/home/ubuntu/.local/lib/python3.10/site-packages/urllib3/util/ssl_.py", line 402, in ssl_wrap_socket
    context.load_verify_locations(ca_certs, ca_cert_dir, ca_cert_data)
  File "/home/ubuntu/.local/lib/python3.10/site-packages/airflow/utils/timeout.py", line 69, in handle_timeout
    raise AirflowTaskTimeout(self.error_message)
airflow.exceptions.AirflowTaskTimeout: DagBag import timeout for /home/ubuntu/airflow/dags/my_dag.py after 30.0s.
Please take a look at these docs to improve your DAG import time:
* https://airflow.apache.org/docs/apache-airflow/2.8.0/best-practices.html#top-level-python-code
* https://airflow.apache.org/docs/apache-airflow/2.8.0/best-practices.html#reducing-dag-complexity, PID: 5725
[2024-01-21T12:38:37.286+0100] {processor.py:842} WARNING - No viable dags retrieved from /home/ubuntu/airflow/dags/my_dag.py
[2024-01-21T12:38:37.316+0100] {processor.py:183} INFO - Processing /home/ubuntu/airflow/dags/my_dag.py took 30.205 seconds
[2024-01-21T12:39:16.068+0100] {processor.py:161} INFO - Started process (PID=5764) to work on /home/ubuntu/airflow/dags/my_dag.py
[2024-01-21T12:39:16.073+0100] {processor.py:830} INFO - Processing file /home/ubuntu/airflow/dags/my_dag.py for tasks to queue
[2024-01-21T12:39:16.074+0100] {logging_mixin.py:188} INFO - [2024-01-21T12:39:16.074+0100] {dagbag.py:538} INFO - Filling up the DagBag from /home/ubuntu/airflow/dags/my_dag.py
[2024-01-21T12:39:17.032+0100] {logging_mixin.py:188} INFO - Nombre: 40
[2024-01-21T12:39:17.462+0100] {logging_mixin.py:188} INFO - Nombre: 60
[2024-01-21T12:39:17.798+0100] {logging_mixin.py:188} INFO - Nombre: 80
[2024-01-21T12:39:18.159+0100] {logging_mixin.py:188} INFO - Nombre: 100
[2024-01-21T12:39:18.497+0100] {logging_mixin.py:188} INFO - Nombre: 120
[2024-01-21T12:39:18.881+0100] {logging_mixin.py:188} INFO - Nombre: 140
[2024-01-21T12:39:19.264+0100] {logging_mixin.py:188} INFO - Nombre: 160
[2024-01-21T12:39:19.682+0100] {logging_mixin.py:188} INFO - Nombre: 180
[2024-01-21T12:39:20.005+0100] {logging_mixin.py:188} INFO - Nombre: 200
[2024-01-21T12:39:20.435+0100] {logging_mixin.py:188} INFO - Nombre: 220
[2024-01-21T12:39:20.771+0100] {logging_mixin.py:188} INFO - Nombre: 240
[2024-01-21T12:39:21.092+0100] {logging_mixin.py:188} INFO - Nombre: 260
[2024-01-21T12:39:21.480+0100] {logging_mixin.py:188} INFO - Nombre: 280
[2024-01-21T12:39:21.837+0100] {logging_mixin.py:188} INFO - Nombre: 300
[2024-01-21T12:39:22.238+0100] {logging_mixin.py:188} INFO - Nombre: 320
[2024-01-21T12:39:22.769+0100] {logging_mixin.py:188} INFO - Nombre: 340
[2024-01-21T12:39:23.100+0100] {logging_mixin.py:188} INFO - Nombre: 360
[2024-01-21T12:39:23.534+0100] {logging_mixin.py:188} INFO - Nombre: 380
[2024-01-21T12:39:23.884+0100] {logging_mixin.py:188} INFO - Nombre: 400
[2024-01-21T12:39:24.248+0100] {logging_mixin.py:188} INFO - Nombre: 420
[2024-01-21T12:39:24.670+0100] {logging_mixin.py:188} INFO - Nombre: 440
[2024-01-21T12:39:25.037+0100] {logging_mixin.py:188} INFO - Nombre: 460
[2024-01-21T12:39:25.497+0100] {logging_mixin.py:188} INFO - Nombre: 480
[2024-01-21T12:39:25.882+0100] {logging_mixin.py:188} INFO - Nombre: 500
[2024-01-21T12:39:26.336+0100] {logging_mixin.py:188} INFO - Nombre: 520
[2024-01-21T12:39:26.770+0100] {logging_mixin.py:188} INFO - Nombre: 540
[2024-01-21T12:39:27.180+0100] {logging_mixin.py:188} INFO - Nombre: 560
[2024-01-21T12:39:27.575+0100] {logging_mixin.py:188} INFO - Nombre: 580
[2024-01-21T12:39:27.872+0100] {logging_mixin.py:188} INFO - Nombre: 600
[2024-01-21T12:39:28.295+0100] {logging_mixin.py:188} INFO - Nombre: 620
[2024-01-21T12:39:28.690+0100] {logging_mixin.py:188} INFO - Nombre: 640
[2024-01-21T12:39:29.236+0100] {logging_mixin.py:188} INFO - Nombre: 660
[2024-01-21T12:39:29.643+0100] {logging_mixin.py:188} INFO - Nombre: 680
[2024-01-21T12:39:30.278+0100] {logging_mixin.py:188} INFO - Nombre: 700
[2024-01-21T12:39:31.010+0100] {logging_mixin.py:188} INFO - Nombre: 720
[2024-01-21T12:39:32.363+0100] {logging_mixin.py:188} INFO - Nombre: 740
[2024-01-21T12:39:32.825+0100] {logging_mixin.py:188} INFO - Nombre: 760
[2024-01-21T12:39:33.196+0100] {logging_mixin.py:188} INFO - Nombre: 780
[2024-01-21T12:39:33.649+0100] {logging_mixin.py:188} INFO - Nombre: 800
[2024-01-21T12:39:34.195+0100] {logging_mixin.py:188} INFO - Nombre: 820
[2024-01-21T12:39:34.682+0100] {logging_mixin.py:188} INFO - Nombre: 840
[2024-01-21T12:39:35.289+0100] {logging_mixin.py:188} INFO - Nombre: 860
[2024-01-21T12:39:35.753+0100] {logging_mixin.py:188} INFO - Nombre: 880
[2024-01-21T12:39:36.138+0100] {logging_mixin.py:188} INFO - Nombre: 900
[2024-01-21T12:39:36.480+0100] {logging_mixin.py:188} INFO - Nombre: 920
[2024-01-21T12:39:36.803+0100] {logging_mixin.py:188} INFO - Nombre: 940
[2024-01-21T12:39:37.127+0100] {logging_mixin.py:188} INFO - Nombre: 960
[2024-01-21T12:39:37.484+0100] {logging_mixin.py:188} INFO - Nombre: 980
[2024-01-21T12:39:37.848+0100] {logging_mixin.py:188} INFO - Nombre: 1000
[2024-01-21T12:39:38.245+0100] {logging_mixin.py:188} INFO - Nombre: 1020
[2024-01-21T12:39:38.617+0100] {logging_mixin.py:188} INFO - Nombre: 1040
[2024-01-21T12:39:38.956+0100] {logging_mixin.py:188} INFO - Nombre: 1060
[2024-01-21T12:39:39.314+0100] {logging_mixin.py:188} INFO - Nombre: 1080
[2024-01-21T12:39:39.722+0100] {logging_mixin.py:188} INFO - Nombre: 1100
[2024-01-21T12:39:40.099+0100] {logging_mixin.py:188} INFO - Nombre: 1120
[2024-01-21T12:39:40.477+0100] {logging_mixin.py:188} INFO - Nombre: 1140
[2024-01-21T12:39:40.825+0100] {logging_mixin.py:188} INFO - Nombre: 1160
[2024-01-21T12:39:41.163+0100] {logging_mixin.py:188} INFO - Nombre: 1180
[2024-01-21T12:39:41.552+0100] {logging_mixin.py:188} INFO - Nombre: 1200
[2024-01-21T12:39:41.842+0100] {logging_mixin.py:188} INFO - Nombre: 1220
[2024-01-21T12:39:42.236+0100] {logging_mixin.py:188} INFO - Nombre: 1240
[2024-01-21T12:39:42.646+0100] {logging_mixin.py:188} INFO - Nombre: 1260
[2024-01-21T12:39:43.022+0100] {logging_mixin.py:188} INFO - Nombre: 1280
[2024-01-21T12:39:43.485+0100] {logging_mixin.py:188} INFO - Nombre: 1300
[2024-01-21T12:39:43.999+0100] {logging_mixin.py:188} INFO - Nombre: 1320
[2024-01-21T12:39:44.471+0100] {logging_mixin.py:188} INFO - Nombre: 1340
[2024-01-21T12:39:45.003+0100] {logging_mixin.py:188} INFO - Nombre: 1360
[2024-01-21T12:39:45.636+0100] {logging_mixin.py:188} INFO - Nombre: 1380
[2024-01-21T12:39:46.085+0100] {logging_mixin.py:188} INFO - [2024-01-21T12:39:46.081+0100] {timeout.py:68} ERROR - Process timed out, PID: 5764
[2024-01-21T12:39:46.104+0100] {logging_mixin.py:188} INFO - [2024-01-21T12:39:46.087+0100] {dagbag.py:348} ERROR - Failed to import: /home/ubuntu/airflow/dags/my_dag.py
Traceback (most recent call last):
  File "/home/ubuntu/.local/lib/python3.10/site-packages/airflow/models/dagbag.py", line 344, in parse
    loader.exec_module(new_module)
  File "<frozen importlib._bootstrap_external>", line 883, in exec_module
  File "<frozen importlib._bootstrap>", line 241, in _call_with_frames_removed
  File "/home/ubuntu/airflow/dags/my_dag.py", line 5, in <module>
    from movies import find_popular_movies_and_save, get_movie_genres
  File "/home/ubuntu/airflow/dags/movies.py", line 45, in <module>
    find_popular_movies_and_save()
  File "/home/ubuntu/airflow/dags/movies.py", line 33, in find_popular_movies_and_save
    response = requests.get(base_url, params=params)
  File "/home/ubuntu/.local/lib/python3.10/site-packages/requests/api.py", line 73, in get
    return request("get", url, params=params, **kwargs)
  File "/home/ubuntu/.local/lib/python3.10/site-packages/requests/api.py", line 59, in request
    return session.request(method=method, url=url, **kwargs)
  File "/home/ubuntu/.local/lib/python3.10/site-packages/requests/sessions.py", line 589, in request
    resp = self.send(prep, **send_kwargs)
  File "/home/ubuntu/.local/lib/python3.10/site-packages/requests/sessions.py", line 703, in send
    r = adapter.send(request, **kwargs)
  File "/home/ubuntu/.local/lib/python3.10/site-packages/requests/adapters.py", line 486, in send
    resp = conn.urlopen(
  File "/home/ubuntu/.local/lib/python3.10/site-packages/urllib3/connectionpool.py", line 715, in urlopen
    httplib_response = self._make_request(
  File "/home/ubuntu/.local/lib/python3.10/site-packages/urllib3/connectionpool.py", line 467, in _make_request
    six.raise_from(e, None)
  File "<string>", line 3, in raise_from
  File "/home/ubuntu/.local/lib/python3.10/site-packages/urllib3/connectionpool.py", line 462, in _make_request
    httplib_response = conn.getresponse()
  File "/usr/lib/python3.10/http/client.py", line 1375, in getresponse
    response.begin()
  File "/usr/lib/python3.10/http/client.py", line 318, in begin
    version, status, reason = self._read_status()
  File "/usr/lib/python3.10/http/client.py", line 279, in _read_status
    line = str(self.fp.readline(_MAXLINE + 1), "iso-8859-1")
  File "/usr/lib/python3.10/socket.py", line 705, in readinto
    return self._sock.recv_into(b)
  File "/usr/lib/python3.10/ssl.py", line 1303, in recv_into
    return self.read(nbytes, buffer)
  File "/usr/lib/python3.10/ssl.py", line 1159, in read
    return self._sslobj.read(len, buffer)
  File "/home/ubuntu/.local/lib/python3.10/site-packages/airflow/utils/timeout.py", line 69, in handle_timeout
    raise AirflowTaskTimeout(self.error_message)
airflow.exceptions.AirflowTaskTimeout: DagBag import timeout for /home/ubuntu/airflow/dags/my_dag.py after 30.0s.
Please take a look at these docs to improve your DAG import time:
* https://airflow.apache.org/docs/apache-airflow/2.8.0/best-practices.html#top-level-python-code
* https://airflow.apache.org/docs/apache-airflow/2.8.0/best-practices.html#reducing-dag-complexity, PID: 5764
[2024-01-21T12:39:46.111+0100] {processor.py:842} WARNING - No viable dags retrieved from /home/ubuntu/airflow/dags/my_dag.py
[2024-01-21T12:39:46.153+0100] {processor.py:183} INFO - Processing /home/ubuntu/airflow/dags/my_dag.py took 30.094 seconds
[2024-01-21T12:40:18.127+0100] {processor.py:161} INFO - Started process (PID=5792) to work on /home/ubuntu/airflow/dags/my_dag.py
[2024-01-21T12:40:18.131+0100] {processor.py:830} INFO - Processing file /home/ubuntu/airflow/dags/my_dag.py for tasks to queue
[2024-01-21T12:40:18.133+0100] {logging_mixin.py:188} INFO - [2024-01-21T12:40:18.133+0100] {dagbag.py:538} INFO - Filling up the DagBag from /home/ubuntu/airflow/dags/my_dag.py
[2024-01-21T12:40:19.268+0100] {logging_mixin.py:188} INFO - Nombre: 40
[2024-01-21T12:40:19.674+0100] {logging_mixin.py:188} INFO - Nombre: 60
[2024-01-21T12:40:20.074+0100] {logging_mixin.py:188} INFO - Nombre: 80
[2024-01-21T12:40:20.521+0100] {logging_mixin.py:188} INFO - Nombre: 100
[2024-01-21T12:40:21.007+0100] {logging_mixin.py:188} INFO - Nombre: 120
[2024-01-21T12:40:21.412+0100] {logging_mixin.py:188} INFO - Nombre: 140
[2024-01-21T12:40:21.743+0100] {logging_mixin.py:188} INFO - Nombre: 160
[2024-01-21T12:40:22.133+0100] {logging_mixin.py:188} INFO - Nombre: 180
[2024-01-21T12:40:22.603+0100] {logging_mixin.py:188} INFO - Nombre: 200
[2024-01-21T12:40:22.967+0100] {logging_mixin.py:188} INFO - Nombre: 220
[2024-01-21T12:40:23.350+0100] {logging_mixin.py:188} INFO - Nombre: 240
[2024-01-21T12:40:23.750+0100] {logging_mixin.py:188} INFO - Nombre: 260
[2024-01-21T12:40:24.137+0100] {logging_mixin.py:188} INFO - Nombre: 280
[2024-01-21T12:40:24.485+0100] {logging_mixin.py:188} INFO - Nombre: 300
[2024-01-21T12:40:24.826+0100] {logging_mixin.py:188} INFO - Nombre: 320
[2024-01-21T12:40:25.158+0100] {logging_mixin.py:188} INFO - Nombre: 340
[2024-01-21T12:40:25.522+0100] {logging_mixin.py:188} INFO - Nombre: 360
[2024-01-21T12:40:25.898+0100] {logging_mixin.py:188} INFO - Nombre: 380
[2024-01-21T12:40:26.200+0100] {logging_mixin.py:188} INFO - Nombre: 400
[2024-01-21T12:40:26.570+0100] {logging_mixin.py:188} INFO - Nombre: 420
[2024-01-21T12:40:26.957+0100] {logging_mixin.py:188} INFO - Nombre: 440
[2024-01-21T12:40:27.310+0100] {logging_mixin.py:188} INFO - Nombre: 460
[2024-01-21T12:40:27.808+0100] {logging_mixin.py:188} INFO - Nombre: 480
[2024-01-21T12:40:28.223+0100] {logging_mixin.py:188} INFO - Nombre: 500
[2024-01-21T12:40:28.683+0100] {logging_mixin.py:188} INFO - Nombre: 520
[2024-01-21T12:40:29.168+0100] {logging_mixin.py:188} INFO - Nombre: 540
[2024-01-21T12:40:29.611+0100] {logging_mixin.py:188} INFO - Nombre: 560
[2024-01-21T12:40:29.909+0100] {logging_mixin.py:188} INFO - Nombre: 580
[2024-01-21T12:40:30.276+0100] {logging_mixin.py:188} INFO - Nombre: 600
[2024-01-21T12:40:30.712+0100] {logging_mixin.py:188} INFO - Nombre: 620
[2024-01-21T12:40:31.094+0100] {logging_mixin.py:188} INFO - Nombre: 640
[2024-01-21T12:40:31.489+0100] {logging_mixin.py:188} INFO - Nombre: 660
[2024-01-21T12:40:31.786+0100] {logging_mixin.py:188} INFO - Nombre: 680
[2024-01-21T12:40:32.161+0100] {logging_mixin.py:188} INFO - Nombre: 700
[2024-01-21T12:40:32.556+0100] {logging_mixin.py:188} INFO - Nombre: 720
[2024-01-21T12:40:32.915+0100] {logging_mixin.py:188} INFO - Nombre: 740
[2024-01-21T12:40:33.287+0100] {logging_mixin.py:188} INFO - Nombre: 760
[2024-01-21T12:40:33.769+0100] {logging_mixin.py:188} INFO - Nombre: 780
[2024-01-21T12:40:34.159+0100] {logging_mixin.py:188} INFO - Nombre: 800
[2024-01-21T12:40:34.614+0100] {logging_mixin.py:188} INFO - Nombre: 820
[2024-01-21T12:40:35.167+0100] {logging_mixin.py:188} INFO - Nombre: 840
[2024-01-21T12:40:35.515+0100] {logging_mixin.py:188} INFO - Nombre: 860
[2024-01-21T12:40:35.854+0100] {logging_mixin.py:188} INFO - Nombre: 880
[2024-01-21T12:40:36.197+0100] {logging_mixin.py:188} INFO - Nombre: 900
[2024-01-21T12:40:36.512+0100] {logging_mixin.py:188} INFO - Nombre: 920
[2024-01-21T12:40:36.853+0100] {logging_mixin.py:188} INFO - Nombre: 940
[2024-01-21T12:40:37.237+0100] {logging_mixin.py:188} INFO - Nombre: 960
[2024-01-21T12:40:37.719+0100] {logging_mixin.py:188} INFO - Nombre: 980
[2024-01-21T12:40:38.105+0100] {logging_mixin.py:188} INFO - Nombre: 1000
[2024-01-21T12:40:38.658+0100] {logging_mixin.py:188} INFO - Nombre: 1020
[2024-01-21T12:40:39.019+0100] {logging_mixin.py:188} INFO - Nombre: 1040
[2024-01-21T12:40:39.434+0100] {logging_mixin.py:188} INFO - Nombre: 1060
[2024-01-21T12:40:40.046+0100] {logging_mixin.py:188} INFO - Nombre: 1080
[2024-01-21T12:40:40.523+0100] {logging_mixin.py:188} INFO - Nombre: 1100
[2024-01-21T12:40:41.016+0100] {logging_mixin.py:188} INFO - Nombre: 1120
[2024-01-21T12:40:41.609+0100] {logging_mixin.py:188} INFO - Nombre: 1140
[2024-01-21T12:40:42.106+0100] {logging_mixin.py:188} INFO - Nombre: 1160
[2024-01-21T12:40:42.621+0100] {logging_mixin.py:188} INFO - Nombre: 1180
[2024-01-21T12:40:43.137+0100] {logging_mixin.py:188} INFO - Nombre: 1200
[2024-01-21T12:40:43.599+0100] {logging_mixin.py:188} INFO - Nombre: 1220
[2024-01-21T12:40:44.061+0100] {logging_mixin.py:188} INFO - Nombre: 1240
[2024-01-21T12:40:44.464+0100] {logging_mixin.py:188} INFO - Nombre: 1260
[2024-01-21T12:40:45.015+0100] {logging_mixin.py:188} INFO - Nombre: 1280
[2024-01-21T12:40:45.556+0100] {logging_mixin.py:188} INFO - Nombre: 1300
[2024-01-21T12:40:46.103+0100] {logging_mixin.py:188} INFO - Nombre: 1320
[2024-01-21T12:40:47.655+0100] {logging_mixin.py:188} INFO - Nombre: 1340
[2024-01-21T12:40:48.739+0100] {logging_mixin.py:188} INFO - [2024-01-21T12:40:48.736+0100] {timeout.py:68} ERROR - Process timed out, PID: 5792
[2024-01-21T12:40:49.100+0100] {logging_mixin.py:188} INFO - [2024-01-21T12:40:48.742+0100] {dagbag.py:348} ERROR - Failed to import: /home/ubuntu/airflow/dags/my_dag.py
Traceback (most recent call last):
  File "/home/ubuntu/.local/lib/python3.10/site-packages/airflow/models/dagbag.py", line 344, in parse
    loader.exec_module(new_module)
  File "<frozen importlib._bootstrap_external>", line 883, in exec_module
  File "<frozen importlib._bootstrap>", line 241, in _call_with_frames_removed
  File "/home/ubuntu/airflow/dags/my_dag.py", line 5, in <module>
    from movies import find_popular_movies_and_save, get_movie_genres
  File "/home/ubuntu/airflow/dags/movies.py", line 45, in <module>
    find_popular_movies_and_save()
  File "/home/ubuntu/airflow/dags/movies.py", line 33, in find_popular_movies_and_save
    response = requests.get(base_url, params=params)
  File "/home/ubuntu/.local/lib/python3.10/site-packages/requests/api.py", line 73, in get
    return request("get", url, params=params, **kwargs)
  File "/home/ubuntu/.local/lib/python3.10/site-packages/requests/api.py", line 59, in request
    return session.request(method=method, url=url, **kwargs)
  File "/home/ubuntu/.local/lib/python3.10/site-packages/requests/sessions.py", line 589, in request
    resp = self.send(prep, **send_kwargs)
  File "/home/ubuntu/.local/lib/python3.10/site-packages/requests/sessions.py", line 703, in send
    r = adapter.send(request, **kwargs)
  File "/home/ubuntu/.local/lib/python3.10/site-packages/requests/adapters.py", line 486, in send
    resp = conn.urlopen(
  File "/home/ubuntu/.local/lib/python3.10/site-packages/urllib3/connectionpool.py", line 715, in urlopen
    httplib_response = self._make_request(
  File "/home/ubuntu/.local/lib/python3.10/site-packages/urllib3/connectionpool.py", line 404, in _make_request
    self._validate_conn(conn)
  File "/home/ubuntu/.local/lib/python3.10/site-packages/urllib3/connectionpool.py", line 1058, in _validate_conn
    conn.connect()
  File "/home/ubuntu/.local/lib/python3.10/site-packages/urllib3/connection.py", line 419, in connect
    self.sock = ssl_wrap_socket(
  File "/home/ubuntu/.local/lib/python3.10/site-packages/urllib3/util/ssl_.py", line 402, in ssl_wrap_socket
    context.load_verify_locations(ca_certs, ca_cert_dir, ca_cert_data)
  File "/home/ubuntu/.local/lib/python3.10/site-packages/airflow/utils/timeout.py", line 69, in handle_timeout
    raise AirflowTaskTimeout(self.error_message)
airflow.exceptions.AirflowTaskTimeout: DagBag import timeout for /home/ubuntu/airflow/dags/my_dag.py after 30.0s.
Please take a look at these docs to improve your DAG import time:
* https://airflow.apache.org/docs/apache-airflow/2.8.0/best-practices.html#top-level-python-code
* https://airflow.apache.org/docs/apache-airflow/2.8.0/best-practices.html#reducing-dag-complexity, PID: 5792
[2024-01-21T12:40:49.344+0100] {processor.py:842} WARNING - No viable dags retrieved from /home/ubuntu/airflow/dags/my_dag.py
[2024-01-21T12:40:49.553+0100] {processor.py:183} INFO - Processing /home/ubuntu/airflow/dags/my_dag.py took 31.433 seconds
[2024-01-21T12:41:21.434+0100] {processor.py:161} INFO - Started process (PID=5833) to work on /home/ubuntu/airflow/dags/my_dag.py
[2024-01-21T12:41:21.437+0100] {processor.py:830} INFO - Processing file /home/ubuntu/airflow/dags/my_dag.py for tasks to queue
[2024-01-21T12:41:21.441+0100] {logging_mixin.py:188} INFO - [2024-01-21T12:41:21.441+0100] {dagbag.py:538} INFO - Filling up the DagBag from /home/ubuntu/airflow/dags/my_dag.py
[2024-01-21T12:41:23.079+0100] {logging_mixin.py:188} INFO - Nombre: 40
[2024-01-21T12:41:23.509+0100] {logging_mixin.py:188} INFO - Nombre: 60
[2024-01-21T12:41:24.054+0100] {logging_mixin.py:188} INFO - Nombre: 80
[2024-01-21T12:41:24.449+0100] {logging_mixin.py:188} INFO - Nombre: 100
[2024-01-21T12:41:24.755+0100] {logging_mixin.py:188} INFO - Nombre: 120
[2024-01-21T12:41:25.369+0100] {logging_mixin.py:188} INFO - Nombre: 140
[2024-01-21T12:41:25.731+0100] {logging_mixin.py:188} INFO - Nombre: 160
[2024-01-21T12:41:26.080+0100] {logging_mixin.py:188} INFO - Nombre: 180
[2024-01-21T12:41:26.556+0100] {logging_mixin.py:188} INFO - Nombre: 200
[2024-01-21T12:41:26.871+0100] {logging_mixin.py:188} INFO - Nombre: 220
[2024-01-21T12:41:27.325+0100] {logging_mixin.py:188} INFO - Nombre: 240
[2024-01-21T12:41:27.728+0100] {logging_mixin.py:188} INFO - Nombre: 260
[2024-01-21T12:41:28.112+0100] {logging_mixin.py:188} INFO - Nombre: 280
[2024-01-21T12:41:28.444+0100] {logging_mixin.py:188} INFO - Nombre: 300
[2024-01-21T12:41:28.780+0100] {logging_mixin.py:188} INFO - Nombre: 320
[2024-01-21T12:41:29.210+0100] {logging_mixin.py:188} INFO - Nombre: 340
[2024-01-21T12:41:29.589+0100] {logging_mixin.py:188} INFO - Nombre: 360
[2024-01-21T12:41:29.942+0100] {logging_mixin.py:188} INFO - Nombre: 380
[2024-01-21T12:41:30.344+0100] {logging_mixin.py:188} INFO - Nombre: 400
[2024-01-21T12:41:30.737+0100] {logging_mixin.py:188} INFO - Nombre: 420
[2024-01-21T12:41:31.139+0100] {logging_mixin.py:188} INFO - Nombre: 440
[2024-01-21T12:41:31.474+0100] {logging_mixin.py:188} INFO - Nombre: 460
[2024-01-21T12:41:31.809+0100] {logging_mixin.py:188} INFO - Nombre: 480
[2024-01-21T12:41:32.207+0100] {logging_mixin.py:188} INFO - Nombre: 500
[2024-01-21T12:41:32.602+0100] {logging_mixin.py:188} INFO - Nombre: 520
[2024-01-21T12:41:33.040+0100] {logging_mixin.py:188} INFO - Nombre: 540
[2024-01-21T12:41:33.480+0100] {logging_mixin.py:188} INFO - Nombre: 560
[2024-01-21T12:41:33.844+0100] {logging_mixin.py:188} INFO - Nombre: 580
[2024-01-21T12:41:34.270+0100] {logging_mixin.py:188} INFO - Nombre: 600
[2024-01-21T12:41:34.670+0100] {logging_mixin.py:188} INFO - Nombre: 620
[2024-01-21T12:41:35.047+0100] {logging_mixin.py:188} INFO - Nombre: 640
[2024-01-21T12:41:35.544+0100] {logging_mixin.py:188} INFO - Nombre: 660
[2024-01-21T12:41:35.924+0100] {logging_mixin.py:188} INFO - Nombre: 680
[2024-01-21T12:41:36.401+0100] {logging_mixin.py:188} INFO - Nombre: 700
[2024-01-21T12:41:36.816+0100] {logging_mixin.py:188} INFO - Nombre: 720
[2024-01-21T12:41:37.203+0100] {logging_mixin.py:188} INFO - Nombre: 740
[2024-01-21T12:41:37.536+0100] {logging_mixin.py:188} INFO - Nombre: 760
[2024-01-21T12:41:37.858+0100] {logging_mixin.py:188} INFO - Nombre: 780
[2024-01-21T12:41:38.231+0100] {logging_mixin.py:188} INFO - Nombre: 800
[2024-01-21T12:41:38.604+0100] {logging_mixin.py:188} INFO - Nombre: 820
[2024-01-21T12:41:38.976+0100] {logging_mixin.py:188} INFO - Nombre: 840
[2024-01-21T12:41:39.364+0100] {logging_mixin.py:188} INFO - Nombre: 860
[2024-01-21T12:41:39.784+0100] {logging_mixin.py:188} INFO - Nombre: 880
[2024-01-21T12:41:40.165+0100] {logging_mixin.py:188} INFO - Nombre: 900
[2024-01-21T12:41:40.542+0100] {logging_mixin.py:188} INFO - Nombre: 920
[2024-01-21T12:41:40.858+0100] {logging_mixin.py:188} INFO - Nombre: 940
[2024-01-21T12:41:41.203+0100] {logging_mixin.py:188} INFO - Nombre: 960
[2024-01-21T12:41:41.582+0100] {logging_mixin.py:188} INFO - Nombre: 980
[2024-01-21T12:41:41.981+0100] {logging_mixin.py:188} INFO - Nombre: 1000
[2024-01-21T12:41:42.400+0100] {logging_mixin.py:188} INFO - Nombre: 1020
[2024-01-21T12:41:42.782+0100] {logging_mixin.py:188} INFO - Nombre: 1040
[2024-01-21T12:41:43.139+0100] {logging_mixin.py:188} INFO - Nombre: 1060
[2024-01-21T12:41:43.511+0100] {logging_mixin.py:188} INFO - Nombre: 1080
[2024-01-21T12:41:43.914+0100] {logging_mixin.py:188} INFO - Nombre: 1100
[2024-01-21T12:41:44.226+0100] {logging_mixin.py:188} INFO - Nombre: 1120
[2024-01-21T12:41:44.760+0100] {logging_mixin.py:188} INFO - Nombre: 1140
[2024-01-21T12:41:45.166+0100] {logging_mixin.py:188} INFO - Nombre: 1160
[2024-01-21T12:41:45.521+0100] {logging_mixin.py:188} INFO - Nombre: 1180
[2024-01-21T12:41:45.841+0100] {logging_mixin.py:188} INFO - Nombre: 1200
[2024-01-21T12:41:46.327+0100] {logging_mixin.py:188} INFO - Nombre: 1220
[2024-01-21T12:41:46.778+0100] {logging_mixin.py:188} INFO - Nombre: 1240
[2024-01-21T12:41:47.143+0100] {logging_mixin.py:188} INFO - Nombre: 1260
[2024-01-21T12:41:47.567+0100] {logging_mixin.py:188} INFO - Nombre: 1280
[2024-01-21T12:41:47.944+0100] {logging_mixin.py:188} INFO - Nombre: 1300
[2024-01-21T12:41:48.247+0100] {logging_mixin.py:188} INFO - Nombre: 1320
[2024-01-21T12:41:48.601+0100] {logging_mixin.py:188} INFO - Nombre: 1340
[2024-01-21T12:41:48.968+0100] {logging_mixin.py:188} INFO - Nombre: 1360
[2024-01-21T12:41:49.354+0100] {logging_mixin.py:188} INFO - Nombre: 1380
[2024-01-21T12:41:49.740+0100] {logging_mixin.py:188} INFO - Nombre: 1400
[2024-01-21T12:41:50.280+0100] {logging_mixin.py:188} INFO - Nombre: 1420
[2024-01-21T12:41:50.805+0100] {logging_mixin.py:188} INFO - Nombre: 1440
[2024-01-21T12:41:51.327+0100] {logging_mixin.py:188} INFO - Nombre: 1460
[2024-01-21T12:41:51.563+0100] {logging_mixin.py:188} INFO - [2024-01-21T12:41:51.562+0100] {timeout.py:68} ERROR - Process timed out, PID: 5833
[2024-01-21T12:41:51.569+0100] {logging_mixin.py:188} INFO - [2024-01-21T12:41:51.564+0100] {dagbag.py:348} ERROR - Failed to import: /home/ubuntu/airflow/dags/my_dag.py
Traceback (most recent call last):
  File "/home/ubuntu/.local/lib/python3.10/site-packages/airflow/models/dagbag.py", line 344, in parse
    loader.exec_module(new_module)
  File "<frozen importlib._bootstrap_external>", line 883, in exec_module
  File "<frozen importlib._bootstrap>", line 241, in _call_with_frames_removed
  File "/home/ubuntu/airflow/dags/my_dag.py", line 5, in <module>
    from movies import find_popular_movies_and_save, get_movie_genres
  File "/home/ubuntu/airflow/dags/movies.py", line 45, in <module>
    find_popular_movies_and_save()
  File "/home/ubuntu/airflow/dags/movies.py", line 33, in find_popular_movies_and_save
    response = requests.get(base_url, params=params)
  File "/home/ubuntu/.local/lib/python3.10/site-packages/requests/api.py", line 73, in get
    return request("get", url, params=params, **kwargs)
  File "/home/ubuntu/.local/lib/python3.10/site-packages/requests/api.py", line 59, in request
    return session.request(method=method, url=url, **kwargs)
  File "/home/ubuntu/.local/lib/python3.10/site-packages/requests/sessions.py", line 589, in request
    resp = self.send(prep, **send_kwargs)
  File "/home/ubuntu/.local/lib/python3.10/site-packages/requests/sessions.py", line 703, in send
    r = adapter.send(request, **kwargs)
  File "/home/ubuntu/.local/lib/python3.10/site-packages/requests/adapters.py", line 486, in send
    resp = conn.urlopen(
  File "/home/ubuntu/.local/lib/python3.10/site-packages/urllib3/connectionpool.py", line 715, in urlopen
    httplib_response = self._make_request(
  File "/home/ubuntu/.local/lib/python3.10/site-packages/urllib3/connectionpool.py", line 404, in _make_request
    self._validate_conn(conn)
  File "/home/ubuntu/.local/lib/python3.10/site-packages/urllib3/connectionpool.py", line 1058, in _validate_conn
    conn.connect()
  File "/home/ubuntu/.local/lib/python3.10/site-packages/urllib3/connection.py", line 419, in connect
    self.sock = ssl_wrap_socket(
  File "/home/ubuntu/.local/lib/python3.10/site-packages/urllib3/util/ssl_.py", line 402, in ssl_wrap_socket
    context.load_verify_locations(ca_certs, ca_cert_dir, ca_cert_data)
  File "/home/ubuntu/.local/lib/python3.10/site-packages/airflow/utils/timeout.py", line 69, in handle_timeout
    raise AirflowTaskTimeout(self.error_message)
airflow.exceptions.AirflowTaskTimeout: DagBag import timeout for /home/ubuntu/airflow/dags/my_dag.py after 30.0s.
Please take a look at these docs to improve your DAG import time:
* https://airflow.apache.org/docs/apache-airflow/2.8.0/best-practices.html#top-level-python-code
* https://airflow.apache.org/docs/apache-airflow/2.8.0/best-practices.html#reducing-dag-complexity, PID: 5833
[2024-01-21T12:41:51.575+0100] {processor.py:842} WARNING - No viable dags retrieved from /home/ubuntu/airflow/dags/my_dag.py
[2024-01-21T12:41:51.661+0100] {processor.py:183} INFO - Processing /home/ubuntu/airflow/dags/my_dag.py took 30.233 seconds
