[2024-01-27T18:55:09.713+0100] {taskinstance.py:1957} INFO - Dependencies all met for dep_context=non-requeueable deps ti=<TaskInstance: jeniferhdfs.popular_movies_task manual__2024-01-27T17:54:33.414261+00:00 [queued]>
[2024-01-27T18:55:09.725+0100] {taskinstance.py:1957} INFO - Dependencies all met for dep_context=requeueable deps ti=<TaskInstance: jeniferhdfs.popular_movies_task manual__2024-01-27T17:54:33.414261+00:00 [queued]>
[2024-01-27T18:55:09.726+0100] {taskinstance.py:2171} INFO - Starting attempt 1 of 2
[2024-01-27T18:55:09.797+0100] {taskinstance.py:2192} INFO - Executing <Task(PythonOperator): popular_movies_task> on 2024-01-27 17:54:33.414261+00:00
[2024-01-27T18:55:09.812+0100] {standard_task_runner.py:60} INFO - Started process 7257 to run task
[2024-01-27T18:55:09.824+0100] {standard_task_runner.py:87} INFO - Running: ['airflow', 'tasks', 'run', 'jeniferhdfs', 'popular_movies_task', 'manual__2024-01-27T17:54:33.414261+00:00', '--job-id', '46', '--raw', '--subdir', 'DAGS_FOLDER/hdfsDag.py', '--cfg-path', '/tmp/tmprjy0o9md']
[2024-01-27T18:55:09.839+0100] {standard_task_runner.py:88} INFO - Job 46: Subtask popular_movies_task
[2024-01-27T18:55:10.006+0100] {task_command.py:423} INFO - Running <TaskInstance: jeniferhdfs.popular_movies_task manual__2024-01-27T17:54:33.414261+00:00 [running]> on host ubuntu.ubuntu.virtualbox.org
[2024-01-27T18:55:10.262+0100] {taskinstance.py:2481} INFO - Exporting env vars: AIRFLOW_CTX_DAG_OWNER='jenifer' AIRFLOW_CTX_DAG_ID='jeniferhdfs' AIRFLOW_CTX_TASK_ID='popular_movies_task' AIRFLOW_CTX_EXECUTION_DATE='2024-01-27T17:54:33.414261+00:00' AIRFLOW_CTX_TRY_NUMBER='1' AIRFLOW_CTX_DAG_RUN_ID='manual__2024-01-27T17:54:33.414261+00:00'
[2024-01-27T18:55:10.275+0100] {logging_mixin.py:188} INFO - {'conf': <airflow.configuration.AirflowConfigParser object at 0x7f3e8c8c89d0>, 'dag': <DAG: jeniferhdfs>, 'dag_run': <DagRun jeniferhdfs @ 2024-01-27 17:54:33.414261+00:00: manual__2024-01-27T17:54:33.414261+00:00, state:running, queued_at: 2024-01-27 17:54:33.689621+00:00. externally triggered: True>, 'data_interval_end': DateTime(2024, 1, 27, 0, 0, 0, tzinfo=Timezone('UTC')), 'data_interval_start': DateTime(2024, 1, 26, 0, 0, 0, tzinfo=Timezone('UTC')), 'ds': '2024-01-27', 'ds_nodash': '20240127', 'execution_date': <Proxy at 0x7f3e6f646880 with factory functools.partial(<function lazy_mapping_from_context.<locals>._deprecated_proxy_factory at 0x7f3e6f4be710>, 'execution_date', DateTime(2024, 1, 27, 17, 54, 33, 414261, tzinfo=Timezone('UTC')))>, 'expanded_ti_count': None, 'inlets': [], 'logical_date': DateTime(2024, 1, 27, 17, 54, 33, 414261, tzinfo=Timezone('UTC')), 'macros': <module 'airflow.macros' from '/home/ubuntu/.local/lib/python3.10/site-packages/airflow/macros/__init__.py'>, 'next_ds': <Proxy at 0x7f3e6f3bcc00 with factory functools.partial(<function lazy_mapping_from_context.<locals>._deprecated_proxy_factory at 0x7f3e6f4be710>, 'next_ds', '2024-01-27')>, 'next_ds_nodash': <Proxy at 0x7f3e6f60a280 with factory functools.partial(<function lazy_mapping_from_context.<locals>._deprecated_proxy_factory at 0x7f3e6f4be710>, 'next_ds_nodash', '20240127')>, 'next_execution_date': <Proxy at 0x7f3e6f532c80 with factory functools.partial(<function lazy_mapping_from_context.<locals>._deprecated_proxy_factory at 0x7f3e6f4be710>, 'next_execution_date', DateTime(2024, 1, 27, 17, 54, 33, 414261, tzinfo=Timezone('UTC')))>, 'outlets': [], 'params': {}, 'prev_data_interval_start_success': None, 'prev_data_interval_end_success': None, 'prev_ds': <Proxy at 0x7f3e854cf440 with factory functools.partial(<function lazy_mapping_from_context.<locals>._deprecated_proxy_factory at 0x7f3e6f4be710>, 'prev_ds', '2024-01-27')>, 'prev_ds_nodash': <Proxy at 0x7f3e6f3ca940 with factory functools.partial(<function lazy_mapping_from_context.<locals>._deprecated_proxy_factory at 0x7f3e6f4be710>, 'prev_ds_nodash', '20240127')>, 'prev_execution_date': <Proxy at 0x7f3e6f3ca980 with factory functools.partial(<function lazy_mapping_from_context.<locals>._deprecated_proxy_factory at 0x7f3e6f4be710>, 'prev_execution_date', DateTime(2024, 1, 27, 17, 54, 33, 414261, tzinfo=Timezone('UTC')))>, 'prev_execution_date_success': <Proxy at 0x7f3e6f3ca9c0 with factory functools.partial(<function lazy_mapping_from_context.<locals>._deprecated_proxy_factory at 0x7f3e6f4be710>, 'prev_execution_date_success', None)>, 'prev_start_date_success': None, 'prev_end_date_success': None, 'run_id': 'manual__2024-01-27T17:54:33.414261+00:00', 'task': <Task(PythonOperator): popular_movies_task>, 'task_instance': <TaskInstance: jeniferhdfs.popular_movies_task manual__2024-01-27T17:54:33.414261+00:00 [running]>, 'task_instance_key_str': 'jeniferhdfs__popular_movies_task__20240127', 'test_mode': False, 'ti': <TaskInstance: jeniferhdfs.popular_movies_task manual__2024-01-27T17:54:33.414261+00:00 [running]>, 'tomorrow_ds': <Proxy at 0x7f3e6f3caa00 with factory functools.partial(<function lazy_mapping_from_context.<locals>._deprecated_proxy_factory at 0x7f3e6f4be710>, 'tomorrow_ds', '2024-01-28')>, 'tomorrow_ds_nodash': <Proxy at 0x7f3e6f3caa40 with factory functools.partial(<function lazy_mapping_from_context.<locals>._deprecated_proxy_factory at 0x7f3e6f4be710>, 'tomorrow_ds_nodash', '20240128')>, 'triggering_dataset_events': <Proxy at 0x7f3e6f56b240 with factory <function _get_template_context.<locals>.get_triggering_events at 0x7f3e6f5745e0>>, 'ts': '2024-01-27T17:54:33.414261+00:00', 'ts_nodash': '20240127T175433', 'ts_nodash_with_tz': '20240127T175433.414261+0000', 'var': {'json': None, 'value': None}, 'conn': None, 'yesterday_ds': <Proxy at 0x7f3e6f3caa80 with factory functools.partial(<function lazy_mapping_from_context.<locals>._deprecated_proxy_factory at 0x7f3e6f4be710>, 'yesterday_ds', '2024-01-26')>, 'yesterday_ds_nodash': <Proxy at 0x7f3e6f3caac0 with factory functools.partial(<function lazy_mapping_from_context.<locals>._deprecated_proxy_factory at 0x7f3e6f4be710>, 'yesterday_ds_nodash', '20240126')>, 'templates_dict': None}
[2024-01-27T18:55:12.150+0100] {client.py:192} INFO - Instantiated <InsecureClient(url='http://localhost:9870')>.
[2024-01-27T18:55:12.167+0100] {client.py:496} INFO - Writing to '/user/project/datalake/raw/2024-01-27/tmdb_popular_movies.json'.
[2024-01-27T18:55:12.175+0100] {taskinstance.py:2699} ERROR - Task failed with exception
Traceback (most recent call last):
  File "/home/ubuntu/.local/lib/python3.10/site-packages/urllib3/connection.py", line 174, in _new_conn
    conn = connection.create_connection(
  File "/home/ubuntu/.local/lib/python3.10/site-packages/urllib3/util/connection.py", line 95, in create_connection
    raise err
  File "/home/ubuntu/.local/lib/python3.10/site-packages/urllib3/util/connection.py", line 85, in create_connection
    sock.connect(sa)
ConnectionRefusedError: [Errno 111] Connection refused

During handling of the above exception, another exception occurred:

Traceback (most recent call last):
  File "/home/ubuntu/.local/lib/python3.10/site-packages/urllib3/connectionpool.py", line 715, in urlopen
    httplib_response = self._make_request(
  File "/home/ubuntu/.local/lib/python3.10/site-packages/urllib3/connectionpool.py", line 416, in _make_request
    conn.request(method, url, **httplib_request_kw)
  File "/home/ubuntu/.local/lib/python3.10/site-packages/urllib3/connection.py", line 244, in request
    super(HTTPConnection, self).request(method, url, body=body, headers=headers)
  File "/usr/lib/python3.10/http/client.py", line 1283, in request
    self._send_request(method, url, body, headers, encode_chunked)
  File "/usr/lib/python3.10/http/client.py", line 1329, in _send_request
    self.endheaders(body, encode_chunked=encode_chunked)
  File "/usr/lib/python3.10/http/client.py", line 1278, in endheaders
    self._send_output(message_body, encode_chunked=encode_chunked)
  File "/usr/lib/python3.10/http/client.py", line 1038, in _send_output
    self.send(msg)
  File "/usr/lib/python3.10/http/client.py", line 976, in send
    self.connect()
  File "/home/ubuntu/.local/lib/python3.10/site-packages/urllib3/connection.py", line 205, in connect
    conn = self._new_conn()
  File "/home/ubuntu/.local/lib/python3.10/site-packages/urllib3/connection.py", line 186, in _new_conn
    raise NewConnectionError(
urllib3.exceptions.NewConnectionError: <urllib3.connection.HTTPConnection object at 0x7f3e6f3ae6e0>: Failed to establish a new connection: [Errno 111] Connection refused

During handling of the above exception, another exception occurred:

Traceback (most recent call last):
  File "/home/ubuntu/.local/lib/python3.10/site-packages/requests/adapters.py", line 486, in send
    resp = conn.urlopen(
  File "/home/ubuntu/.local/lib/python3.10/site-packages/urllib3/connectionpool.py", line 799, in urlopen
    retries = retries.increment(
  File "/home/ubuntu/.local/lib/python3.10/site-packages/urllib3/util/retry.py", line 592, in increment
    raise MaxRetryError(_pool, url, error or ResponseError(cause))
urllib3.exceptions.MaxRetryError: HTTPConnectionPool(host='localhost', port=9870): Max retries exceeded with url: /webhdfs/v1/user/project/datalake/raw/2024-01-27/tmdb_popular_movies.json?user.name=hadoop&overwrite=True&op=CREATE (Caused by NewConnectionError('<urllib3.connection.HTTPConnection object at 0x7f3e6f3ae6e0>: Failed to establish a new connection: [Errno 111] Connection refused'))

During handling of the above exception, another exception occurred:

Traceback (most recent call last):
  File "/home/ubuntu/.local/lib/python3.10/site-packages/airflow/models/taskinstance.py", line 433, in _execute_task
    result = execute_callable(context=context, **execute_callable_kwargs)
  File "/home/ubuntu/.local/lib/python3.10/site-packages/airflow/operators/python.py", line 199, in execute
    return_value = self.execute_callable()
  File "/home/ubuntu/.local/lib/python3.10/site-packages/airflow/operators/python.py", line 216, in execute_callable
    return self.python_callable(*self.op_args, **self.op_kwargs)
  File "/home/ubuntu/airflow/dags/getDataHdfs.py", line 53, in ingest_all_data
    fetch_and_save_multiple_pages(api_key, start_page=1, end_page=4)
  File "/home/ubuntu/airflow/dags/getDataHdfs.py", line 44, in fetch_and_save_multiple_pages
    save_to_hdfs(all_data)
  File "/home/ubuntu/airflow/dags/getDataHdfs.py", line 30, in save_to_hdfs
    with client.write(hdfs_path, overwrite=True) as writer:
  File "/home/ubuntu/.local/lib/python3.10/site-packages/hdfs/client.py", line 497, in write
    res = self._create(
  File "/home/ubuntu/.local/lib/python3.10/site-packages/hdfs/client.py", line 125, in api_handler
    raise err
  File "/home/ubuntu/.local/lib/python3.10/site-packages/hdfs/client.py", line 102, in api_handler
    res = client._request(
  File "/home/ubuntu/.local/lib/python3.10/site-packages/hdfs/client.py", line 209, in _request
    return self._session.request(
  File "/home/ubuntu/.local/lib/python3.10/site-packages/requests/sessions.py", line 589, in request
    resp = self.send(prep, **send_kwargs)
  File "/home/ubuntu/.local/lib/python3.10/site-packages/requests/sessions.py", line 703, in send
    r = adapter.send(request, **kwargs)
  File "/home/ubuntu/.local/lib/python3.10/site-packages/requests/adapters.py", line 519, in send
    raise ConnectionError(e, request=request)
requests.exceptions.ConnectionError: HTTPConnectionPool(host='localhost', port=9870): Max retries exceeded with url: /webhdfs/v1/user/project/datalake/raw/2024-01-27/tmdb_popular_movies.json?user.name=hadoop&overwrite=True&op=CREATE (Caused by NewConnectionError('<urllib3.connection.HTTPConnection object at 0x7f3e6f3ae6e0>: Failed to establish a new connection: [Errno 111] Connection refused'))
[2024-01-27T18:55:12.198+0100] {taskinstance.py:1138} INFO - Marking task as UP_FOR_RETRY. dag_id=jeniferhdfs, task_id=popular_movies_task, execution_date=20240127T175433, start_date=20240127T175509, end_date=20240127T175512
[2024-01-27T18:55:12.290+0100] {standard_task_runner.py:107} ERROR - Failed to execute job 46 for task popular_movies_task (HTTPConnectionPool(host='localhost', port=9870): Max retries exceeded with url: /webhdfs/v1/user/project/datalake/raw/2024-01-27/tmdb_popular_movies.json?user.name=hadoop&overwrite=True&op=CREATE (Caused by NewConnectionError('<urllib3.connection.HTTPConnection object at 0x7f3e6f3ae6e0>: Failed to establish a new connection: [Errno 111] Connection refused')); 7257)
[2024-01-27T18:55:12.320+0100] {local_task_job_runner.py:234} INFO - Task exited with return code 1
[2024-01-27T18:55:12.360+0100] {taskinstance.py:3281} INFO - 0 downstream tasks scheduled from follow-on schedule check
